Workbook

Sheet 안내
A1: maiReport 식이 문구 세트 · 의학 검수 결과 · v1.1.0 · 2026-10-13
A2: 확장 초안 191개를 가정의학 임상 관점에서 검수했다. 실제 의학팀 최종 승인을 대체하지 않는다 — 쟁점 8번 참조. 2026-10-06에 국내외 학회 가이드라인 근거 문구 29개를 5차로 올렸고 이 29개는 아직 검수 전이다. 2026-10-07에 만성 신장질환 결식 시 쓸 회복 풀 문구 2개를 6차로 올렸고 이 2개도 검수 전이다. 2026-10-07에 저녁 회복 문구 3개를 6차로 올리고 승인했다. 2026-10-13에 반복을 줄이려고 만든 추가 문구 227개(N226~N452)를 7차로 올렸고, 사용자 · Claude가 의학팀 역할로 검수해 승인했다(해초샐러드 1개는 확인 필요).
A4: 판정 | B4: 뜻 | C4: 건수 | D4: 처리
A5: 승인 | B5: 그대로 쓸 수 있다 | C5: =COUNTIF(검수결과!L:L,"승인") -> 394 | D5: 문구 세트에 편입
A6: 조건부 | B6: 금지 · 제한을 추가하면 쓸 수 있다 | C6: =COUNTIF(검수결과!L:L,"조건부") -> 12 | D6: 신규금지규칙 시트 반영 후 편입
A7: 수정 | B7: 문구나 이유 문장을 고쳐야 한다 | C7: =COUNTIF(검수결과!L:L,"수정") -> 6 | D7: 검수 후 문구 열 적용
A8: 확인 필요 | B8: 해롭지는 않으나 수행 불가 집단이 있다 | C8: =COUNTIF(검수결과!L:L,"확인 필요") -> 3 | D8: 서비스 대상 정책에서 판단
A9: 보류 | B9: 축 적합성 · 단계 구분에 의문 | C9: =COUNTIF(검수결과!L:L,"보류") -> 2 | D9: 설계 확정 후 재검토
A10: 삭제 | B10: 제한 불가 위험 또는 중복 | C10: =COUNTIF(검수결과!L:L,"삭제") -> 5 | D10: 세트에서 뺀다
A11: 합계 | C11: =SUM(C5:C10) -> 422
A13: 가장 중요한 것
A14: · 수분을 늘리는 문구 5개에 심부전 · 투석 금지가 없다. 상병코드 추천이 「그런 문구가 생기면 제외하라」고 미리 적어 둔 항목이 확장으로 실제 생겼다.
A15: · 야간 공복을 늘리는 문구에 당뇨 금지가 빠져 있다. 처방 정보가 없어 저혈당 위험군을 가릴 수 없으므로 확진 전원에 적용해야 한다.
A16: · 해조류 문구는 요오드 때문에 갑상선질환에 문제가 되는데, 갑상선은 진단 층에서 가져오지 않아 제한을 걸 수단이 없다. 그래서 삭제를 권한다.
A17: · 견과류 · 과일의 신장 제한이 확정 세트와 확장 세트에서 서로 다르게 적용돼 있다.
A19: 계약서와의 연결
A20: 검수결과 시트 오른쪽에 「계약서 문구 ID」와 「연결 상태」 두 열을 두었다. 연결 상태가 「계약서에 없음」인 항목은 검수는 했으나 데이터계약 목표문구에 올라가 있지 않은 것이다. 2026-10-06 기준 연결 128 · 없음 92.

Sheet 검수결과
A1: ID | B1: 묶음 | C1: 축 | D1: 단계 | E1: 원안 문구 | F1: 검수 후 문구 | G1: 자 | H1: 이유 한 줄 | I1: 표시 | J1: 근거 | K1: 기존 제한 | L1: 판정 | M1: 추가 제한 | N1: 검수 의견 | O1: 계약서 문구 ID | P1: 연결 상태
A2: N1 | B2: 1차 | C2: 끼니 규칙 | D2: 입문 | E2: 아침에 우유나 두유 한 잔 | F2: 아침에 우유나 두유 한 잔 | G2: 14 | H2: 마실 것 하나라도 아침 끼니가 돼요. | I2: 오전 진입 | J2: 식생활지침 수칙 1 · 5 | K2: — | L2: 승인 | O2: DIET-P-0040 | P2: 근거대조서를 거쳐 연결
A3: N2 | B3: 1차 | C3: 끼니 규칙 | D3: 입문 | E3: 아침에 과일 한 조각 | F3: 아침에 과일 한 조각 | G3: 11 | H3: 손이 가는 것부터 아침을 시작해요. | I3: 오전 진입 | J3: 식생활지침 수칙 1 · 5 | K3: — | L3: 삭제 | N3: 과일을 「더 먹기」로 권하는 문구다. 대체 맥락이 아니어서 당뇨 · 비만 사용자에게는 열량과 당이 순증한다. 빈속에 과일만 먹으면 식후 혈당도 크게 오른다. 끼니 규칙 입문 칸에는 N1(우유 · 두유) · N47 · N94가 이미 있어 빼도 칸이 빈다고 보기 어렵다. | O3: — | P3: 계약서에 없음
A4: N3 | B4: 1차 | C4: 끼니 규칙 | D4: 기본 | E4: 점심은 늦지 않게 챙기기 | F4: 점심 늦지 않게 | G4: 8 | H4: 점심이 늦어지면 저녁까지 몰아 먹게 돼요. | I4: — | J4: 식생활지침 수칙 4 | K4: — | L4: 승인 | O4: DIET-P-0041 | P4: 근거대조서를 거쳐 연결
A5: N4 | B5: 1차 | C5: 끼니 규칙 | D5: 도전 | E5: 오늘 세 끼 모두 챙기기 | F5: 오늘 세 끼 챙기기 | G5: 10 | H5: 세 끼가 다 있으면 한 끼 양이 자연히 줄어요. | I5: — | J5: 식생활지침 수칙 1 · 4 | K5: — | L5: 승인 | O5: DIET-P-0042 | P5: 문구 그대로
A6: N6 | B6: 1차 | C6: 채소 | D6: 입문 | E6: 국 대신 나물 한 접시 | F6: 국 대신 나물 반찬 | G6: 10 | H6: 국물 자리에 채소를 넣으면 나트륨도 함께 줄어요. | I6: — | J6: 식생활지침 수칙 1 · 2 | K6: 신장 3기↑ | L6: 승인 | O6: DIET-P-0044 | P6: 문구 그대로
A7: N7 | B7: 1차 | C7: 채소 | D7: 입문 | E7: 고기 먹을 땐 쌈 채소 함께 | F7: 고기엔 쌈 채소 함께 | G7: 11 | H7: 쌈 채소는 가장 쉽게 채소를 더하는 방법이에요. | I7: — | J7: 식생활지침 수칙 1 | K7: 신장 3기↑ | L7: 승인 | O7: DIET-P-0045 | P7: 근거대조서를 거쳐 연결
A8: N8 | B8: 1차 | C8: 채소 | D8: 기본 | E8: 외식 때 채소 반찬 하나 추가 | F8: 외식에도 채소 하나 더 | G8: 12 | H8: 외식은 채소가 가장 빠지기 쉬운 끼니예요. | I8: — | J8: 식생활지침 수칙 1 · WHO 400g | K8: 신장 3기↑ | L8: 승인 | O8: DIET-P-0046 | P8: 문구 그대로
A9: N9 | B9: 1차 | C9: 채소 | D9: 도전 | E9: 매 끼니 채소 두 가지 | F9: 끼니마다 채소 두 가지 | G9: 12 | H9: 끼니마다 두 가지면 하루 다섯 접시에 가까워져요. | I9: — | J9: WHO 400g(5접시) | K9: 신장 3기↑ | L9: 승인 | O9: DIET-P-0047 | P9: 문구 그대로
A10: N10 | B10: 1차 | C10: 채소 | D10: 도전 | E10: 점심도 채소부터 먼저 | F10: 점심도 채소부터 먼저 | G10: 11 | H10: 저녁뿐 아니라 점심에도 순서를 바꿔 보는 단계예요. | I10: — | J10: 식사 순서 무작위 대조 연구 | K10: 신장 3기↑ | L10: 승인 | O10: DIET-P-0048 | P10: 근거대조서를 거쳐 연결
A11: N11 | B11: 1차 | C11: 단 음료 · 단 간식 | D11: 입문 | E11: 커피는 시럽 · 크림 빼고 | F11: 시럽 · 크림 빼기 | G11: 10 | H11: 커피 한 잔의 시럽이 하루 당 권고량의 절반이에요. | I11: — | J11: WHO 당류 지침 | K11: — | L11: 승인 | O11: DIET-P-0049 | P11: 문구 그대로
A12: N12 | B12: 1차 | C12: 단 음료 · 단 간식 | D12: 입문 | E12: 탄산음료 대신 탄산수 | F12: 탄산음료 대신 탄산수 | G12: 11 | H12: 톡 쏘는 느낌은 그대로, 당만 빠져요. | I12: — | J12: WHO 당류 지침 | K12: — | L12: 승인 | O12: DIET-P-0050 | P12: 문구 그대로
A13: N13 | B13: 1차 | C13: 단 음료 · 단 간식 | D13: 기본 | E13: 요구르트는 무가당으로 | F13: 요구르트는 무가당으로 | G13: 11 | H13: 가당 요구르트 한 개에 각설탕 세 개 분량이 들어 있어요. | I13: — | J13: WHO 당류 지침 · 식약처 당류 표시 | K13: — | L13: 승인 | O13: DIET-P-0051 | P13: 문구 그대로
A14: N14 | B14: 1차 | C14: 단 음료 · 단 간식 | D14: 기본 | E14: 과일주스 대신 생과일 | F14: 과일주스 대신 생과일 | G14: 11 | H14: 주스는 과일의 당만 남고 섬유질은 빠져요. | I14: — | J14: WHO 당류 지침(주스는 유리당) | K14: — | L14: 승인 | O14: — | P14: 계약서에 없음
A15: N15 | B15: 1차 | C15: 단 음료 · 단 간식 | D15: 도전 | E15: 단 간식 오늘 하루 쉬기 | F15: 오늘 단 간식 없이 | G15: 10 | H15: 간식의 당은 끼니보다 눈에 안 띄게 쌓여요. | I15: — | J15: WHO 당류 지침 | K15: 섭식장애 임신·수유 | L15: 승인 | O15: DIET-P-0053 | P15: 근거대조서를 거쳐 연결
... A23: N23 | B23: 1차 | C23: 짠맛 · 국물 | D23: 도전 | E23: 반주는 한 잔까지 | F23: 반주는 한 잔까지 | G23: 9 | H23: 하루 한 잔을 넘기면 혈압과 중성지방이 함께 올라요. | I23: 저녁 연결 전용 | J23: 고혈압학회 2022(남 2잔 · 여 1잔 이하) | K23: 임신·수유 간질환 | L23: 승인 | O23: — | P23: 계약서에 없음
A24: N24 | B24: 1차 | C24: 식사 시각 | D24: 입문 | E24: 밤 9시 이후엔 물만 | F24: 밤 9시 이후엔 물만 | G24: 11 | H24: 시각을 하나 정해 두면 야식 결정이 쉬워져요. | I24: 저녁 | J24: 비만학회 식사요법(야식 회피) 약함 | K24: 섭식장애 | L24: 삭제 | N24: N75(잠들기 전 2시간은 물만) · N165와 같은 행동이며, 「밤 9시」는 취침 시각이 제각각인 사용자에게 임의값이다. 취침 기준인 N75를 남긴다. | O24: — | P24: 계약서에 없음
A25: N25 | B25: 1차 | C25: 식사 시각 | D25: 기본 | E25: 저녁은 8시 전에 마치기 | F25: 저녁은 8시 전에 마치기 | G25: 13 | H25: 저녁이 늦어질수록 야식과 수면 둘 다 영향을 받아요. | I25: 저녁 | J25: ACG 위식도역류 지침 · 관찰 연구 | K25: 섭식장애 | L25: 승인 | O25: — | P25: 계약서에 없음
A26: N26 | B26: 1차 | C26: 식사 시각 | D26: 기본 | E26: 야식 대신 일찍 잠자리로 | F26: 야식 대신 일찍 잠자리로 | G26: 13 | H26: 늦은 허기는 졸림과 헷갈리기 쉬워요. | I26: 저녁 | J26: 수면위생 약함 | K26: 섭식장애 | L26: 보류 | N26: 식이 축 문구인데 실제 행동은 취침이다. 수면 목표와 같은 행동이 두 타일에 나갈 수 있다. 수면 축 설계 후 어디에 둘지 정한다. | O26: — | P26: 계약서에 없음
A27: N27 | B27: 1차 | C27: 식사 시각 | D27: 도전 | E27: 저녁 뒤엔 먹지 않고 마무리 | F27: 저녁 뒤엔 먹지 않고 마무리 | G27: 15 | H27: 저녁이 하루의 마지막 끼니가 되게 하는 단계예요. | I27: 저녁 | J27: 비만학회 식사요법 · 관찰 연구 | K27: 섭식장애 | L27: 조건부 | M27: 당뇨병 | N27: 야간 공복을 늘리는 행동이다. 인슐린 · 설포닐우레아 사용자는 야간 저혈당 위험이 있는데 처방 정보가 없어 약물을 알 수 없다. 기존 당뇨 금지와 같은 원칙으로 확진 전원에 적용한다. N122에는 이미 표시돼 있다. | O27: — | P27: 계약서에 없음
A28: N28 | B28: 1차 | C28: 식사 속도 · 양 | D28: 입문 | E28: 밥은 작은 그릇에 담기 | F28: 밥은 작은 그릇에 담기 | G28: 12 | H28: 그릇이 작아지면 양은 줄고 포만감은 같아요. | I28: — | J28: 비만학회 행동치료(자극 조절) | K28: 섭식장애 | L28: 승인 | O28: — | P28: 계약서에 없음
A29: N29 | B29: 1차 | C29: 식사 속도 · 양 | D29: 입문 | E29: TV · 휴대폰 끄고 식사 | F29: 휴대폰 끄고 식사 | G29: 9 | H29: 화면을 보며 먹으면 얼마나 먹었는지 놓쳐요. | I29: — | J29: 비만학회 행동치료(자극 조절) | K29: 섭식장애 | L29: 승인 | O29: DIET-P-0066 | P29: 문구 그대로
A30: N30 | B30: 1차 | C30: 식사 속도 · 양 | D30: 기본 | E30: 한 입에 스무 번 씹기 | F30: 한 입에 스무 번 씹기 | G30: 12 | H30: 씹는 횟수가 늘면 속도가 자연히 느려져요. | I30: — | J30: 식사 속도 메타분석 · 20회는 통용값 | K30: 섭식장애 | L30: 확인 필요 | M30: 연하곤란 · 뇌졸중 후유증 | N30: 해롭지는 않으나 수행이 불가능한 집단이 있다. 연하곤란(R13)은 진단 층에서 제외돼 있고 뇌졸중 후유증(I69)은 심혈관질환 연결에 포함된다. 서비스 대상 정책에서 함께 볼 항목. | O30: — | P30: 계약서에 없음
A31: N31 | B31: 1차 | C31: 식사 속도 · 양 | D31: 기본 | E31: 밥은 젓가락으로 먹기 | F31: 밥은 젓가락으로 먹기 | G31: 11 | H31: 젓가락은 한 번에 덜 뜨게 해서 속도를 늦춰요. | I31: — | J31: 식사 속도 메타분석 | K31: 섭식장애 | L31: 확인 필요 | M31: 연하곤란 · 뇌졸중 후유증 | N31: 해롭지는 않으나 수행이 불가능한 집단이 있다. 연하곤란(R13)은 진단 층에서 제외돼 있고 뇌졸중 후유증(I69)은 심혈관질환 연결에 포함된다. 서비스 대상 정책에서 함께 볼 항목. | O31: — | P31: 계약서에 없음
A32: N32 | B32: 1차 | C32: 식사 속도 · 양 | D32: 도전 | E32: 밥 더 담지 않기 | F32: 밥 더 담지 않기 | G32: 9 | H32: 한 그릇에서 멈추는 습관이 과식을 막아요. | I32: — | J32: 식생활지침 수칙 4 | K32: 섭식장애 임신·수유 암 치료 중 | L32: 승인 | O32: — | P32: 계약서에 없음
A33: N33 | B33: 1차 | C33: 단백질 | D33: 입문 | E33: 아침에 달걀 하나 | F33: 아침에 달걀 하나 | G33: 9 | H33: 달걀 하나로 아침 단백질이 채워져요. | I33: 오전 진입 | J33: 영양소 섭취기준 · 식생활지침 수칙 1 | K33: 신장질환 | L33: 승인 | O33: DIET-P-0070 | P33: 문구 그대로
A34: N34 | B34: 1차 | C34: 단백질 | D34: 입문 | E34: 두유나 우유 한 잔 챙기기 | F34: 우유 · 두유 한 잔 | G34: 11 | H34: 마시는 단백질은 반찬이 없어도 챙길 수 있어요. | I34: — | J34: 식생활지침 수칙 1(우유 · 유제품) | K34: 신장질환 | L34: 승인 | O34: DIET-P-0071 | P34: 문구 그대로
A35: N35 | B35: 1차 | C35: 단백질 | D35: 기본 | E35: 생선 반찬 한 끼 | F35: 생선 반찬 한 끼 | G35: 9 | H35: 생선은 단백질과 좋은 지방을 함께 줘요. | I35: — | J35: 식생활지침 수칙 1 · 지질동맥경화학회 5판 | K35: 신장질환 통풍(2차) | L35: 승인 | O35: DIET-P-0072 | P35: 문구 그대로
A36: N36 | B36: 1차 | C36: 단백질 | D36: 기본 | E36: 두부 반 모 반찬으로 | F36: 두부 반 모 반찬으로 | G36: 11 | H36: 두부 반 모가 고기 한 접시 단백질과 비슷해요. | I36: — | J36: 영양소 섭취기준(콩류) | K36: 신장질환 | L36: 승인 | O36: DIET-P-0073 | P36: 근거대조서를 거쳐 연결
A37: N37 | B37: 1차 | C37: 단백질 | D37: 도전 | E37: 끼니마다 다른 단백질 반찬 | F37: 끼니마다 다른 단백질 | G37: 11 | H37: 고기 · 생선 · 달걀 · 콩을 돌리면 영양이 고르게 돼요. | I37: — | J37: 식생활지침 수칙 1 | K37: 신장질환 | L37: 승인 | O37: DIET-P-0074 | P37: 근거대조서를 거쳐 연결
A38: N38 | B38: 1차 | C38: 기름진 음식 | D38: 입문 | E38: 튀김 대신 구이 · 찜 한 끼 | F38: 튀김 대신 구이 · 찜 | G38: 12 | H38: 조리법만 바꿔도 지방이 절반 이하로 줘요. | I38: — | J38: 식생활지침 수칙 2 · 지질학회 5판 | K38: — | L38: 승인 | O38: DIET-P-0075 | P38: 문구 그대로
A39: N39 | B39: 1차 | C39: 기름진 음식 | D39: 입문 | E39: 삼겹살 대신 목살 · 안심 | F39: 삼겹살 대신 목살 | G39: 9 | H39: 같은 고기라도 부위로 포화지방이 크게 달라요. | I39: — | J39: 지질학회 5판(포화지방) | K39: — | L39: 승인 | O39: DIET-P-0076 | P39: 근거대조서를 거쳐 연결
A40: N40 | B40: 1차 | C40: 기름진 음식 | D40: 기본 | E40: 드레싱 · 마요네즈는 반만 | F40: 드레싱은 반만 | G40: 7 | H40: 샐러드의 지방은 대부분 드레싱에서 와요. | I40: — | J40: WHO 건강식(지방 30% 미만) | K40: — | L40: 승인 | O40: DIET-P-0077 | P40: 문구 그대로
A41: N41 | B41: 1차 | C41: 기름진 음식 | D41: 기본 | E41: 라면 대신 국수 · 밥 한 끼 | F41: 라면 대신 국수 · 밥 | G41: 12 | H41: 라면 한 봉지 지방이 하루 권고의 4분의 1이에요. | I41: — | J41: 식약처 영양표시 · WHO | K41: — | L41: 승인 | O41: DIET-P-0078 | P41: 문구 그대로
A42: N42 | B42: 1차 | C42: 기름진 음식 | D42: 도전 | E42: 튀김 없는 하루 | F42: 튀김 없는 하루 | G42: 8 | H42: 튀김을 하루 끊는 것이 포화지방을 줄이는 가장 큰 한 걸음이에요. | I42: — | J42: 지질학회 5판 | K42: — | L42: 승인 | O42: DIET-P-0079 | P42: 문구 그대로
A43: N43 | B43: 1차 | C43: 기름진 음식 | D43: 도전 | E43: 기름진 음식은 점심에만 | F43: 기름진 음식은 점심에만 | G43: 12 | H43: 저녁 지방은 활동으로 쓰이지 못하고 남아요. | I43: — | J43: 열량 배분 연구 · 지질학회 약함 | K43: — | L43: 수정 | N43: 이유 문장 완화 필요. 열량 배분 연구는 총열량 · 체중에 대한 것이지 지방을 낮에 먹으면 낫다는 근거가 아니다. 「낮에 먹는 쪽이 체중 관리에 유리했어요」 수준으로 낮춘다. | O43: — | P43: 계약서에 없음
A44: N44 | B44: 1차 | C44: 회복 풀 | D44: 회복 | E44: 따뜻한 물 한 잔으로 시작 | F44: 따뜻한 물 한 잔으로 시작 | G44: 14 | H44: 못 먹은 뒤엔 물부터 채우는 게 부담이 없어요. | I44: 오전 진입 | J44: 식생활지침 수칙 3(물) 약함 | K44: — | L44: 조건부 | M44: 심부전 · 투석 | N44: 수분 섭취를 늘리는 행동이다. 심부전(I50)과 투석(Z49 · Z99.2)은 수분 제한 대상이라 역방향이 된다. 상병코드 추천 ⑤가 「오늘 물 6잔류 문구가 있다면 제외 — 현재 세트에 없음」이라 적었는데, 확장으로 생겼다. | O44: — | P44: 계약서에 없음
A45: N45 | B45: 1차 | C45: 회복 풀 | D45: 회복 | E45: 과일 한 조각으로 빈 끼 메우기 | F45: 빈 끼는 우유나 두유 한 잔 | G45: 15 | H45: 과일은 준비 없이 바로 먹을 수 있는 회복 끼니예요. | I45: 오후 진입 | J45: 식생활지침 수칙 1 | K45: 신장 3기↑ (칼륨) | L45: 수정 | M45: 신장 3기↑(칼륨) · 당뇨병 | N45: 회복 풀은 결식을 메우는 자리인데 과일만으로는 단백질과 열량이 모자란다. 같은 회복 맥락에서 우유 · 두유가 낫다. | O45: DIET-P-0082 | P45: 근거대조서를 거쳐 연결
A46: N46 | B46: 1차 | C46: 부담 줄이기 풀 | D46: 부담 | E46: 커피 대신 따뜻한 차 한 잔 | F46: 커피 대신 따뜻한 차 한 잔 | G46: 15 | H46: 피곤한 날 카페인은 잠을 더 밀어내요. | I46: — | J46: 카페인 · 수면 실험(2013) | K46: — | L46: 승인 | O46: DIET-P-0083 | P46: 근거대조서를 거쳐 연결
A47: N47 | B47: 2차 | C47: 끼니 규칙 | D47: 입문 | E47: 일어나서 한 시간 안에 한 입 | F47: 일어나서 한 시간 안에 한 입 | G47: 16 | H47: 시간을 정해 두면 아침을 건너뛰기 어려워져요. | I47: 오전 진입 | J47: 식생활지침 수칙 5 | K47: — | L47: 승인 | O47: — | P47: 계약서에 없음
...

Sheet 신규금지규칙
A1: 질환 유형 | B1: 상병코드 | C1: 추가할 금지 문구 | D1: 임상 근거 | E1: 기존 문서 반영 위치
A2: 심부전 · 투석 | B2: I50 · Z49 · Z99.2 · Z94.0 | C2: N44 따뜻한 물 한 잔으로 시작 · N72 야식 생각나면 물 한 잔 먼저 · N106 물병 채워 두고 시작하기 · N186 목마르면 물 한 잔 먼저 · N189 미지근한 물부터 한 잔 | D2: 수분 섭취를 늘리는 행동. 심부전은 울혈 악화, 투석 환자는 체중 증가와 폐부종 위험. 심부전의 수분 제한은 개인차가 있으나 「더 마시라」는 방향은 어느 쪽에도 맞지 않는다. | E2: 상병코드 추천 ② 2-5 심혈관질환 금지 열 · ③ 투석 행
A3: 당뇨병(확진 전원) | B3: E10~E14 | C3: N27 저녁 뒤엔 먹지 않고 마무리 · N75 잠들기 전 2시간은 물만 · N48 아침 대신 바나나 하나 · N149 간식은 고구마 반 개로 | D3: 야간 공복 연장은 인슐린 · 설포닐우레아 사용자에게 야간 저혈당 위험. 처방 정보가 연동되지 않아 약물 종류를 알 수 없으므로 기존 당뇨 금지와 같은 원칙으로 확진 전원에 적용. 바나나 · 고구마는 혈당지수와 탄수화물량이 간식 한 번 분량을 넘는다. | E3: 상병코드 추천 ② 2-1 당뇨병 금지 열
A4: 만성 신장질환(전 단계) | B4: N18 · N19 | C4: N133 과자 대신 견과류 사 두기 · N160 간식은 과일 · 견과로만 · N166 간식도 단백질로 챙기기 · 확정 「과일은 한 줌만」 | D4: 견과류와 과일은 칼륨 · 인이 높다. 확정 세트의 「간식은 견과류 한 줌으로」 「채소 · 과일 한 접시 더」가 이미 같은 이유로 금지인데 동일 성격 문구에 빠져 있다. | E4: 상병코드 추천 ② 2-4 만성 신장질환 금지 열
A5: 위 절제 · 비만수술 | B5: Z90.3 · Z98.0 · K91.1 | C5: N157 밥 · 빵 · 면 모두 통곡으로 · N162 아침은 통곡물로 고정하기 | D5: 섬유질을 한 번에 크게 늘리면 소화 부담과 덤핑을 유발할 수 있다. N142에는 이미 표시돼 있어 일관성이 필요하다. | E5: 상병코드 추천 ③ 위 절제 · 비만수술 행
A6: 고혈압 · 만성 신장질환 | B6: I10~I15 · N18 · N19 | C6: N191 저녁은 차리기 쉬운 것으로(원안: 한 그릇 음식으로) | D6: 「한 그릇 음식」은 국밥 · 덮밥 · 라면을 떠올리게 해 나트륨이 높다. 문구를 조리 수고로 바꾸면 제한 없이 쓸 수 있으나, 원안을 유지한다면 제한이 필요하다. | E6: 상병코드 추천 ② 2-2 고혈압 · 2-4 신장질환
A7: 갑상선질환 (신규 검토) | B7: E05 · E06 · E03 | C7: N154 해조류 반찬 한 가지 → 삭제 권고 | D7: 미역 · 김은 요오드 함량이 매우 높다. 갑상선기능항진증과 자가면역 갑상선질환에서 문제가 된다. 갑상선은 현재 「가져오지 않음」이라 제한을 걸 수단이 없으므로, 금지 전용 유형으로 추가하든지 문구를 빼든지 택해야 한다. 문구 하나 때문에 질환 유형을 늘리는 것보다 빼는 쪽을 권한다. | E7: 상병코드 추천 ⑤ 가져오지 않는 것 · ⑨ 검토 포인트 신규
A8: 연하곤란 · 뇌졸중 후유증 | B8: R13 · I69 · G30 · F00~F03 | C8: N30 한 입에 스무 번 씹기 · N31 밥은 젓가락으로 먹기 (확인 필요) | D8: 해롭지는 않으나 수행이 불가능한 집단이 있다. 진단 층이 아니라 서비스 대상 정책에서 다룰 문제라는 기존 판단과 같은 성격이다. | E8: 상병코드 추천 ⑨-5 인지 · 연하 장애 대상 정책

Sheet 쟁점
A1: # | B1: 항목 | C1: 쟁점 | D1: 검수 의견 | E1: 결정 주체
A2: 1 | B2: 과일 문구의 범위 | C2: 과당 섭취가 해롭다는 지적에 따라 과일 문구를 줄일지 | D2: 구분해서 본다. WHO 당류 지침은 유리당(첨가당 · 주스)을 제한하며 통과일은 명시적으로 제외한다. 과당의 해로움 근거는 첨가 과당 · 액상과당 · 가당 음료에 대한 것이고, 통과일 섭취는 코호트에서 일관되게 심혈관 · 당뇨 위험 감소와 연관된다. 다만 「대체」가 아니라 「추가」로 권하는 문구는 당뇨 · 비만 사용자에게 열량과 당이 순증하므로 뺄 근거가 있다. 대체형(주스→생과일, 케이크→과일, 아이스크림→얼린 과일)은 유지, 추가형(N2 아침에 과일 한 조각, N45 빈 끼를 과일로)은 삭제 · 수정했다. | E2: 기획 · 의학팀
A3: 2 | B3: N26 야식 대신 일찍 잠자리로 | C3: 식이 축 문구인데 실제 행동은 취침이다 | D3: 수면 목표가 같은 행동을 낼 경우 두 타일에 같은 말이 나간다. 수면 축 설계 후 어디에 둘지 정한다. 그때까지 보류. | E3: 기획
A4: 3 | B4: N169 한 끼를 30분에 걸쳐 먹기 | C4: 기본 칸의 「20분 이상」과 10분 차이뿐 | D4: 단계 구분이 되는지 임상 판단 필요. 되지 않는다면 도전 칸은 다른 행동(예: 식사 중 두 번 멈추기)으로 채우는 편이 낫다. | E4: 의학팀
A5: 4 | B5: N167 붉은 고기 없는 하루 | C5: 지질 이득과 철결핍 빈혈 위험이 충돌 | D5: 지질동맥경화학회는 적색육 · 가공육 제한을 권고하고, 철결핍 빈혈에서는 헴철 급원이 줄어 불리하다. 제한 열에 둘 다 표시했으나 우선순위는 임상 판단이다. | E5: 의학팀
A6: 5 | B6: 「물만」 계열 세 문구 | C6: N24 · N75 · N165가 사실상 같은 행동 | D6: 취침 기준이고 근거(ACG 지침)가 분명한 N75만 남기고 둘을 삭제했다. N24의 「밤 9시」는 취침 시각이 제각각인 사용자에게 임의값이다. | E6: 기획
A7: 6 | B7: 통곡 전면 전환 세 문구 | C7: N142 · N157 · N159가 같은 행동 | D7: N159를 삭제했다. 같은 칸에 셋을 두면 회전의 의미가 없다. | E7: 기획
A8: 7 | B8: 근거 강도 「약함」 문구의 비중 | C8: 지침 수준 권고가 없는 문구가 세트에 섞여 있다 | D8: 「약함」 표시 자체는 유지하되, 같은 칸에 약함 문구만 남는 상황을 막아야 한다. 문구 선정에서 약함은 후순위로 두는 규칙을 검토한다. | E8: 기획 · 의학팀
A9: 8 | B9: 검수자 자격 | C9: 이 검수는 실제 의학팀 승인을 대체하지 않는다 | D9: 가정의학 임상 관점에서 지침 대조와 안전 검토를 수행한 결과이며, 문구 단위 최종 승인은 의학팀이 해야 한다. 특히 신규 금지 규칙 7건과 쟁점 4건은 의학팀 확인 전 반영하지 않는 것이 맞다. | E9: 의학팀
