Workbook

Sheet 안내
A1: 항목 | B1: 내용 | C1: 열1 | D1: 열2
A2: 발행 상태 | B2: 식이 개발 전달 데이터 계약 · v1.3.0 · 2026-10-14 (최초 발행 2026-09-23)
A3: 범위 | B3: 참조 데이터 정규화와 런타임 테이블 정의. 환자 데이터는 포함하지 않음
A4: 참조 데이터 | B4: maiReport_식이_참조설정데이터_v1.0.0.xlsx (2026-10-13)
A5: 규칙 기준 | B5: mai-report-식이_질문목표_상세기획_v1.0.0.html (2026-10-13)
A6: 검진 기준 | B6: maiReport_AI검진요약_기준범위_레퍼런스.html (2026-09-14). 공단 2026-01-07 별첨과 주요 1차 구간 대조
A7: 읽는 순서 | B7: 테이블정의 → 필드정의 → 구현기준 → 실제 데이터 시트 → 검증규칙
A8: NULL 처리 | B8: NULL은 거짓·0·임의 기본값으로 치환하지 않는다. 필수 입력이 없으면 해당 분기를 적용하지 않고 다음 우선순위로 이동한다.
A9: 데이터 계층 | B9: 참조 시트는 개발용 정규화 데이터. 런타임 테이블은 테이블·필드 정의만 제공
A10: 데이터 건수 | B10: ="질문 "&COUNTA(질문!A2:A100)&", 선택지 "&COUNTA(선택지!A2:A200)&", 목표문구 "&COUNTA(목표문구!A2:A999)&", 노출조건 "&COUNTA(노출조건!A2:A999)&", 질환규칙 "&COUNTA(질환규칙!A2:A100)&", 상병코드조건 "&COUNTA(상병코드조건!A2:A1000)&", 설정 "&COUNTA(설정!A2:A1000)&" · 식후 가능 문구 "&COUNTIF(노출조건!G2:G999,TRUE)&" · 보류 문구 "&COUNTIF(목표문구!C2:C999,"보류")
A11: 데이터 원칙 | B11: 문구·이유·코드·원본 메모를 보존한다. 명확한 단일 태그만 구조화하고 복합 조건은 원본 메모와 노출조건을 함께 읽는다.
A12: 임시 식별자 | B12: COND-nnn과 CFG-nnn은 원본 행 기반. 운영 DB 적재 전에 영속 ID 확정 필요
A13: 검진 자료 경계 | B13: 공단 3구간은 검진 배지용. 식이 목표는 검진 신호가 기존 축 문구 풀을 우선 선정. 또래 분포표는 별도 확정 필요
A14: 실행 경계 | B14: 검진일로부터 3개월 이내 결과만 식이 목표에 반영. 목표 축은 그날 회전 질문으로 고른 축과 같다. 그 축에 통과 문구가 없을 때만 직접 선택 → 진료정보 확인 → 검진 신호 → 일반 순서로 다음 축을 찾는다. 안전 제외는 출처와 무관하게 합산
A16: 바뀐 내용 · 2026-10-14
A17: v1.1.0 · v1.2.0 · v1.3.0에서 바꾼 것. 파일 이름은 v1.0.0 그대로 둔다.
A19: 항목 | B19: 전 | C19: 후 | D19: 바뀐 자리
A20: 목표 문구 227개 추가 | B20: 저녁·새벽에 쓸 수 있는 식후 문구가 15개뿐이라 입문 사용자 한 명이 60일 동안 저녁 9개, 새벽 7개 문구만 반복해서 봄(시뮬레이터) 입문 문구가 축마다 5~9개라 단계가 오르지 않는 사용자가 같은 문구를 자주 봄 | C20: DIET-P-0274~0500 227개 추가: 저녁·새벽 문구 · 입문 보강 · 새 표현 · 끼니 추천(아침추천 · 저녁추천, 샐러드는 「○○샐러드+1/2소스」) · 회복 · 부담 줄이기 모두 12자 이내 · 성격 확정 · 근거 출처 ID 기재 · 영문은 외주 번역 예정 시뮬레이터 기준 저녁 60일 9개 → 33개, 같은 문구 다시 보기까지 6일 → 32일 | D20: 목표문구 · 노출조건 시트 DIET-P-0274~0500 · 번역_en 추가 행 · 검증규칙 V-05 · V-53 · V-54
A21: 풀어 쓴 문구 추가 (v1.2.0) | B21: 목표 문구는 12자 타일 문구와 이유 한 줄뿐이라, 「세 끼 어제처럼 먹기」「아침추천: 시금치/오이」처럼 짧아서 무엇을 하라는 건지 알기 어려운 문구가 있음 | C21: 문구 403개 모두에 full_text(풀어 쓴 문구) 한 문장 추가 · 40자 이내 · 무엇을 어떻게 하면 되는지 바로 알 수 있게 씀 · 타일 문구·이유 한 줄·문구 버전은 그대로 / 예: 「세 끼 어제처럼 먹기」 → 「오늘도 어제와 비슷한 시간에 아침·점심·저녁 세 끼를 드세요.」 / 영문은 다음 차례 | D21: 목표문구 full_text 열 · 필드정의 diet_goal_phrase.full_text · diet_goal.full_text_snapshot · 검증규칙 V-05
A22: 세 번째 선택지 문구 바꿈 | B22: 고정 질문(DIET-Q-00) 세 번째 선택지가 「거의 못 먹음」. 코드(very_little_or_skipped)에는 걸렀다는 뜻도 담았지만 글자에는 드러나지 않아, 거른 사람과 조금 먹은 사람이 같은 답을 고르는지 알기 어려움 | C22: 「거의 못 먹거나 거름」으로 바꿈. 코드 · 점수(-1) · 순서는 그대로라 저장된 답과 집계는 바뀌지 않음. 11자라 선택지 5~7자 규칙의 예외. 영어는 「Barely ate or skipped」 | D22: 선택지 DIET-Q-00 3번 option_label · 번역_en OPTION very_little_or_skipped · 구현기준 R-10 · 검증규칙 V-52
A23: 고정 질문 선택지 문구 바꿈 (10-14) | B23: 고정 질문(DIET-Q-00) 선택지가 「평소대로 · 조금 적게 · 거의 못 먹거나 거름」이라 많이 먹은 날과 몇 입만 먹은 날을 어디에 눌러야 할지 글자로 드러나지 않았음 | C23: 「충분히 먹음 · 적게 · 몇 입만 · 못 먹거나 거름」으로 바꿈. 코드 · 점수 · 순서는 그대로. 몇 입만 먹은 끼니도 소식으로 보고 「적게 · 몇 입만」(less, 0점)에 넣으며 점수를 깎지 않음. 회복 목표는 이 답에서도 그대로 나감. 3번 코드 very_little_or_skipped는 이름과 달리 「못 먹거나 거름」, 곧 걸렀거나 먹지 못한 끼니만 뜻함 | D23: 선택지 DIET-Q-00 1~3번 option_label · 번역_en 11~13행
A24: 끼니별 식사 시각 단계 추가 (v1.3.0 · 10-14) | B24: 식사 시각을 받는 질문이 없어 자기돌봄 · 일상안정의 「식후 행동」 칸이 늘 비어 있었다. 고정 질문(DIET-Q-00)은 양만 묻는다 | C24: 고정 질문에 「충분히 먹음 · 적게 · 몇 입만」으로 답하면 같은 자리에서 「{끼니}은 언제쯤 드셨어요?」(점심·저녁 DIET-Q-08, 아침은 「아침은 몇 시쯤 드셨어요?」 DIET-Q-09)를 이어서 묻는다. 질문 1개로 세어 식이 최대 3문항 · 전체 최대 5문항. 버튼 3개(1시간 간격 · 10분 내림 · 끼니별 선택지 상한 시각) · 건너뛰기 없음 · 점수 없음. 어제 저녁 · 「못 먹거나 거름」 · 건강 앱 식사 기록이 있으면 묻지 않는다. 받은 답으로 식사 시각을 추정해 diet_meal_time에 저장한다 | D24: 질문 DIET-Q-08 · 09 · 선택지 6행 · 테이블정의 diet_meal_time · 필드정의(diet_question.question_role FOLLOW_UP, diet_question_state.slot_code MEAL_TIME, diet_answer.option_window_start/end, diet_meal_time 13열) · 구현기준 R-11 · 설정 CFG-072~085 · 설정파라미터 · 검증규칙 V-53 · V-55~V-58 · 번역_en 11행
A25: 식후 행동 판정 기준 추가 (10-14) | B25: 식사 시각은 받지만 식후에 걸었는지를 어떻게 판정하는지가 계약에 없었음 | C25: 걸음 기록으로 판정한다: 식후 관찰 시간 안 5분 초과 이어 걷기(분당 20보) · 합계 300보 · 운동 기록 시작 중 하나면 완료, 아니면 미완료, 걸음 기록이 없거나 식사 시각이 모름이면 모름. 계산식 전달 문서 v7.0이 판정을 서비스 몫으로 두므로 이 계약에서 정한다 | D25: 구현기준 R-12 · 설정 CFG-086~088 · 설정파라미터 · 검증규칙 V-59 · 필드정의 diet_meal_time.post_meal_action / post_meal_action_basis
A26: 시각 단계 선택지 글자 · 어제 저녁 질문 (10-14) | B26: 점심 · 저녁 선택지 큰 글자가 「오후 12:20 이후」처럼 시각이라 길고(5~7자 규칙 예외), 어제 저녁에는 시각을 묻지 않았음 | C26: 선택지 글자는 「1시간 이내 / 1~2시간 전 / 그보다 전」(5~7자 안), 작은 글씨 없음. 상한 · 하한에 걸린 동안은 시각 글자. 어제 저녁도 묻는다(DIET-Q-10 「어제 저녁은 몇 시쯤 드셨어요?」, 저녁 7시 · 8시 고정, CFG-089) — 일상안정이 최근 7일 식후 행동을 합산하므로 어제 값도 쓰임 | D26: 질문 DIET-Q-10 · 선택지 DIET-Q-08 label 3행 · DIET-Q-10 3행 · 설정 CFG-089 · 구현기준 R-11 · 검증규칙 V-53 · V-55 · V-56 · 필드정의 skip_reason · 번역_en
A27: 저녁 선택지 (10-14) | B27: 저녁을 오후 9시 뒤에 답하면 선택지가 9시에서 멈춰 10시에 먹은 사람은 고를 칸이 없고, 5시 하한 때문에 4시 반에 먹은 사람도 못 골랐음 | C27: 오후 9시까지는 「1시간 이내 / 1~2시간 전 / 그보다 전」(하한 4시로 내림, CFG-090), 9시가 지나서 답하면 「7시 이전 / 7시~9시 / 9시 이후」 고정(DIET-Q-11, CFG-089). 어제 저녁(DIET-Q-10)도 같은 고정 선택지로 통일. 모의 정확도는 1시간 칸만 쓸 때와 같고(30분 이내 77%), 5시 · 10시 식사가 모두 들어감 | D27: 질문 DIET-Q-11 · 선택지 DIET-Q-10 relabel · DIET-Q-11 3행 · 설정 CFG-076 · 077 · 089 · 090 · 구현기준 R-11 · 검증규칙 V-53 · V-55 · V-56 · 번역_en
A28: 식사 시각 추정 단순화 (10-14) | B28: 추정 순서에 걸음 멈춤 단서(CFG-079)와 지난 2주 평소 시각(CFG-080)이 있었음 | C28: 둘 다 1차에서 뺌. 추정은 건강 앱 식사 기록 → 선택지 범위의 가운데 두 단계. 건강 앱 기록은 끼니 구분이 없고 선택지 추정값은 가운데값이라 평소 시각이 믿을 만하지 않음. 식후 걸음 판정 결과(모의 87~89%)는 그대로 | D28: 구현기준 R-11 ⑤ · 검증규칙 V-57 · 설정 CFG-079 · 080 사용 안 함 · 필드정의 diet_meal_time

Sheet 테이블정의
A1: 테이블명 | B1: 데이터 시트 | C1: 계층 | D1: 저장 단위 | E1: 기본키 | F1: 용도 | G1: 상태
A2: diet_question | B2: 질문 | C2: 참조 | D2: 질문 ID + 버전 | E2: question_id,question_version | F2: 식이 질문 8종과 노출 역할 | G2: 조건부 사용
A3: diet_question_option | B3: 선택지 | C3: 참조 | D3: 질문 ID + 버전 + 선택지 순서 | E3: question_id,question_version,option_order | F3: 선택지 문구·코드·집계값 | G3: 조건부 사용
A4: diet_goal_phrase | B4: 목표문구 | C4: 참조 | D4: 문구 ID + 버전 | E4: phrase_id,phrase_version | F4: 목표 행동·이유·축·성격 | G4: 일반 문구는 노출 조건에 따라 적용; 검진 전용 연결 보류
A5: diet_phrase_applicability | B5: 노출조건 | C5: 참조 | D5: 문구 ID + 버전 | E5: phrase_id,phrase_version | F5: 문구별 시간대·평일·주말·명절·연휴 노출 조건 | G5: READY만 자동 후보. 시간·평일/주말은 실행 시점에 판정; 상황·명절 조건은 입력 자료가 없어 보류
A6: diet_disease_rule | B6: 질환규칙 | C6: 참조 | D6: 규칙 ID | E6: rule_id | F6: 원본 연결·금지 플래그와 추천 동작 분리 | G6: 규칙별 동작 적용; 진단 후보 조건 별도 검토
A7: diet_disease_axis | B7: 질환연결축 | C7: 참조 | D7: 규칙 ID + 질문 ID | E7: rule_id,question_id | F7: 질환 확인 후 우선할 질문 축 | G7: 사용자 질환 확인 후 규칙별 적용
A8: diet_disease_ban_nature | B8: 질환금지성격 | C8: 참조 | D8: 규칙 ID + 성격 | E8: rule_id,nature_code | F8: 진단 후보부터 제외할 문구 성격 | G8: STOP_ALL 우선; 그 외 성격별 제외
A9: diet_disease_code_condition | B9: 상병코드조건 | C9: 참조 | D9: 원본 조건 행 ID | E9: condition_id | F9: 진단 후보 생성용 코드·기간·횟수 조건 | G9: 동반 코드 논리 등 개별 조건 검토 필요
A10: diet_rule_setting | B10: 설정 | C10: 참조 | D10: 설정 ID | E10: setting_id | F10: 운영 값과 실행 가능 여부 분리 | G10: 문장형 규칙 구조화 필요
A11: diet_implementation_rule | B11: 구현기준 | C11: 관리 | D11: 기준 ID | E11: rule_id | F11: 확정된 화면·데이터 구현 규칙 | G11: v1.0.0 적용 기준
A12: diet_session | B12: 정의만 제공 | C12: 런타임 | D12: 사용자 + 세션 날짜 | E12: user_id,session_date | F12: 04시 경계의 하루 질문·목표 묶음 | G12: 구현 정의
... A40: diet_meal_time | B40: 정의만 제공 | C40: 런타임 | D40: 사용자 + 실제 끼니 날짜 + 끼니 종류 | E40: user_id,meal_date,meal_type | F40: 시각 단계 답(또는 건강 앱 기록)으로 추정한 끼니별 식사 시각과 식후 행동을 볼 시간 범위 | G40: 세션 종속. 어제 저녁 · 거른 끼니는 행을 만들지 않는다. 추정 순서는 구현기준 R-11

Sheet 필드정의
A1: 테이블명 | B1: 순서 | C1: 필드명 | D1: 한글명 | E1: 타입 | F1: 필수 | G1: 키 | H1: 허용값 | I1: 설명
A2: diet_question | B2: 1 | C2: question_id | D2: 질문 ID | E2: VARCHAR(20) | F2: Y | G2: PK
A3: diet_question | B3: 2 | C3: question_version | D3: 질문 버전 | E3: VARCHAR(10) | F3: Y | G3: PK
A4: diet_question | B4: 3 | C4: axis_name | D4: 행동 축 | E4: VARCHAR(40) | F4: Y
A5: diet_question | B5: 4 | C5: question_role | D5: 질문 역할 | E5: ENUM | F5: Y | H5: FIXED,ROTATING,CONFIRMATION,FOLLOW_UP | I5: FOLLOW_UP은 앞 질문의 답에 따라 같은 자리에서 이어 묻는 질문(식사 시각 단계). 질문 수에 1개로 센다
A6: diet_question | B6: 5 | C6: question_template | D6: 질문 문장 | E6: VARCHAR(120) | F6: Y
A7: diet_question | B7: 6 | C7: meal_scope_raw | D7: 물을 수 있는 끼니 원문 | E7: VARCHAR(40) | F7: Y
A8: diet_question | B8: 7 | C8: observation_scope | D8: 관찰 범위 | E8: TEXT | F8: Y
A9: diet_question | B9: 8 | C9: interpretation_limit | D9: 해석 한계 | E9: TEXT | F9: Y
A10: diet_question | B10: 9 | C10: source_row | D10: 원본 행 | E10: INTEGER | F10: Y
A11: diet_question_option | B11: 1 | C11: question_id | D11: 질문 ID | E11: VARCHAR(20) | F11: Y | G11: FK→diet_question
A12: diet_question_option | B12: 2 | C12: question_version | D12: 질문 버전 | E12: VARCHAR(10) | F12: Y | G12: FK→diet_question
A13: diet_question_option | B13: 3 | C13: option_order | D13: 선택지 순서 | E13: SMALLINT | F13: Y | G13: PK | H13: 1,2,3 | I13: 질문별 정확히 1, 2, 3. 세 선택지 모두 표시
A14: diet_question_option | B14: 4 | C14: option_code | D14: 선택지 코드 | E14: VARCHAR(50) | F14: Y
A15: diet_question_option | B15: 5 | C15: option_label | D15: 화면 문구 | E15: VARCHAR(40) | F15: Y
A16: diet_question_option | B16: 6 | C16: score_value | D16: 집계값 | E16: SMALLINT | F16: N | H16: -1,0,1,NULL | I16: NULL은 식사 시각처럼 상태 점수를 산출하지 않는 사실 응답에만 사용. 미응답은 선택지 아님
A17: diet_question_option | B17: 7 | C17: source_row | D17: 원본 행 | E17: INTEGER | F17: Y
A18: diet_goal_phrase | B18: 1 | C18: phrase_id | D18: 문구 ID | E18: VARCHAR(20) | F18: Y | G18: PK
A19: diet_goal_phrase | B19: 2 | C19: phrase_version | D19: 문구 버전 | E19: VARCHAR(10) | F19: Y | G19: PK
A20: diet_goal_phrase | B20: 3 | C20: source_status | D20: 원본 상태 | E20: ENUM | F20: Y | H20: 사용,보류
A21: diet_goal_phrase | B21: 4 | C21: pool_type | D21: 문구 풀 | E21: ENUM | F21: Y | H21: AXIS_STAGE,RECOVERY,LOW_BURDEN
A22: diet_goal_phrase | B22: 5 | C22: axis_question_id | D22: 축 질문 ID | E22: VARCHAR(20) | F22: N | G22: FK→diet_question
A23: diet_goal_phrase | B23: 6 | C23: stage_code | D23: 실천 단계 | E23: ENUM | F23: N | H23: INTRO,BASE,CHALLENGE | I23: INTRO 입문 · BASE 기본 · CHALLENGE 도전. 상승 조건은 검증규칙 V-42, 설정 CFG-068·CFG-069
A24: diet_goal_phrase | B24: 7 | C24: tile_text | D24: 타일 문구 | E24: VARCHAR(22) | F24: Y
A25: diet_goal_phrase | B25: 8 | C25: full_text | D25: 풀어 쓴 문구 | E25: VARCHAR(40) | F25: Y | I25: 타일 문구를 풀어 쓴 한 문장. 무엇을 어떻게 하면 되는지 처음 보는 사람도 바로 알 수 있게 쓴다. 띄어쓰기 포함 40자 이내, 마침표로 끝난다. 타일 문구에 없는 새 음식·분량을 덧붙이지 않는다. 화면 위치는 화면 확정 필요. 예: 「세 끼 어제처럼 먹기」 → 「오늘도 어제와 비슷한 시간에 아침·점심·저녁 세 끼를 드세요.」
A26: diet_goal_phrase | B26: 9 | C26: reason_text | D26: 이유 한 줄 | E26: TEXT | F26: Y
A27: diet_goal_phrase | B27: 10 | C27: nature_code | D27: 문구 성격 | E27: ENUM | F27: N | H27: REDUCE,FAST,INCREASE,FLUID,TEXTURE,NULL | I27: 한 문구에 한 값인 원본 제약 보존
A28: diet_goal_phrase | B28: 11 | C28: screening_only | D28: 검진 경계 전용 | E28: BOOLEAN | F28: N | H28: NULL | I28: 1차는 검진 전용 문구를 사용하지 않고 기존 축 풀을 재사용. 원본 공란 유지
A29: diet_goal_phrase | B29: 12 | C29: evidence_raw | D29: 근거 원문 | E29: TEXT | F29: Y
A30: diet_goal_phrase | B30: 13 | C30: source_note_raw | D30: 원본 메모 | E30: TEXT | F30: N | I30: 참조설정데이터의 적용 조건·해석 메모
A31: diet_goal_phrase | B31: 14 | C31: source_row | D31: 원본 행 | E31: INTEGER | F31: Y
A32: diet_phrase_applicability | B32: 1 | C32: phrase_id | D32: 문구 ID | E32: VARCHAR(20) | F32: Y | G32: PK/FK→diet_goal_phrase
A33: diet_phrase_applicability | B33: 2 | C33: phrase_version | D33: 문구 버전 | E33: VARCHAR(10) | F33: Y | G33: PK/FK→diet_goal_phrase
A34: diet_phrase_applicability | B34: 3 | C34: raw_tag | D34: 원본 노출 조건 | E34: VARCHAR(60) | F34: N | I34: 시간대·요일·명절 표시 원문
A35: diet_phrase_applicability | B35: 4 | C35: time_code | D35: 시간 조건 | E35: ENUM | F35: N | H35: ANY,EVENING,PRE_MIDNIGHT,MORNING_ENTRY,AFTERNOON_ENTRY,UNKNOWN
A36: diet_phrase_applicability | B36: 5 | C36: calendar_code | D36: 달력 조건 | E36: ENUM | F36: N | H36: ANY,WEEKDAY,WEEKEND,HOLIDAY,HOLIDAY_OR_EXTENDED | I36: WEEKDAY·WEEKEND는 목표 행동을 실행할 사용자 현지 달력 날짜로 판정. HOLIDAY·HOLIDAY_OR_EXTENDED는 자료 연결 전 보류; session_date와 혼동하지 않음
A37: diet_phrase_applicability | B37: 6 | C37: context_code | D37: 상황 조건 | E37: VARCHAR(40) | F37: N | H37: ANY | I37: v1.0.0에서는 상황 조건을 사용하지 않으며 ANY로 고정
A38: diet_phrase_applicability | B38: 7 | C38: after_dinner_eligible | D38: 저녁 식후 후보 | E38: BOOLEAN | F38: Y | H38: TRUE,FALSE | I38: 상세기획에 열거된 10개만 TRUE
A39: diet_phrase_applicability | B39: 8 | C39: parse_status | D39: 조건 변환 상태 | E39: ENUM | F39: Y | H39: READY | I39: 시간·달력 조건이 실행 가능한 자동 후보
A40: diet_phrase_applicability | B40: 9 | C40: context_match_mode | D40: 상황 결합 | E40: ENUM | F40: N | I40: v1.0.0 미사용
...

Sheet 구현기준
A1: 기준 ID | B1: 구분 | C1: 영향 테이블 | D1: 출처 | E1: 확정 규칙 | F1: 구현 메모 | G1: 상태
A2: R-01 | B2: 질문 UX | C2: diet_disease_confirmation,diet_question,diet_question_option | D2: 식이 질문·목표 상세기획 | E2: 식이 질문은 세션당 최대 2개다. 미확인 진료 질환이 있으면 확인 질문 1개를 먼저 내고, 현재 관리 중이면 해당 질환 회전 질문 1개, 아니요·모르겠어요이면 공통 고정 질문 1개를 둘째로 낸다. | F2: 질환 확인이 없는 날만 공통 고정 1개와 회전 최대 1개를 낸다. 한 세션에 세 번째 식이 질문은 생성하지 않는다. | G2: ACTIVE
A3: R-02 | B3: 끼니 시각 | C3: diet_session,diet_answer | D3: 설정 CFG-057 | E3: 00~04시·04~10시는 어제 저녁, 10~12시는 오늘 아침, 12~17시는 오늘 점심, 17~24시는 오늘 저녁을 묻는다. | F3: 경계 시각은 뒤 구간에 포함한다. | G3: ACTIVE
A4: R-03 | B4: 목표 축 | C4: user_condition_selection,diet_disease_confirmation | D4: 설정 CFG-059~063 | E4: 목표 축은 CFG-041로 고른 그날의 회전 질문 축과 같다. 그 축에 통과 문구가 없을 때만 직접 선택 → 확인된 진료정보 → 3개월 이내 검진 신호 → 일반 순으로 내려간다. 끼니 규칙 축(고정 질문 축)도 일반 축으로 보고 이 순서의 마지막에 후보로 둔다. | F4: 질문과 목표가 한 묶음으로 읽히도록 같은 축을 쓴다. 질환 축의 비중은 질문 축 선정(CFG-041, R-09)에서 이미 지켜지므로 목표에서 따로 올리지 않는다. | G4: ACTIVE
A5: R-04 | B5: 검진 유효기간 | C5: screening_diet_signal | D5: 설정 CFG-058 | E5: 목표 선정일 기준 검진일로부터 3개월 이내 결과만 식이 목표 선정에 사용한다. | F5: 미래·만료·검진일 미상 결과는 검진 분기에서 제외한다. | G5: ACTIVE
A6: R-05 | B6: 식후 목표 | C6: diet_phrase_applicability | D6: 노출조건 after_dinner_eligible | E6: ="17~24시와 00~04시 식후 목표는 READY이면서 after_dinner_eligible=true인 문구(노출조건 시트에서 true인 줄 전체, 지금 "&COUNTIF(노출조건!G2:G999,TRUE)&"개)를 후보로 사용한다. "&"17~24시는 모두 쓰고, 00~04시는 그중 시간 제한이 없거나(ANY) 저녁 전체 시간대(EVENING)인 문구만 쓴다(지금 "&(COUNTIFS(노출조건!G2:G999,TRUE,노출조건!D2:D999,"ANY")+COUNTIFS(노출조건!G2:G999,TRUE,노출조건!D2:D999,"EVENING"))&"개). "&"이 숫자는 노출조건 시트에서 자동으로 계산되므로 문구가 늘거나 줄어도 이 문장은 고치지 않는다." | F6: 질환 안전·시간·달력 조건을 다시 적용한다. | G6: ACTIVE
A7: R-06 | B7: 내정보 질환 | C7: profile_condition_diet_map | D7: 내정보질환매핑 | E7: 사용자 직접 선택지는 고혈압·당뇨병·이상지질혈증·만성 신장질환 네 개로 고정한다. | F7: 앞의 세 질환은 연결 축과 안전 제외, 만성 신장질환은 안전 제외에만 적용한다. | G7: ACTIVE
A8: R-07 | B8: 개인 조건 | C8: diet_goal | D8: 식이 질문·목표 상세기획 | E8: 개인 처방식·식품 알레르기 정보를 받지 않으므로 이를 전제로 한 개인화 목표를 생성하지 않는다. | F8: 특정 식품을 반드시 먹도록 지시하지 않는다. | G8: ACTIVE
A9: R-08 | B9: 노출 조건 | C9: diet_phrase_applicability | D9: 앱 진입 시각·현지 날짜·대한민국 명절 캘린더 | E9: 자동 노출 조건은 시간대, 평일·주말, 명절·연휴만 사용한다. 명절·연휴는 달력일자 시트의 날짜(calendar_code HOLIDAY)로 판정한다. 그 날짜에는 그날 목표 축에서 현재 단계 이하의 명절·연휴 문구가 통과하면 다른 문구보다 먼저 쓴다. 배달·편의점·회식·카페·사무실·급식·마트·야근·여행처럼 앱이 확인하지 않는 상황 조건은 사용하지 않는다. | F9: HOLIDAY와 HOLIDAY_OR_EXTENDED는 백엔드가 전달한 날짜 목록으로 판정한다. 날짜 목록이 없으면 해당 문구를 후보에서 제외한다. | G9: ACTIVE
A10: R-09 | B10: 질문 축 선정 | C10: diet_answer, diet_question, diet_question_state | D10: 설정 CFG-041 | E10: 회전 질문의 축은 질환·검진으로 연결된 축에서 고른다. 마지막으로 일반 축을 낸 뒤 연결 축을 모두 한 번씩 물었으면 그다음 날은 일반 축에서 하나 고른다. 같은 묶음 안에서는 28일 유효답이 가장 적은 축, 같으면 마지막으로 물은 지 오래된 축, 그다음 question_id 오름차순이다. 연결 축이 없으면 전체 축을 같은 순서로 본다. | F10: 목표 축(R-03)과 따로 계산한다. 한 값으로 둘 다 정하면 연결 축만 반복해 묻게 되어 나머지 축의 상태가 영원히 관찰 중에 머문다. | G10: ACTIVE
A11: R-10 | B11: 목표 고르는 순서 | C11: diet_goal | D11: 검증규칙 V-52 · 구현기준 R-03 · R-05 · 설정 CFG-041 | E11: 목표는 아래 순서로 고른다. ① 고정 질문 답이 「적게 · 몇 입만」「못 먹거나 거름」이면 회복 풀(17시 이후·새벽은 식후 가능 회복 문구만). ② 연동 수면이 5시간 미만이면 부담 줄이기 풀. ③ 그날 회전 질문과 같은 축의 문구(R-03). ④ 그 축에 통과 문구가 없으면 내정보 직접 선택 → 확인된 진료정보 → 3개월 이내 검진 신호 → 일반 순서로 다음 축을 찾는다(끼니 규칙 축도 일반 축에 포함). 모든 단계에서 질환 금지 성격·시간·달력 조건을 다시 적용하고, 끝까지 후보가 없으면 목표 없이 안내만 낸다. | F11: 회복은 상태·단계를 건너뛰고(단계 계산에도 세지 않음) 바로 꺼낸다. 질환 안전 제외는 이 순서보다 먼저 걸리고 완화되지 않는다. 상세기획의 옛 문장(회복 → 내정보 직접 선택 → 진료정보 → 검진 → 수면 → 일반)과 순서가 다르면 이 행이 기준이다. | G11: ACTIVE
A12: R-11 | B12: 식사 시각 단계 | C12: diet_question_state,diet_answer,diet_meal_time | D12: maiReport_식이_식사시각질문_v1.0.0.html (2026-10-14) · 설정 CFG-072~085 | E12: ① 고정 질문(DIET-Q-00) 답이 usual · less이고 그 끼니의 건강 앱 식사 기록이 없으면, 다음 질문으로 넘어가기 전 같은 자리에서 시각 단계를 낸다. 점심 · 저녁(오후 9시까지) DIET-Q-08, 아침 DIET-Q-09, 어제 저녁 DIET-Q-10, 저녁을 오후 9시가 지나서 답하면 DIET-Q-11. 질문 1개로 세어 진행 번호도 따로 센다. 선택지 3개 · 건너뛰기 없음 · 작은 글씨 없음. 어제 저녁도 묻는다 — 일상안정이 최근 7일의 식후 행동을 합산하므로 어제 값도 쓰인다. 어젯밤 같은 끼니에 이미 답했으면 재사용(V-30). ② 점심 · 저녁(9시까지) 선택지: 「1시간 이내 / 1~2시간 전 / 그보다 전」. 각 선택지의 시각 구간은 답한 시각을 10분 단위로 내리고(CFG-073) 1시간(CFG-072)씩 거꾸로 센다. 점심은 선택지 상한 시각 14:00(CFG-075)을 넘으면 「오후 1:00 이후 / 12:00~1:00 / 12:00 이전」으로 두고 시각 글자를 보여 준다. 「…이후」 칸의 끝은 끼니 끝 기본값(점심 14:00, CFG-091)으로 자른다. 선택지 하한 시각(점심 12:00 · 저녁 16:00, CFG-090) 아래로는 내려가지 않고, 하한에 걸린 동안도 시각 글자를 보여 준다. ③ 고정 선택지: 아침 「7시 이전 / 7시~8시 / 8시 이후」(CFG-078, 범위 6~7 · 7~8 · 8~10시 — 「8시 이후」는 아침 끝 기본값 10시까지). 저녁을 오후 9시(CFG-076)가 지나서 답할 때와 어제 저녁은 「7시 이전 / 7시~9시 / 9시 이후」(CFG-089, 범위 17~19 · 19~21 · 21~23시). 1시간 칸 3개로는 5시 식사와 10시 식사를 함께 덮을 수 없기 때문이다. ④ 저장: diet_answer에 option_code와 사용자가 본 구간(option_window_start/end)을 함께 저장한다. 점수 없음. ⑤ 추정(diet_meal_time): 그 끼니 시간대 안에 건강 앱 식사 기록이 있으면 그 시각(HIGH, 시각 단계를 묻지 않음) → 없으면 고른 선택지 범위의 가운데(MEDIUM). 범위는 끼니 시작 기본값(CFG-077)보다 이른 부분을 잘라 내고, 「…이후」 칸은 끼니 끝 기본값(CFG-091)까지로 본다. 저녁 「9시 이후」는 9시로 본다. 범위가 비어 있으면 UNKNOWN. 식후 관찰 시간은 건강 앱이면 그 시각부터 30분, 가운데값이면 범위 전체 + 30분(CFG-082). 걸음 단서(CFG-079) · 평소 시각(CFG-080)은 1차에서 쓰지 않는다. ⑥ 시각 단계 도중 앱을 나갔다 오면 식사 답은 두고 선택지는 다시 들어온 시각으로 새로 만든다(저녁은 9시 앞뒤로 질문이 바뀔 수 있다). 「오늘 답변 모두 보기」에서는 답할 때 보여 준 선택지를 그대로 다시 보여 준다. | F12: 참조 구현 diet-meal-time-v1.0.0.mjs(askMealTime · mealTimeOptions · estimateMealTime · judgePostMealAction). 선택지 글자는 모두 5~7자 안. 모의(저녁 19시±45분, 10%는 밤 9시 반 뒤 답): 30분 이내 적중 77%, 모름 2% — 1시간 칸만 쓰는 방식과 같고, 5시 · 10시 식사도 고를 수 있다. | G12: ACTIVE
A13: R-12 | B13: 식후 행동 판정 | C13: diet_meal_time | D13: maiReport_식이_식사시각질문_v1.0.0.html (2026-10-14) · 계산식 전달 문서(LJH) v7.0 README 5 · 8장 | E13: 식후에 걸었는지는 걸음 기록으로 판정한다. 계산식 전달 문서 v7.0은 「어떤 행동을 식후 행동으로 인정할지는 운영(서비스)이 정하고, 계산기는 완료 · 미완료 · 모름만 받는다」고 하므로 판정은 이 계약의 몫이다. ① 식사 시각이 UNKNOWN이면 UNKNOWN(NO_MEAL_TIME). ② diet_meal_time의 식후 관찰 시간(post_meal_window) 안에 운동 기록이 시작되면 COMPLETED(WORKOUT). ③ 관찰 시간에 분 단위 걸음 기록이 하나도 없으면 UNKNOWN(NO_STEP_DATA). ④ 분당 20보 이상이 5분 넘게 이어지면 COMPLETED(STEP_STREAK, CFG-086). ⑤ 합계 300보 이상이면 COMPLETED(STEP_TOTAL, CFG-087). ⑥ 그 밖에는 NOT_COMPLETED. 결과를 diet_meal_time.post_meal_action · post_meal_action_basis에 저장하고, 지표 계산기에는 completed/not_completed/unknown으로 넘긴다(자기돌봄 post_anchor_action_credit · 일상안정 action lane). UNKNOWN은 분모에서 뺀다. | F13: 참조 구현 diet-meal-time-v1.0.0.mjs judgePostMealAction. 5분 · 20보 · 300보는 임시값으로 출시 뒤 실제 데이터로 조정. 식후 걷기 「목표」 완료 버튼과는 별개다(목표 완료는 사용자가 누른 것만). | G13: ACTIVE

Sheet 질문
A1: question_id | B1: question_version | C1: axis_name | D1: question_role | E1: question_template | F1: meal_scope_raw | G1: observation_scope | H1: interpretation_limit | I1: source_row
A2: DIET-Q-00 | B2: 1.0.0 | C2: 끼니 규칙 | D2: FIXED | E2: {지난 끼니}은 평소만큼 드셨나요? | F2: 질환 확인 질문이 없는 날 또는 확인 답이 아니요·모르겠어요인 날 | G2: 지난 끼니의 상대적 섭취량. 결식 빈도·영양 충족도 아님 | H2: 고정 답은 회복 목표 분기에도 사용. 미섭취와 소량 섭취를 구분할 수 없음 | I2: 2
A3: DIET-Q-01 | B3: 1.0.0 | C3: 채소 | D3: ROTATING | E3: {지난 끼니}엔 채소 반찬을 얼마나 드셨나요? | F3: 모든 끼니 | G3: 채소 반찬을 먹은 정도(본인 판단). 중량·먹는 순서 아님 | H3: 본인이 느낀 양만 관찰. 400g 달성·혈당 개선으로 해석 금지 | I3: 3
A4: DIET-Q-02 | B4: 1.0.0 | C4: 단 음료 · 단 간식 | D4: ROTATING | E4: {지난 끼니} 전후 단 음료·간식은 몇 번이었나요? | F4: 모든 끼니 | G4: 단 음료·단 간식 섭취 횟수. 양·총당량 아님 | H4: 저혈당 처치용 섭취는 불리한 응답으로 평가하지 않음. 해당 위험 시 축 집계/목표 제한 | I4: 4
A5: DIET-Q-03 | B5: 1.0.0 | C5: 짠맛 · 국물 | D5: ROTATING | E5: {지난 끼니}엔 국물을 얼마나 드셨나요? | F5: 모든 끼니 | G5: 제공된 국물 중 먹은 대략 비율. 전체 나트륨 아님 | H5: 국물이 없는 끼니도 첫 답. 저나트륨 식사로 단정하지 않음 | I5: 5
A6: DIET-Q-04 | B6: 1.0.0 | C6: 식사 시각 | D6: ROTATING | E6: 어젯밤 야식은 얼마나 드셨나요? | F6: 04:00~10:00 진입에서만(전날 밤 회상) | G6: 전날 저녁 식사 후~당일 04:00 전의 야식 자기보고 양(조금 / 배불리). 오늘 아침 식사는 제외. 위해성·수면 영향 판정 아님 | H6: 야식 여부·양만 저장. 필요한 간식·교대근무 상황은 구분 불가. 상태 점수 산출 중지 | I6: 6
A7: DIET-Q-05 | B7: 1.0.0 | C7: 식사 속도 · 양 | D7: ROTATING | E7: {지난 끼니} 후 배부름은 어땠나요? | F7: 모든 끼니 | G7: 식후 주관적 포만감. 속도·열량 아님 | H7: 체중감량 필요·속도 과다로 해석 금지 | I7: 7
A8: DIET-Q-06 | B8: 1.0.0 | C8: 단백질 | D8: ROTATING | E8: {지난 끼니}엔 단백질류(고기·생선·달걀 등)를 드셨나요? | F8: 모든 끼니 | G8: 단백질 식품 섭취 여부와 맛보기 구분. 필요량 충족 아님 | H8: 어제 결식 후 단백질 질문 강제 분기 제거. 개인 식사 제한 우선 | I8: 8
A9: DIET-Q-07 | B9: 1.0.0 | C9: 기름진 음식 | D9: ROTATING | E9: {지난 끼니}엔 튀긴 음식을 드셨나요? | F9: 모든 끼니 | G9: 튀긴 음식 섭취 여부와 맛보기 구분. 총지방·포화지방량 아님 | H9: 식품 존재 여부만 관찰. 지방 부족/과다 진단 금지 | I9: 9
A10: DIET-Q-90 | B10: 1.0.0 | C10: 질환 확인 | D10: CONFIRMATION | E10: {질환명}을 진단받았거나 관리 중이신가요? | F10: 해당 없음. 미확인 진료 질환이 있는 세션의 첫째 질문으로만 노출 | G10: 해당 질환을 진단받았거나 지금 관리하고 있는지에 대한 자기보고. 임상 확진 여부 아님 | H10: 자가 응답이므로 임상 확진이 아니다. 아니요·모르겠어요가 질환 없음을 뜻하지 않으며 후보 단계의 문구 금지는 그대로 유지된다. 축 점수로 집계하지 않는다
A11: DIET-Q-08 | B11: 1.0.0 | C11: 식사 시각 단계 | D11: FOLLOW_UP | E11: {끼니}은 언제쯤 드셨어요? | F11: 오늘 점심(12~17시) · 오늘 저녁(17시~오후 9시에 답할 때). 고정 질문 DIET-Q-00에 usual · less로 답한 바로 뒤. 저녁을 오후 9시가 지나서 답하면 DIET-Q-11로 대신한다. very_little_or_skipped 답, 건강 앱 식사 기록이 있는 끼니에는 내지 않는다 | G11: 그 끼니를 먹은 시각의 대략 범위(1시간 구간). 선택지 글자는 「1시간 이내 / 1~2시간 전 / 그보다 전」으로 고정이고, 아래 작은 글씨로 시각 구간(답한 시각 기준, CFG-072~076)을 보여 준다. 상한 · 하한에 걸린 동안은 시각 글자를 크게 쓰고 작은 글씨를 뺀다 | H11: 점수 없음. 좋음 · 나쁨 등급 · 축 상태를 만들지 않는다. 식후 행동 판정(자기돌봄 · 일상안정)의 입력으로만 쓴다. 사실 빈도 저장 원칙(CFG-044)은 그대로
A12: DIET-Q-09 | B12: 1.0.0 | C12: 식사 시각 단계 | D12: FOLLOW_UP | E12: 아침은 몇 시쯤 드셨어요? | F12: 오늘 아침(10~12시). 고정 질문 DIET-Q-00에 usual · less로 답한 바로 뒤. very_little_or_skipped 답, 건강 앱 식사 기록이 있는 끼니에는 내지 않는다 | G12: 아침을 먹은 시각의 대략 범위. 버튼은 7시 · 8시 정각으로 고정(CFG-078). 아침 질문은 10시가 넘어야 나와 선택지 상한 시각(9시)을 늘 지난 뒤이기 때문 | H12: DIET-Q-08과 같다. 「8시 이후」 선택 비율이 30%를 넘으면 경계를 다시 본다(CFG-084)
A13: DIET-Q-10 | B13: 1.0.0 | C13: 식사 시각 단계 | D13: FOLLOW_UP | E13: 어제 저녁은 몇 시쯤 드셨어요? | F13: 어제 저녁(00~10시 진입). 고정 질문 DIET-Q-00에 usual · less로 답한 바로 뒤. 어젯밤 같은 끼니에 이미 답했으면 재사용(V-30)하고 다시 묻지 않는다 | G13: 어제 저녁을 먹은 시각의 대략 범위. 선택지는 「7시 이전 / 7시~9시 / 9시 이후」 고정(CFG-089). 하루 지난 끼니라 답한 시각에서 거꾸로 세지 않는다 | H13: 일상안정은 최근 7일의 식후 행동을 합산하므로 어제 값도 들어간다. 점수 없음. 모름이면 계산에서 빠진다
A14: DIET-Q-11 | B14: 1.0.0 | C14: 식사 시각 단계 | D14: FOLLOW_UP | E14: 저녁은 몇 시쯤 드셨어요? | F14: 오늘 저녁을 오후 9시(선택지 상한, 10분 내림 기준)가 지나서 답할 때. 고정 질문 DIET-Q-00에 usual · less로 답한 바로 뒤 | G14: 저녁을 먹은 시각의 대략 범위. 선택지는 「7시 이전 / 7시~9시 / 9시 이후」 고정(CFG-089). 1시간 칸 3개로는 5시 식사와 10시 식사를 다 덮을 수 없어 늦게 답한 날은 2시간 칸을 쓴다 | H14: 점수 없음. 칸이 2시간이라 걸음 단서 · 평소 시각이 없으면 가운데값 오차가 최대 1시간. 모름이면 계산에서 빠진다

Sheet 선택지
A1: question_id | B1: question_version | C1: option_order | D1: option_code | E1: option_label | F1: score_value | G1: source_row | H1: 설명
A2: DIET-Q-00 | B2: 1.0.0 | C2: 1 | D2: usual | E2: 충분히 먹음 | F2: 1 | G2: 2
A3: DIET-Q-00 | B3: 1.0.0 | C3: 2 | D3: less | E3: 적게 · 몇 입만 | F3: 0 | G3: 2
A4: DIET-Q-00 | B4: 1.0.0 | C4: 3 | D4: very_little_or_skipped | E4: 못 먹거나 거름 | F4: -1 | G4: 2
A5: DIET-Q-01 | B5: 1.0.0 | C5: 1 | D5: two_or_more | E5: 충분히 먹음 | F5: 1 | G5: 3
A6: DIET-Q-01 | B6: 1.0.0 | C6: 2 | D6: one | E6: 조금 먹음 | F6: 0 | G6: 3
A7: DIET-Q-01 | B7: 1.0.0 | C7: 3 | D7: none | E7: 먹지 않음 | F7: -1 | G7: 3
A8: DIET-Q-02 | B8: 1.0.0 | C8: 1 | D8: none | E8: 없었어요 | F8: 1 | G8: 4
A9: DIET-Q-02 | B9: 1.0.0 | C9: 2 | D9: once | E9: 한 번 | F9: 0 | G9: 4
A10: DIET-Q-02 | B10: 1.0.0 | C10: 3 | D10: twice_or_more | E10: 두 번 이상 | F10: -1 | G10: 4
A11: DIET-Q-03 | B11: 1.0.0 | C11: 1 | D11: none | E11: 먹지 않음 | F11: 1 | G11: 5
A12: DIET-Q-03 | B12: 1.0.0 | C12: 2 | D12: half_or_less | E12: 절반 이하 | F12: 0 | G12: 5
A13: DIET-Q-03 | B13: 1.0.0 | C13: 3 | D13: more_than_half | E13: 절반 넘게 | F13: -1 | G13: 5
A14: DIET-Q-04 | B14: 1.0.0 | C14: 1 | D14: none | E14: 먹지 않음 | G14: 6
A15: DIET-Q-04 | B15: 1.0.0 | C15: 2 | D15: light | E15: 조금 먹음 | G15: 6
A16: DIET-Q-04 | B16: 1.0.0 | C16: 3 | D16: meal_sized | E16: 배불리 먹음 | G16: 6
A17: DIET-Q-05 | B17: 1.0.0 | C17: 1 | D17: comfortable | E17: 편안했어요 | F17: 1 | G17: 7
A18: DIET-Q-05 | B18: 1.0.0 | C18: 2 | D18: somewhat_full | E18: 조금 배불렀어요 | F18: 0 | G18: 7
A19: DIET-Q-05 | B19: 1.0.0 | C19: 3 | D19: too_full | E19: 많이 배불렀어요 | F19: -1 | G19: 7
A20: DIET-Q-06 | B20: 1.0.0 | C20: 1 | D20: ate | E20: 먹었어요 | F20: 1 | G20: 8
A21: DIET-Q-06 | B21: 1.0.0 | C21: 2 | D21: tasted_only | E21: 맛만 봤어요 | F21: 0 | G21: 8
A22: DIET-Q-06 | B22: 1.0.0 | C22: 3 | D22: absent | E22: 안 먹었어요 | F22: -1 | G22: 8
A23: DIET-Q-07 | B23: 1.0.0 | C23: 1 | D23: absent | E23: 안 먹었어요 | F23: 1 | G23: 9
A24: DIET-Q-07 | B24: 1.0.0 | C24: 2 | D24: tasted_only | E24: 맛만 봤어요 | F24: 0 | G24: 9
A25: DIET-Q-07 | B25: 1.0.0 | C25: 3 | D25: ate | E25: 먹었어요 | F25: -1 | G25: 9
A26: DIET-Q-90 | B26: 1.0.0 | C26: 1 | D26: confirmed | E26: 네
A27: DIET-Q-90 | B27: 1.0.0 | C27: 2 | D27: denied | E27: 아니요
A28: DIET-Q-90 | B28: 1.0.0 | C28: 3 | D28: unknown | E28: 모르겠어요
A29: DIET-Q-08 | B29: 1.0.0 | C29: 1 | D29: within_1h | E29: 1시간 이내 | H29: 점심·저녁. 글자는 고정, 구간 「{t0} 이후」({t0}=답한 시각(10분 내림)−1시간)는 저장용. 상한·하한에 걸린 동안은 시각 글자(「1시 이후 / 12시~1시 사이 / 12시 이전」, 낮 12시대는 「12시 이후 / 11시~12시 사이 / 11시 이전」)를 보여 줌
A30: DIET-Q-08 | B30: 1.0.0 | C30: 2 | D30: one_to_two_h | E30: 1~2시간 전 | H30: 구간 「{t1}~{t0}」({t1}={t0}−1시간)는 저장용
A31: DIET-Q-08 | B31: 1.0.0 | C31: 3 | D31: earlier | E31: 그보다 전 | H31: 구간 「{t1} 이전」은 저장용
A32: DIET-Q-09 | B32: 1.0.0 | C32: 1 | D32: before_7 | E32: 7시 이전 | H32: 아침 고정. 작은 글씨 없음
A33: DIET-Q-09 | B33: 1.0.0 | C33: 2 | D33: seven_to_eight | E33: 7시~8시 | H33: 아침 고정
A34: DIET-Q-09 | B34: 1.0.0 | C34: 3 | D34: after_8 | E34: 8시 이후 | H34: 아침 고정
A35: DIET-Q-10 | B35: 1.0.0 | C35: 1 | D35: before_7 | E35: 7시 이전 | H35: 어제 저녁 고정. 범위 17:00~19:00
A36: DIET-Q-10 | B36: 1.0.0 | C36: 2 | D36: seven_to_nine | E36: 7시~9시 | H36: 범위 19:00~21:00
A37: DIET-Q-10 | B37: 1.0.0 | C37: 3 | D37: after_9 | E37: 9시 이후 | H37: 범위 21:00~23:00. 추정은 21:00(9시에 먹은 것으로 봄)
A38: DIET-Q-11 | B38: 1.0.0 | C38: 1 | D38: before_7 | E38: 7시 이전 | H38: 저녁 9시 뒤 고정. 범위 17:00~19:00
A39: DIET-Q-11 | B39: 1.0.0 | C39: 2 | D39: seven_to_nine | E39: 7시~9시 | H39: 범위 19:00~21:00
A40: DIET-Q-11 | B40: 1.0.0 | C40: 3 | D40: after_9 | E40: 9시 이후 | H40: 범위 21:00~23:00. 추정은 21:00(9시에 먹은 것으로 봄)

Sheet 질환규칙
A1: rule_id | B1: disease_name | C1: release_phase | D1: link_enabled | E1: ban_enabled | F1: confirmation_enabled | G1: confirmation_label | H1: ban_reason | I1: recommendation_action | J1: action_basis | K1: source_row
A2: DX-01 | B2: 당뇨병 | C2: 1차 | D2: TRUE | E2: TRUE | F2: TRUE | G2: 당뇨병 | H2: 저혈당 처치 우선. 공복 연장과 식사·탄수화물 일률 감량을 자동으로 내지 않는다 | I2: EXCLUDE_PHRASE | J2: 원본 link_enabled·ban_enabled 조합에서 파생 | K2: 2
A3: DX-02 | B3: 고혈압 | C3: 1차 | D3: TRUE | E3: FALSE | F3: TRUE | G3: 고혈압 | I3: LINK_ONLY | J3: 원본 link_enabled·ban_enabled 조합에서 파생 | K3: 3
A4: DX-03 | B4: 이상지질혈증 | C4: 1차 | D4: TRUE | E4: FALSE | F4: TRUE | G4: 고지혈증(이상지질혈증) | I4: LINK_ONLY | J4: 원본 link_enabled·ban_enabled 조합에서 파생 | K4: 4
A5: DX-04 | B5: 이상지질혈증 · 고중성지방 | C5: 1차 | D5: TRUE | E5: FALSE | F5: TRUE | G5: 고지혈증(이상지질혈증) | I5: LINK_ONLY | J5: 원본 link_enabled·ban_enabled 조합에서 파생 | K5: 5
A6: DX-05 | B6: 만성 신장질환 | C6: 1차 | D6: FALSE | E6: TRUE | F6: TRUE | G6: 만성 신장질환 | H6: 칼륨·인·단백질·수분은 병기·검사·투석·영양상태별로 개별화한다. 정보를 확인하기 전에는 섭취 증감·수분 목표를 자동으로 내지 않는다 | I6: EXCLUDE_PHRASE | J6: 연결 축 없음. 금지만 적용한다(내정보질환매핑 SAFETY_ONLY와 맞춤) | K6: 6
A7: DX-06 | B7: 심혈관질환 | C7: 1차 | D7: TRUE | E7: TRUE | F7: TRUE | G7: 심장 · 뇌혈관 질환 | H7: 심부전은 처방된 수분 계획이 우선이다 | I7: EXCLUDE_PHRASE | J7: 원본 link_enabled·ban_enabled 조합에서 파생 | K7: 7
A8: DX-07 | B8: 지방간 | C8: 1차 | D8: TRUE | E8: FALSE | F8: TRUE | G8: 지방간 | I8: LINK_ONLY | J8: 원본 link_enabled·ban_enabled 조합에서 파생 | K8: 8
A9: DX-08 | B9: 임신 · 산후 · 수유 | C9: 1차 | D9: FALSE | E9: TRUE | F9: FALSE | H9: 전문가의 개인 영양 계획을 확인하기 전에는 일반 감량·공복·증량을 자동으로 내지 않는다 | I9: EXCLUDE_PHRASE | J9: ban_reason과 맞춘 값. 연결=False는 이 질환으로 목표를 몰아주지 않는다는 뜻이지 목표를 만들지 말라는 뜻이 아니다. 후보가 0이 되면 안내 상태로 끝난다 | K9: 9
A10: DX-09 | B10: 섭식장애 | C10: 1차 | D10: FALSE | E10: TRUE | F10: FALSE | H10: 전문가의 개인 영양 계획을 확인하기 전에는 일반 감량·공복·증량을 자동으로 내지 않는다 | I10: EXCLUDE_PHRASE | J10: ban_reason과 맞춘 값. 연결=False는 이 질환으로 목표를 몰아주지 않는다는 뜻이지 목표를 만들지 말라는 뜻이 아니다. 후보가 0이 되면 안내 상태로 끝난다 | K10: 10
A11: DX-10 | B11: 영양결핍 · 저체중 | C11: 1차 | D11: FALSE | E11: TRUE | F11: FALSE | H11: 전문가의 개인 영양 계획을 확인하기 전에는 일반 감량·공복·증량을 자동으로 내지 않는다 | I11: EXCLUDE_PHRASE | J11: ban_reason과 맞춘 값. 연결=False는 이 질환으로 목표를 몰아주지 않는다는 뜻이지 목표를 만들지 말라는 뜻이 아니다. 후보가 0이 되면 안내 상태로 끝난다 | K11: 11
A12: DX-11 | B12: 악성신생물 치료 중 | C12: 1차 | D12: FALSE | E12: TRUE | F12: FALSE | H12: 전문가의 개인 영양 계획을 확인하기 전에는 일반 감량·공복·증량을 자동으로 내지 않는다 | I12: EXCLUDE_PHRASE | J12: ban_reason과 맞춘 값. 연결=False는 이 질환으로 목표를 몰아주지 않는다는 뜻이지 목표를 만들지 말라는 뜻이 아니다. 후보가 0이 되면 안내 상태로 끝난다 | K12: 12
A13: DX-12 | B13: 위 절제 · 비만수술 상태 | C13: 1차 | D13: FALSE | E13: TRUE | F13: FALSE | H13: 전문가의 개인 영양 계획을 확인하기 전에는 일반 감량·공복·증량을 자동으로 내지 않는다 | I13: EXCLUDE_PHRASE | J13: ban_reason과 맞춘 값. 연결=False는 이 질환으로 목표를 몰아주지 않는다는 뜻이지 목표를 만들지 말라는 뜻이 아니다. 후보가 0이 되면 안내 상태로 끝난다 | K13: 13
A14: DX-18 | B14: 투석 · 이식 | C14: 1차 | D14: FALSE | E14: TRUE | F14: FALSE | H14: 칼륨·인·단백질·수분은 병기·검사·투석·영양상태별로 개별화한다. 정보를 확인하기 전에는 증량·감량을 자동으로 내지 않는다 | I14: EXCLUDE_PHRASE | J14: ban_reason과 맞춘 값. 연결=False는 이 질환으로 목표를 몰아주지 않는다는 뜻이지 목표를 만들지 말라는 뜻이 아니다. 후보가 0이 되면 안내 상태로 끝난다 | K14: 14
A15: DX-20 | B15: 연하장애 | C15: 1차 | D15: FALSE | E15: TRUE | F15: FALSE | H15: 삼킴이 어려운 상태에서는 음식의 양·속도·질감을 개인 평가 없이 자동으로 권하지 않는다. 묽은 액체는 후두가 닫히기 전에 기도로 넘어가기 쉬워 물·차 권유도 막는다 | I15: EXCLUDE_PHRASE | J15: ban_reason과 맞춘 값. 연결=False는 이 질환으로 목표를 몰아주지 않는다는 뜻이지 목표를 만들지 말라는 뜻이 아니다. 후보가 0이 되면 안내 상태로 끝난다 | K15: 15

Sheet 질환연결축
A1: rule_id | B1: question_id | C1: source_row
A2: DX-01 | B2: DIET-Q-01 | C2: 2
A3: DX-01 | B3: DIET-Q-02 | C3: 2
A4: DX-01 | B4: DIET-Q-05 | C4: 2
A5: DX-02 | B5: DIET-Q-03 | C5: 3
A6: DX-02 | B6: DIET-Q-01 | C6: 3
A7: DX-03 | B7: DIET-Q-07 | C7: 4
A8: DX-03 | B8: DIET-Q-05 | C8: 4
A9: DX-04 | B9: DIET-Q-07 | C9: 5
A10: DX-04 | B10: DIET-Q-05 | C10: 5
A11: DX-04 | B11: DIET-Q-02 | C11: 5
A12: DX-06 | B12: DIET-Q-03 | C12: 7
A13: DX-06 | B13: DIET-Q-07 | C13: 7
... A16: DX-07 | B16: DIET-Q-05 | C16: 8

Sheet 질환금지성격
A1: rule_id | B1: nature_code | C1: source_row
A2: DX-01 | B2: FAST | C2: 2
A3: DX-01 | B3: REDUCE | C3: 2
A4: DX-05 | B4: INCREASE | C4: 6
A5: DX-05 | B5: REDUCE | C5: 6
A6: DX-06 | B6: FLUID | C6: 7
A7: DX-08 | B7: REDUCE | C7: 9
A8: DX-08 | B8: FAST | C8: 9
A9: DX-08 | B9: INCREASE | C9: 9
A10: DX-09 | B10: REDUCE | C10: 10
A11: DX-09 | B11: FAST | C11: 10
A12: DX-09 | B12: INCREASE | C12: 10
A13: DX-10 | B13: REDUCE | C13: 11
... A29: DX-05 | B29: FLUID | C29: 6

Sheet 상병코드조건
A1: condition_id | B1: rule_id | C1: diagnosis_code | D1: code_label | E1: match_type | F1: range_end | G1: window_months | H1: min_occurrences | I1: primary_only | J1: companion_codes_raw | K1: condition_note | L1: source_row
A2: COND-002 | B2: DX-01 | C2: E11 | D2: 2형 당뇨병 | E2: PREFIX | G2: 12 | H2: 2 | I2: TRUE | K2: 2형 당뇨병. 세부 4자리 포함 | L2: 2
A3: COND-003 | B3: DX-01 | C3: E13 | D3: 기타 명시된 당뇨병 | E3: PREFIX | G3: 12 | H3: 2 | I3: TRUE | L3: 3
A4: COND-004 | B4: DX-01 | C4: E14 | D4: 상세불명의 당뇨병 | E4: PREFIX | G4: 12 | H4: 2 | I4: TRUE | L4: 4
A5: COND-005 | B5: DX-01 | C5: E10 | D5: 1형 당뇨병 | E5: PREFIX | G5: 12 | H5: 2 | I5: TRUE | K5: 1형 당뇨병 | L5: 5
A6: COND-006 | B6: DX-02 | C6: I10 | D6: 본태성(원발성) 고혈압 | E6: PREFIX | G6: 12 | H6: 2 | I6: TRUE | L6: 6
A7: COND-007 | B7: DX-02 | C7: I11 | D7: 고혈압성 심장질환 | E7: PREFIX | G7: 12 | H7: 2 | I7: TRUE | L7: 7
A8: COND-008 | B8: DX-02 | C8: I15 | D8: 이차성 고혈압 | E8: PREFIX | G8: 12 | H8: 2 | I8: TRUE | L8: 8
A9: COND-009 | B9: DX-03 | C9: E78.0 | D9: 순수 고콜레스테롤혈증 | E9: EXACT | G9: 12 | H9: 2 | I9: TRUE | L9: 9
A10: COND-010 | B10: DX-03 | C10: E78.4 | D10: 기타 고지질혈증 | E10: EXACT | G10: 12 | H10: 2 | I10: TRUE | L10: 10
A11: COND-011 | B11: DX-03 | C11: E78.5 | D11: 상세불명의 고지질혈증 | E11: EXACT | G11: 12 | H11: 2 | I11: TRUE | K11: E78.6은 쓰지 않는다 | L11: 11
A12: COND-012 | B12: DX-04 | C12: E78.1 | D12: 순수 고글리세리드혈증 | E12: EXACT | G12: 12 | H12: 2 | I12: TRUE | K12: 고중성지방 | L12: 12
A13: COND-013 | B13: DX-04 | C13: E78.2 | D13: 혼합성 고지질혈증 | E13: EXACT | G13: 12 | H13: 2 | I13: TRUE | K13: 고중성지방 | L13: 13
A14: COND-014 | B14: DX-05 | C14: N18.3 | D14: 만성 신장질환 3기 | E14: EXACT | G14: 12 | H14: 1 | I14: TRUE | K14: 3기 이상은 1회로 족하다 | L14: 14
A15: COND-015 | B15: DX-05 | C15: N18.4 | D15: 만성 신장질환 4기 | E15: EXACT | G15: 12 | H15: 1 | I15: TRUE | L15: 15
A16: COND-016 | B16: DX-05 | C16: N18.5 | D16: 만성 신장질환 5기 | E16: EXACT | G16: 12 | H16: 1 | I16: TRUE | L16: 16
A17: COND-017 | B17: DX-05 | C17: N18.1 | D17: 만성 신장질환 1기 | E17: EXACT | G17: 12 | H17: 2 | I17: TRUE | L17: 17
A18: COND-018 | B18: DX-05 | C18: N18.2 | D18: 만성 신장질환 2기 | E18: EXACT | G18: 12 | H18: 2 | I18: TRUE | L18: 18
A19: COND-019 | B19: DX-05 | C19: N18.9 | D19: 상세불명의 만성 신장질환 | E19: EXACT | G19: 12 | H19: 2 | I19: TRUE | L19: 19
A20: COND-020 | B20: DX-05 | C20: N19 | D20: 상세불명의 신장기능상실 | E20: PREFIX | G20: 12 | H20: 2 | I20: TRUE | L20: 20
A21: COND-021 | B21: DX-05 | C21: E11.2 | D21: 2형 당뇨병 · 신장 합병증 동반 | E21: EXACT | G21: 12 | H21: 2 | I21: TRUE | K21: 당뇨병성 신장합병증 | L21: 21
A22: COND-022 | B22: DX-05 | C22: E14.2 | D22: 상세불명 당뇨병 · 신장 합병증 동반 | E22: EXACT | G22: 12 | H22: 2 | I22: TRUE | L22: 22
A23: COND-023 | B23: DX-05 | C23: I12 | D23: 고혈압성 신장질환 | E23: PREFIX | G23: 12 | H23: 2 | I23: TRUE | K23: 고혈압성 신장질환. 고혈압(DX-02)에서 빼고 여기만 남겼다 | L23: 23
A24: COND-024 | B24: DX-05 | C24: I13 | D24: 고혈압성 심장 및 신장질환 | E24: PREFIX | G24: 12 | H24: 2 | I24: TRUE | K24: 고혈압성 심장·신장질환. 고혈압(DX-02)에서 빼고 여기만 남겼다 | L24: 24
A25: COND-025 | B25: DX-06 | C25: I21 | D25: 급성 심근경색증 | E25: PREFIX | G25: 12 | H25: 1 | I25: TRUE | K25: 급성 심근경색 | L25: 25
A26: COND-026 | B26: DX-06 | C26: I25.2 | D26: 진구성 심근경색증 | E26: EXACT | G26: 12 | H26: 1 | I26: TRUE | K26: 진구성 심근경색 | L26: 26
A27: COND-027 | B27: DX-06 | C27: I20 | D27: 협심증 | E27: PREFIX | G27: 12 | H27: 2 | I27: TRUE | L27: 27
A28: COND-028 | B28: DX-06 | C28: I22 | D28: 후속 심근경색증 | E28: PREFIX | G28: 12 | H28: 2 | I28: TRUE | L28: 28
A29: COND-029 | B29: DX-06 | C29: I23 | D29: 급성 심근경색증 후 특정 현존 합병증 | E29: PREFIX | G29: 12 | H29: 2 | I29: TRUE | L29: 29
A30: COND-030 | B30: DX-06 | C30: I24 | D30: 기타 급성 허혈성 심장질환 | E30: PREFIX | G30: 12 | H30: 2 | I30: TRUE | L30: 30
A31: COND-031 | B31: DX-06 | C31: I25 | D31: 만성 허혈성 심장질환 | E31: PREFIX | G31: 12 | H31: 2 | I31: TRUE | K31: I25.2는 위 1회 규칙이 우선한다 | L31: 31
A32: COND-032 | B32: DX-06 | C32: I50 | D32: 심부전 | E32: PREFIX | G32: 12 | H32: 2 | I32: TRUE | K32: 심부전 | L32: 32
A33: COND-033 | B33: DX-06 | C33: I63 | D33: 뇌경색증 | E33: PREFIX | G33: 12 | H33: 1 | I33: TRUE | K33: 뇌경색 | L33: 33
A34: COND-034 | B34: DX-06 | C34: I64 | D34: 출혈 또는 경색으로 명시되지 않은 뇌졸중 | E34: PREFIX | G34: 12 | H34: 1 | I34: TRUE | K34: 뇌졸중 | L34: 34
A35: COND-035 | B35: DX-06 | C35: I69 | D35: 뇌혈관질환의 후유증 | E35: PREFIX | G35: 12 | H35: 1 | I35: TRUE | K35: 뇌혈관질환 후유증 | L35: 35
A36: COND-036 | B36: DX-07 | C36: K76.0 | D36: 달리 분류되지 않은 지방간 | E36: EXACT | G36: 12 | H36: 2 | I36: TRUE | K36: 12개월 2회 또는 1회 + 검진 간기능 경계 | L36: 36
A37: COND-037 | B37: DX-07 | C37: K75.8 | D37: 기타 명시된 염증성 간질환 — 비알코올성 지방간염 포함 | E37: EXACT | G37: 12 | H37: 2 | I37: TRUE | L37: 37
A38: COND-038 | B38: DX-07 | C38: K70.0 | D38: 알코올성 지방간 | E38: EXACT | G38: 12 | H38: 2 | I38: TRUE | L38: 38
A39: COND-039 | B39: DX-08 | C39: O00 | D39: 임신 · 출산 및 산후기 (O00~O99) | E39: RANGE | F39: O99 | G39: 10 | H39: 1 | I39: FALSE | K39: 임신·출산·산욕 | L39: 39
A40: COND-040 | B40: DX-08 | C40: Z32.1 | D40: 임신 확인됨 | E40: EXACT | G40: 10 | H40: 1 | I40: FALSE | K40: 원본에 기간이 없어 O 코드와 같게 두었다. 확인 필요 | L40: 40
...

Sheet 설정
A1: setting_id | B1: setting_group | C1: setting_name | D1: value_raw | E1: value_type | F1: number_value | G1: time_value | H1: boolean_value | I1: execution_status | J1: use_case | K1: source_row
A2: CFG-002 | B2: 축 상태 | C2: 개선 필요 경계 | D2: 나쁨 비율 >= 0.5 | E2: TEXT_RULE | I2: TYPED | J2: 축 상태 판정 | K2: 2
A3: CFG-003 | B3: 축 상태 | C3: 양호 경계 · 3단계 축 (좋음) | D3: 좋음 비율 >= 0.6 | E3: TEXT_RULE | I3: TYPED | J3: 축 상태 판정 | K3: 3
A4: CFG-004 | B4: 축 상태 | C4: 양호 경계 · 3단계 축 (나쁨 상한) | D4: 나쁨 비율 < 0.2 | E4: TEXT_RULE | I4: TYPED | J4: 축 상태 판정 | K4: 4
A5: CFG-005 | B5: 축 상태 | C5: 양호 판정 결합 규칙 | D5: CFG-003(좋음 비율 >= 0.6) AND CFG-004(나쁨 비율 < 0.2) | E5: TEXT_RULE | I5: TYPED | J5: 축 상태 판정 | K5: 5
A6: CFG-006 | B6: 축 상태 | C6: 관찰 창 · 개선 필요 · 보통 | D6: 28 | E6: NUMBER | F6: 28 | I6: TYPED | J6: 유효 답 수 집계 | K6: 6
A7: CFG-007 | B7: 축 상태 | C7: 상태 판정 최소 건수 · 개선 필요 · 보통 | D7: 3 | E7: NUMBER | F7: 3 | I7: TYPED | J7: 축 상태 판정 | K7: 7
A8: CFG-008 | B8: 축 상태 | C8: 양호 판정 기준 · 최근 유효 응답 수 | D8: 7 | E8: NUMBER | F8: 7 | I8: TYPED | J8: 축 상태 판정 | K8: 8
A9: CFG-009 | B9: 축 상태 | C9: 양호 판정 기준 · 거슬러 보는 상한 | D9: 84 | E9: NUMBER | F9: 84 | I9: TYPED | J9: 축 상태 판정 | K9: 9
A10: CFG-010 | B10: 단계 | C10: 올리기 조건 | D10: 마지막 단계 변경 이후 그 축의 확정된 축 목표 최근 4건 중 3건 완료. 확정된 축 목표가 3건 미만이면 판단하지 않음 | E10: TEXT_RULE | I10: TYPED | J10: 축 단계 상향 | K10: 10
A11: CFG-011 | B11: 단계 | C11: 내리기 조건 | D11: 동일 축의 축 목표가 완료되지 않은 채 확정된 것 연속 2건 | E11: TEXT_RULE | I11: TYPED | J11: 축 단계 하향 | K11: 11
A12: CFG-012 | B12: 끼니 | C12: 끼니 경계 1 | D12: 10:00:00 | E12: TIME | G12: 10:00:00 | I12: TYPED | J12: 지난 끼니 = 어제 저녁 / 오늘 아침 | K12: 12
A13: CFG-013 | B13: 끼니 | C13: 끼니 경계 2 | D13: 12:00:00 | E13: TIME | G13: 12:00:00 | I13: TYPED | J13: 지난 끼니 = 오늘 아침 / 오늘 점심 | K13: 13
A14: CFG-014 | B14: 끼니 | C14: 끼니 경계 3 | D14: 17:00:00 | E14: TIME | G14: 17:00:00 | I14: TYPED | J14: 지난 끼니 = 오늘 점심 / 오늘 저녁. 00:00~04:00은 실제 달력일의 어제 저녁 | K14: 14
A15: CFG-015 | B15: 날짜 | C15: 세션 경계 | D15: 04:00:00 | E15: TIME | G15: 04:00:00 | I15: TYPED | J15: 질문 세트 · 목표 · 코칭의 하루 단위 | K15: 15
A16: CFG-016 | B16: 문구 | C16: 저녁 문구 우선 시각 | D16: 17:00:00 | E16: TIME | G16: 17:00:00 | I16: TYPED | J16: 17:00~24:00 저녁 문구 우선. 00:00~04:00은 어제 저녁으로 표시 | K16: 16
A17: CFG-017 | B17: 문구 | C17: 오전 진입 문구 제한 | D17: 10:00 이후 제외 | E17: TEXT_RULE | I17: TYPED | J17: 시간대 표시 「오전 진입」 | K17: 17
A18: CFG-018 | B18: 회전 문항 | C18: 같은 축 연속 제한 | D18: 3일. 질문이 나간 날 기준(답하지 않아도 센다) | E18: TEXT_RULE | I18: TYPED | J18: 회전 축 선정에서 제외 | K18: 18
A19: CFG-019 | B19: 진단 층 | C19: 진료정보 조회 창 | D19: 유형별 조회 창 | E19: TEXT_RULE | I19: NEEDS_STRUCTURING | J19: 진단 후보 판정 | K19: 19
A20: CFG-020 | B20: 진단 층 | C20: 기본 후보 조건 | D20: 주상병 2회 이상 | E20: TEXT_RULE | I20: TYPED | J20: 진단 후보 판정 | K20: 20
A21: CFG-021 | B21: 진단 층 | C21: 재질문 주기 | D21: 30일 | E21: TEXT_RULE | I21: TYPED | J21: 「모르겠어요」 답변 후 | K21: 21
A22: CFG-022 | B22: 검진 경계 | C22: 혈압 유효 조건 | D22: 측정 환경·기기·반복 측정·품질 저장 | E22: TEXT_RULE | I22: NEEDS_STRUCTURING | J22: 기기 연동값 채택 | K22: 22
A23: CFG-023 | B23: 검진 경계 | C23: 공복혈당 유효 조건 | D23: 검진 검사값과 기기 관찰값을 분리 | E23: TEXT_RULE | I23: NEEDS_STRUCTURING | J23: 기기 연동값 채택 | K23: 23
A24: CFG-024 | B24: 검진 경계 | C24: 체중 유효 조건 | D24: 하루 첫 측정 1건 | E24: TEXT_RULE | I24: NEEDS_STRUCTURING | J24: 체질량지수 재계산 | K24: 24
A25: CFG-025 | B25: 검진 경계 | C25: 공복혈당 구간 | D25: 검사실 참고 구간: 100~125 / 126 이상 | E25: TEXT_RULE | I25: NEEDS_STRUCTURING | J25: 검진 경계 판정 | K25: 25
A26: CFG-026 | B26: 검진 경계 | C26: 혈압 구간 | D26: 원본 임계치 보존·자동 판정 연결 보류 | E26: TEXT_RULE | I26: NEEDS_STRUCTURING | J26: 검진 경계 판정 | K26: 26
A27: CFG-027 | B27: 검진 경계 | C27: 콜레스테롤 구간 | D27: 검진 결과와 검사실 참고범위 저장 | E27: TEXT_RULE | I27: NEEDS_STRUCTURING | J27: 검진 경계 판정 | K27: 27
A28: CFG-028 | B28: 검진 경계 | C28: 체질량지수 구간 | D28: 성인용 기존 분류는 참고값으로만 | E28: TEXT_RULE | I28: NEEDS_STRUCTURING | J28: 검진 경계 판정 | K28: 28
... A38: CFG-038 | B38: 질문 | C38: 고정·회전 노출 수 | D38: 1+최대1 | E38: TEXT_RULE | I38: TYPED | J38: 고정·회전 문항 모두 선택지 3개 | K38: 38
A39: CFG-039 | B39: 질문 | C39: 어제 목표 확인 질문 | D39: false | E39: BOOLEAN | H39: FALSE | I39: TYPED | J39: 회전 선정 | K39: 39
A40: CFG-040 | B40: 질문 | C40: 어제 결식 단백질 강제 | D40: false | E40: BOOLEAN | H40: FALSE | I40: TYPED | J40: 회전 선정 | K40: 40
A41: CFG-041 | B41: 질문 | C41: 회전 우선순위 | D41: 질환 연결 축을 모두 한 번씩 물은 다음 날 일반 축 하나. 같은 묶음 안에서는 28일 유효답 최소 → 최근 질문 오래됨 → 질문 ID 오름차순 | E41: TEXT_RULE | I41: TYPED | J41: 회전 선정 | K41: 41
A42: CFG-042 | B42: 집계 | C42: 미응답 처리 | D42: 응답 없으면 문항 미완료·집계 제외 | E42: TEXT_RULE | I42: TYPED | J42: 질문 상태·목표 잠금 | K42: 42
A43: CFG-043 | B43: 집계 | C43: 오늘 선정용 스냅샷 | D43: 첫 선정 전일까지의 28일 | E43: TEXT_RULE | I43: NEEDS_STRUCTURING | J43: 목표 선정 | K43: 43
A44: CFG-044 | B44: 집계 | C44: 식사 시각 상태 | D44: 사실 빈도만 저장 | E44: TEXT_RULE | I44: NEEDS_STRUCTURING | J44: 시간 축 | K44: 44
A45: CFG-045 | B45: 단계 | C45: 양호 시 도전 강제 | D45: false | E45: BOOLEAN | H45: FALSE | I45: TYPED | J45: 단계 선정 | K45: 45
A46: CFG-046 | B46: 안전 | C46: 금지 필터 범위 | D46: 모든 풀·모든 대체 단계·최종 저장. 완화할 수 없다 | E46: TEXT_RULE | I46: TYPED | J46: 목표 선정 | K46: 46
A47: CFG-047 | B47: 안전 | C47: 후보 없음 | D47: 생성 안 함·안내 표시. 완료율 분모에는 들어가며 미완료로 센다 | E47: TEXT_RULE | I47: TYPED | J47: 목표 타일 | K47: 47
A48: CFG-049 | B48: 운영 | C48: 규칙 버전 | D48: 1.0.0 | E48: TEXT_RULE | I48: NEEDS_STRUCTURING | J48: 전체 | K48: 48
A49: CFG-050 | B49: 데이터 | C49: 질환 확인 의미 | D49: 사용자 확인 질환 | E49: TEXT_RULE | I49: NEEDS_STRUCTURING | J49: 진단 층 | K49: 49
...

Sheet 설정파라미터
A1: setting_id | B1: parameter_key | C1: operator_code | D1: number_value | E1: text_value | F1: unit_code | G1: parse_scope | H1: note
A2: CFG-002 | B2: BAD_RATIO | C2: GTE | D2: 0.5 | F2: RATIO | G2: FULL | H2: 분모와 관찰 창을 아래 행에 함께 적었다
A3: CFG-003 | B3: GOOD_RATIO | C3: GTE | D3: 0.6 | F3: RATIO | G3: FULL | H3: 분모와 관찰 창을 아래 행에 함께 적었다
A4: CFG-004 | B4: BAD_RATIO | C4: LT | D4: 0.2 | F4: RATIO | G4: FULL | H4: 분모와 관찰 창을 아래 행에 함께 적었다
A5: CFG-018 | B5: CONSECUTIVE_AXIS_DAYS | C5: EQ | D5: 3 | F5: DAY | G5: SOURCE_ATOM | H5: 축 재노출 제한. 질문이 나간 날 기준(답하지 않아도 센다)
A6: CFG-020 | B6: PRIMARY_DIAGNOSIS_OCCURRENCES | C6: GTE | D6: 2 | F6: COUNT | G6: SOURCE_ATOM | H6: 후보 조건의 한 항목
A7: CFG-021 | B7: REASK_INTERVAL | C7: EQ | D7: 30 | F7: DAY | G7: SOURCE_ATOM | H7: 재질문 주기
A8: CFG-029 | B8: TILE_MAX_CHARS | C8: LTE | D8: 22 | F8: CHAR | G8: SOURCE_ATOM | H8: 2줄 × 11자
A9: CFG-030 | B9: QUESTION_MAX_CHARS | C9: LTE | D9: 32 | F9: CHAR | G9: SOURCE_ATOM | H9: 2줄 × 16자
A10: CFG-031 | B10: OPTION_MAX_CHARS | C10: LTE | D10: 14 | F10: CHAR | G10: SOURCE_ATOM | H10: 답 버튼
A11: CFG-033 | B11: BEFORE_NOON_ENTRY_RATIO | C11: LT | D11: 0.4 | F11: RATIO | G11: SOURCE_ATOM | H11: 관찰 기간·분모 별도 결정
A12: CFG-038 | B12: FIXED_QUESTION_COUNT | C12: EQ | D12: 1 | F12: COUNT | G12: SOURCE_ATOM | H12: 고정 질문
A13: CFG-038 | B13: ROTATING_QUESTION_MAX | C13: LTE | D13: 1 | F13: COUNT | G13: SOURCE_ATOM | H13: 회전 질문 최대
A14: CFG-017 | B14: MORNING_ENTRY_EXCLUDE_AT_OR_AFTER | C14: GTE | E14: 10:00 | F14: LOCAL_TIME | G14: SOURCE_ATOM | H14: 사용자 시간대 기준
A15: CFG-033 | B15: ENTRY_BEFORE_TIME | C15: LT | E15: 10:00 | F15: LOCAL_TIME | G15: PARTIAL | H15: 비율의 분모·관찰 기간 별도 결정
A16: CFG-059 | B16: AXIS_SOURCE_PRIORITY | C16: EQ | D16: 1 | F16: ORDER | G16: SOURCE_ATOM | H16: SELF_REPORTED. 숫자가 작을수록 먼저 적용
A17: CFG-060 | B17: AXIS_SOURCE_PRIORITY | C17: EQ | D17: 2 | F17: ORDER | G17: SOURCE_ATOM | H17: CLINIC_CONFIRMED. 직접 선택과 같은 질환은 중복 제거
A18: CFG-061 | B18: AXIS_SOURCE_PRIORITY | C18: EQ | D18: 3 | F18: ORDER | G18: SOURCE_ATOM | H18: SCREENING. 검진일로부터 3개월 이내 신호만 사용
A19: CFG-062 | B19: AXIS_SOURCE_PRIORITY | C19: EQ | D19: 4 | F19: ORDER | G19: SOURCE_ATOM | H19: QUESTION. 앞선 출처에 통과 후보가 없을 때 사용
A20: CFG-063 | B20: SELECTION_ORDER | C20: ASC | F20: ORDER | G20: SOURCE_ATOM | H20: 선택 순서를 그대로 보존하고 중복 순서를 거부
A21: CFG-064 | B21: CLINIC_CONFIRMATION_SECOND_SLOT | C21: EQ | E21: USER_CONFIRMED=DISEASE_ROTATING;DENIED_OR_UNKNOWN=FIXED | F21: QUESTION_PLAN | G21: SOURCE_ATOM | H21: 세션 전체 최대 2개. 확인 당일 공통 고정과 회전을 동시에 내지 않음
A22: CFG-065 | B22: GOAL_RECENT_WINDOW_DAYS | C22: EQ | D22: 30 | F22: GOAL_SELECTION | G22: SOURCE_ATOM | H22: 사용자별 최근 30일 일반·식후 목표를 최신순으로 조회
A23: CFG-066 | B23: CONFIRMATION_QUEUE_ORDER | C23: EQ | E23: GROUP_BY=confirmation_label;ORDER=source_visit_date DESC,rule_id ASC;PER_DAY=1 | G23: QUESTION_PLAN | H23: 하루 한 묶음. 표기가 같은 규칙은 한 묶음으로 본다
A24: CFG-068 | B24: STAGE_UP_REQUIRES | C24: NEQ | E24: axis_state=OBSERVING | G24: GOAL_STAGE | H24: 관찰 중인 축은 단계를 올리지 않는다
A25: CFG-069 | B25: STAGE_CAP_WHEN_NEEDS_WORK | C25: EQ | E25: BASE | G25: GOAL_STAGE | H25: 개선 필요인 축은 기본까지만
A26: CFG-041 | B26: ROTATING_AXIS_ORDER | C26: EQ | E26: GROUP=linked_then_general_after_full_cycle; ORDER=answers_28d ASC, last_asked ASC, question_id ASC | G26: QUESTION_AXIS | H26: 연결 축이 없으면 전체 축을 같은 순서로 본다. 목표 축(V-39)과 따로 계산한다
A27: CFG-002 | B27: WINDOW_DAYS | C27: EQ | D27: 28 | F27: DAY | G27: FULL | H27: CFG-006과 같은 28일 창에서 센다
A28: CFG-002 | B28: MIN_VALID_ANSWERS | C28: GTE | D28: 3 | F28: COUNT | G28: FULL | H28: CFG-007. 이보다 적으면 관찰 중
A29: CFG-003 | B29: RECENT_ANSWERS | C29: EQ | D29: 7 | F29: COUNT | G29: FULL | H29: CFG-008. 최근 유효 응답 7건이 분모
A30: CFG-003 | B30: LOOKBACK_DAYS_MAX | C30: LTE | D30: 84 | F30: DAY | G30: FULL | H30: CFG-009. 7건을 못 채우면 양호 아님
A31: CFG-004 | B31: RECENT_ANSWERS | C31: EQ | D31: 7 | F31: COUNT | G31: FULL | H31: CFG-008. CFG-003과 같은 분모
A32: CFG-004 | B32: LOOKBACK_DAYS_MAX | C32: LTE | D32: 84 | F32: DAY | G32: FULL | H32: CFG-009. CFG-003과 같은 상한
A33: CFG-005 | B33: COMBINE_OPERATOR | C33: EQ | E33: AND | F33: NONE | G33: FULL | H33: 둘 다 참일 때만 양호
A34: CFG-005 | B34: COMBINE_MEMBERS | C34: EQ | E34: CFG-003,CFG-004 | F34: NONE | G34: FULL | H34: 결합 대상 설정 ID
A35: CFG-010 | B35: STAGE_UP_RECENT_GOALS | C35: EQ | D35: 4 | F35: COUNT | G35: GOAL_STAGE | H35: 마지막 단계 변경 이후 그 축의 확정된 축 목표 중 최근 4건을 본다
A36: CFG-010 | B36: STAGE_UP_MIN_COMPLETED | C36: GTE | D36: 3 | F36: COUNT | G36: GOAL_STAGE | H36: 그 4건 중 완료가 3건 이상이면 1단계 올린다
A37: CFG-010 | B37: STAGE_UP_MIN_ENDED | C37: GTE | D37: 3 | F37: COUNT | G37: GOAL_STAGE | H37: 확정된 축 목표가 3건 미만이면 판단하지 않는다
A38: CFG-011 | B38: STAGE_DOWN_CONSECUTIVE_INCOMPLETE | C38: EQ | D38: 2 | F38: COUNT | G38: GOAL_STAGE | H38: 확정된 축 목표 최근 2건이 연속 미완료면 1단계 내린다
A39: CFG-071 | B39: STAGE_LOOKBACK_DAYS | C39: LTE | D39: 56 | F39: DAY | G39: GOAL_STAGE | H39: 56일보다 오래된 목표는 세지 않는다
A40: CFG-072 | B40: MEAL_TIME_STEP_MINUTES | C40: EQ | D40: 60 | F40: MINUTE | G40: SOURCE_ATOM | H40: 버튼 간격
...

Sheet 검진출처
A1: source_id | B1: source_name | C1: source_kind | D1: source_version | E1: source_uri | F1: usage_scope
A2: NHIS-2026-01 | B2: 건강검진 실시기준 [별표 4의 별첨] 검사항목별 판정기준 | C2: PRIMARY | D2: 시행 2026-01-07 | E2: https://law.go.kr/LSW/flDownload.do?bylClsCd=200207&flNm=%5B%EB%B3%84%EC%B2%A8+1%5D+%EA%B2%80%EC%82%AC%ED%95%AD%EB%AA%A9%EB%B3%84+%ED%8C%90%EC%A0%95%EA%B8%B0%EC%A4%80&flSeq=160922929 | F2: 화면 배지 1차 수치 구간. 결과지 판정이 있으면 결과지 우선
A3: MAI-REF-20260914 | B3: maiReport AI검진요약 기준범위 레퍼런스 | C3: SNAPSHOT | D3: 2026-09-14 | E3: maiReport_AI검진요약_기준범위_레퍼런스.html | F3: 프로토타입 표시 범위·보조 기준·또래 등수 방법
A4: KDIGO-2024 | B4: KDIGO 2024 CKD Guideline | C4: SUPPLEMENT | D4: 2024 | E4: https://kdigo.org/wp-content/uploads/2024/03/KDIGO-2024-CKD-Guideline.pdf | F4: eGFR 세부 단계 참고. 공단 배지 판정 대체 금지
A5: KSH-2022 | B5: 대한고혈압학회 진료지침 | C5: SUPPLEMENT | D5: 2022 | E5: https://www.koreanhypertension.org/reference/guide?idno=10081&mode=read | F5: 혈압 세부 분류 문구 참고
A6: KDA-2023 | B6: 대한당뇨병학회 진료지침 | C6: SUPPLEMENT | D6: 2023 | F6: 혈당 진단 기준 참고. 단일 검진값은 확진 아님
A7: KSoLA-2022 | B7: 한국지질·동맥경화학회 이상지질혈증 진료지침 | C7: SUPPLEMENT | D7: 2022 | E7: https://www.lipid.or.kr/reference/guideline.php?boardid=guideline&category=&idx=1281&mode=view&offset=&sk=&sw= | F7: 지질 세부 구간 참고. 2026판 발간 여부 별도 검토
A8: KSSO-2022 | B8: 대한비만학회 비만 진료지침 | C8: SUPPLEMENT | D8: 2020/2022 | F8: BMI 세부 구간 참고
A9: MAI-DIET-1.0.0 | B9: maiReport 식이 목표 검진 연동 정책 | C9: PRODUCT_POLICY | D9: v1.0.0 | F9: 검진 신호→기존 식이 축 연결과 검진일 기준 3개월 유효기간. 검진 판정 의학 기준을 대체하지 않음

Sheet 검진항목
A1: metric_id | B1: metric_name | C1: unit_code | D1: value_kind | E1: sex_required | F1: diet_signal | G1: screening_source_id | H1: note
A2: BP | B2: 혈압 | C2: mmHg | D2: PAIR | E2: FALSE | F2: TRUE | G2: NHIS-2026-01 | H2: 수축기와 이완기 동시 입력. 진료실/가정 측정 환경 구분
A3: BMI | B3: 체질량지수 | C3: kg/m² | D3: NUMERIC | E3: FALSE | F3: TRUE | G3: NHIS-2026-01 | H3: 성인 검진용. 계산에 사용한 키·체중 출처 보존
A4: WAIST | B4: 허리둘레 | C4: cm | D4: NUMERIC | E4: TRUE | F4: FALSE | G4: NHIS-2026-01 | H4: 성별별 경계
A5: FPG | B5: 공복혈당 | C5: mg/dL | D5: NUMERIC | E5: FALSE | F5: TRUE | G5: NHIS-2026-01 | H5: 검진 검사실 공복값. 자가혈당·CGM 대체 불가
A6: TC | B6: 총콜레스테롤 | C6: mg/dL | D6: NUMERIC | E6: FALSE | F6: TRUE | G6: NHIS-2026-01 | H6: 검진 경계 신호. LDL과 혼동 금지
A7: HDL | B7: HDL 콜레스테롤 | C7: mg/dL | D7: NUMERIC | E7: FALSE | F7: FALSE | G7: NHIS-2026-01 | H7: 높을수록 정상A인 역방향 항목
A8: TG | B8: 중성지방 | C8: mg/dL | D8: NUMERIC | E8: FALSE | F8: FALSE | G8: NHIS-2026-01
A9: LDL | B9: LDL 콜레스테롤 | C9: mg/dL | D9: NUMERIC | E9: FALSE | F9: FALSE | G9: NHIS-2026-01 | H9: 당뇨 동반 시 목표는 개별 의사 판단
A10: AST | B10: AST(SGOT) | C10: U/L | D10: NUMERIC | E10: FALSE | F10: FALSE | G10: NHIS-2026-01 | H10: 검사기관 참고범위가 있으면 막대 눈금에 우선
A11: ALT | B11: ALT(SGPT) | C11: U/L | D11: NUMERIC | E11: FALSE | F11: FALSE | G11: NHIS-2026-01 | H11: 공단 정상A 상한 35
A12: GGT | B12: γ-GTP | C12: U/L | D12: NUMERIC | E12: TRUE | F12: FALSE | G12: NHIS-2026-01 | H12: 성별별 범위. 하한 미만은 공단 표에 판정 없음
A13: URINE_PROTEIN | B13: 요단백 | D13: CATEGORY | E13: FALSE | F13: FALSE | G13: NHIS-2026-01 | H13: 음성·약양성·양성 1+ 이상
A14: CREATININE | B14: 혈청크레아티닌 | C14: mg/dL | D14: NUMERIC | E14: FALSE | F14: FALSE | G14: NHIS-2026-01 | H14: 공단 2구간
A15: EGFR | B15: eGFR | C15: mL/min/1.73㎡ | D15: NUMERIC | E15: FALSE | F15: FALSE | G15: NHIS-2026-01 | H15: 공단 배지 2구간. 60~89 참고 막대는 별도
A16: HGB | B16: 혈색소 | C16: g/dL | D16: NUMERIC | E16: TRUE | F16: FALSE | G16: NHIS-2026-01 | H16: 성별별 범위. 상한 초과는 공단 표에 판정 없음

Sheet 검진성분규격
A1: metric_id | B1: component_key | C1: value_kind | D1: required | E1: expected_unit | F1: normalization_note
A2: BP | B2: SBP | C2: NUMBER | D2: TRUE | E2: mmHg | F2: 원본 수치와 단위 보존
A3: BP | B3: DBP | C3: NUMBER | D3: TRUE | E3: mmHg | F3: 원본 수치와 단위 보존
A4: BMI | B4: VALUE | C4: NUMBER | D4: TRUE | E4: kg/m² | F4: 원본 수치와 단위 보존
A5: WAIST | B5: VALUE | C5: NUMBER | D5: TRUE | E5: cm | F5: 원본 수치와 단위 보존
A6: FPG | B6: VALUE | C6: NUMBER | D6: TRUE | E6: mg/dL | F6: 원본 수치와 단위 보존
A7: TC | B7: VALUE | C7: NUMBER | D7: TRUE | E7: mg/dL | F7: 원본 수치와 단위 보존
A8: HDL | B8: VALUE | C8: NUMBER | D8: TRUE | E8: mg/dL | F8: 원본 수치와 단위 보존
A9: TG | B9: VALUE | C9: NUMBER | D9: TRUE | E9: mg/dL | F9: 원본 수치와 단위 보존
A10: LDL | B10: VALUE | C10: NUMBER | D10: TRUE | E10: mg/dL | F10: 원본 수치와 단위 보존
A11: AST | B11: VALUE | C11: NUMBER | D11: TRUE | E11: U/L | F11: 원본 수치와 단위 보존
A12: ALT | B12: VALUE | C12: NUMBER | D12: TRUE | E12: U/L | F12: 원본 수치와 단위 보존
A13: GGT | B13: VALUE | C13: NUMBER | D13: TRUE | E13: U/L | F13: 원본 수치와 단위 보존
A14: URINE_PROTEIN | B14: PROTEIN_GRADE | C14: CATEGORY | D14: TRUE | F14: 원본 범주 코드를 검진범주코드의 ordinal_value로 변환
A15: CREATININE | B15: VALUE | C15: NUMBER | D15: TRUE | E15: mg/dL | F15: 원본 수치와 단위 보존
A16: EGFR | B16: VALUE | C16: NUMBER | D16: TRUE | E16: mL/min/1.73㎡ | F16: 원본 수치와 단위 보존
A17: HGB | B17: VALUE | C17: NUMBER | D17: TRUE | E17: g/dL | F17: 원본 수치와 단위 보존

Sheet 검진판정그룹
A1: rule_group_id | B1: metric_id | C1: sex_code | D1: band_code | E1: precedence | F1: group_logic | G1: source_id | H1: rule_version | I1: effective_from
A2: BP-SUS-SYS | B2: BP | C2: ALL | D2: SUSPECT | E2: 1 | F2: AND | G2: NHIS-2026-01 | H2: NHIS-2026-01 | I2: 46029
A3: BP-SUS-DIA | B3: BP | C3: ALL | D3: SUSPECT | E3: 1 | F3: AND | G3: NHIS-2026-01 | H3: NHIS-2026-01 | I3: 46029
A4: BP-B-SYS | B4: BP | C4: ALL | D4: NORMAL_B | E4: 2 | F4: AND | G4: NHIS-2026-01 | H4: NHIS-2026-01 | I4: 46029
A5: BP-B-DIA | B5: BP | C5: ALL | D5: NORMAL_B | E5: 2 | F5: AND | G5: NHIS-2026-01 | H5: NHIS-2026-01 | I5: 46029
A6: BP-A | B6: BP | C6: ALL | D6: NORMAL_A | E6: 3 | F6: AND | G6: NHIS-2026-01 | H6: NHIS-2026-01 | I6: 46029
A7: BMI-SUS-LOW | B7: BMI | C7: ALL | D7: SUSPECT | E7: 1 | F7: AND | G7: NHIS-2026-01 | H7: NHIS-2026-01 | I7: 46029
A8: BMI-SUS-HIGH | B8: BMI | C8: ALL | D8: SUSPECT | E8: 1 | F8: AND | G8: NHIS-2026-01 | H8: NHIS-2026-01 | I8: 46029
A9: BMI-B | B9: BMI | C9: ALL | D9: NORMAL_B | E9: 2 | F9: AND | G9: NHIS-2026-01 | H9: NHIS-2026-01 | I9: 46029
A10: BMI-A | B10: BMI | C10: ALL | D10: NORMAL_A | E10: 3 | F10: AND | G10: NHIS-2026-01 | H10: NHIS-2026-01 | I10: 46029
A11: WAIST-MALE-B | B11: WAIST | C11: MALE | D11: NORMAL_B | E11: 2 | F11: AND | G11: NHIS-2026-01 | H11: NHIS-2026-01 | I11: 46029
A12: WAIST-MALE-A | B12: WAIST | C12: MALE | D12: NORMAL_A | E12: 3 | F12: AND | G12: NHIS-2026-01 | H12: NHIS-2026-01 | I12: 46029
A13: WAIST-FEMALE-B | B13: WAIST | C13: FEMALE | D13: NORMAL_B | E13: 2 | F13: AND | G13: NHIS-2026-01 | H13: NHIS-2026-01 | I13: 46029
... A54: HGB-FEMALE-A | B54: HGB | C54: FEMALE | D54: NORMAL_A | E54: 3 | F54: AND | G54: NHIS-2026-01 | H54: NHIS-2026-01 | I54: 46029

Sheet 검진판정조건
A1: rule_group_id | B1: condition_order | C1: metric_id | D1: component_key | E1: operator_code | F1: threshold_number | G1: note
A2: BP-SUS-SYS | B2: 1 | C2: BP | D2: SBP | E2: GTE | F2: 140
A3: BP-SUS-DIA | B3: 1 | C3: BP | D3: DBP | E3: GTE | F3: 90
A4: BP-B-SYS | B4: 1 | C4: BP | D4: SBP | E4: GTE | F4: 120
A5: BP-B-SYS | B5: 2 | C5: BP | D5: SBP | E5: LT | F5: 140
A6: BP-B-DIA | B6: 1 | C6: BP | D6: DBP | E6: GTE | F6: 80
A7: BP-B-DIA | B7: 2 | C7: BP | D7: DBP | E7: LT | F7: 90
A8: BP-A | B8: 1 | C8: BP | D8: SBP | E8: LT | F8: 120
A9: BP-A | B9: 2 | C9: BP | D9: DBP | E9: LT | F9: 80
A10: BMI-SUS-LOW | B10: 1 | C10: BMI | D10: VALUE | E10: LT | F10: 18.5
A11: BMI-SUS-HIGH | B11: 1 | C11: BMI | D11: VALUE | E11: GTE | F11: 30
A12: BMI-B | B12: 1 | C12: BMI | D12: VALUE | E12: GTE | F12: 25
A13: BMI-B | B13: 2 | C13: BMI | D13: VALUE | E13: LT | F13: 30
... A74: HGB-FEMALE-A | B74: 2 | C74: HGB | D74: VALUE | E74: LTE | F74: 15.5

Sheet 검진범주코드
A1: metric_id | B1: raw_code | C1: normalized_code | D1: ordinal_value | E1: note
A2: URINE_PROTEIN | B2: 음성(−) | C2: NEGATIVE | D2: -1 | E2: 검사 결과 원본 표기별 매핑 확인
A3: URINE_PROTEIN | B3: 약양성(±) | C3: TRACE | D3: 0 | E3: 검사 결과 원본 표기별 매핑 확인
A4: URINE_PROTEIN | B4: 양성(+1) 이상 | C4: POSITIVE_1_PLUS | D4: 1 | E4: +1 이상은 1 이상으로 정규화

Sheet 검진적용정책
A1: policy_id | B1: scope_code | C1: priority | D1: policy_text | E1: execution_status | F1: source_id
A2: SP-01 | B2: BADGE | C2: 1 | D2: 결과지에 검진기관 판정이 있으면 그 판정을 우선 표시한다. | E2: READY | F2: NHIS-2026-01
A3: SP-02 | B3: BADGE | C3: 2 | D3: 검진기관 판정이 없고 수치·단위·성별 조건이 충족되면 공단 구간을 계산한다. | E3: READY | F3: MAI-REF-20260914
A4: SP-03 | B4: BADGE | C4: 3 | D4: 공단 구간에 없는 값은 UNCLASSIFIED로 두며 정상으로 보정하지 않는다. | E4: READY | F4: MAI-REF-20260914
A5: SP-04 | B5: BAR | C5: 1 | D5: 검진기관 자체 참고범위가 결과지에 있으면 막대 눈금에 우선 적용한다. | E5: READY | F5: MAI-REF-20260914
A6: SP-05 | B6: BAR | C6: 2 | D6: 보조 지침의 세부 범위는 막대 참고 표기로만 쓴다. 배지는 공단 판정과 분리한다. | E6: READY | F6: MAI-REF-20260914
A7: SP-06 | B7: DIET | C7: 1 | D7: 자가혈당·CGM·가정혈압을 검사실·진료실 검진 판정으로 일괄 대체하지 않는다. | E7: READY | F7: MAI-REF-20260914
A8: SP-07 | B8: PEER | C8: 1 | D8: 또래 등수는 검진 판정·식이 목표 선정과 별도의 분포 기준을 사용한다. | E8: READY | F8: MAI-REF-20260914
A9: SP-08 | B9: BADGE | C9: 4 | D9: 성별 분기 항목은 적용 성별 정보가 없으면 계산 판정을 보류한다. | E9: READY | F9: MAI-REF-20260914
A10: SP-09 | B10: DIET | C10: 2 | D10: 검진 결과는 검진일로부터 3개월 뒤 같은 날짜까지 식이 목표 선정에 사용한다. 검진일 미상·미래일·만료 후에는 제외하며, 결과 기록·검진 배지에는 이 기간을 적용하지 않는다. | E10: READY | F10: MAI-DIET-1.0.0

Sheet 검진보조기준
A1: supplemental_id | B1: metric_id | C1: sex_code | D1: label | E1: range_text | F1: use_scope | G1: source_id | H1: note
A2: SUP-001 | B2: BP | C2: ALL | D2: 정상혈압 | E2: 수축기 <120 그리고 이완기 <80 | F2: REFERENCE_ONLY | G2: KSH-2022
A3: SUP-002 | B3: BP | C3: ALL | D3: 주의혈압 | E3: 수축기 120~129 그리고 이완기 <80 | F3: REFERENCE_ONLY | G3: KSH-2022
A4: SUP-003 | B4: BP | C4: ALL | D4: 고혈압전단계 | E4: 수축기 130~139 또는 이완기 80~89 | F4: REFERENCE_ONLY | G4: KSH-2022
A5: SUP-004 | B5: BP | C5: ALL | D5: 고혈압 1기 | E5: 수축기 140~159 또는 이완기 90~99 | F5: REFERENCE_ONLY | G5: KSH-2022
A6: SUP-005 | B6: BP | C6: ALL | D6: 고혈압 2기 | E6: 수축기 ≥160 또는 이완기 ≥100 | F6: REFERENCE_ONLY | G6: KSH-2022
A7: SUP-006 | B7: BP | C7: ALL | D7: 수축기단독고혈압 | E7: 수축기 ≥140 그리고 이완기 <90 | F7: REFERENCE_ONLY | G7: KSH-2022
A8: SUP-007 | B8: FPG | C8: ALL | D8: 공복혈당장애 | E8: 100~125 mg/dL | F8: REFERENCE_ONLY | G8: KDA-2023 | H8: 검진 수치 단독 확진 금지
A9: SUP-008 | B9: LDL | C9: ALL | D9: 적정 | E9: <100 | F9: REFERENCE_ONLY | G9: KSoLA-2022
A10: SUP-009 | B10: LDL | C10: ALL | D10: 정상 | E10: 100~129 | F10: REFERENCE_ONLY | G10: KSoLA-2022
A11: SUP-010 | B11: LDL | C11: ALL | D11: 경계 | E11: 130~159 | F11: REFERENCE_ONLY | G11: KSoLA-2022
A12: SUP-011 | B12: LDL | C12: ALL | D12: 높음 | E12: 160~189 | F12: REFERENCE_ONLY | G12: KSoLA-2022
A13: SUP-012 | B13: LDL | C13: ALL | D13: 매우 높음 | E13: ≥190 | F13: REFERENCE_ONLY | G13: KSoLA-2022
A14: SUP-013 | B14: TC | C14: ALL | D14: 적정 | E14: <200 | F14: REFERENCE_ONLY | G14: KSoLA-2022
A15: SUP-014 | B15: TC | C15: ALL | D15: 경계 | E15: 200~239 | F15: REFERENCE_ONLY | G15: KSoLA-2022
A16: SUP-015 | B16: TC | C16: ALL | D16: 매우 높음 | E16: ≥240 | F16: REFERENCE_ONLY | G16: KSoLA-2022
A17: SUP-016 | B17: TG | C17: ALL | D17: 적정 | E17: <150 | F17: REFERENCE_ONLY | G17: KSoLA-2022
A18: SUP-017 | B18: TG | C18: ALL | D18: 경계 | E18: 150~199 | F18: REFERENCE_ONLY | G18: KSoLA-2022
A19: SUP-018 | B19: TG | C19: ALL | D19: 높음 | E19: 200~499 | F19: REFERENCE_ONLY | G19: KSoLA-2022
A20: SUP-019 | B20: TG | C20: ALL | D20: 매우 높음 | E20: ≥500 | F20: REFERENCE_ONLY | G20: KSoLA-2022
... A22: SUP-021 | B22: HDL | C22: ALL | D22: 낮음 | E22: <60 | F22: REFERENCE_ONLY | G22: KSoLA-2022
A23: SUP-022 | B23: EGFR | C23: ALL | D23: G1 | E23: ≥90 | F23: BAR_CONTEXT | G23: KDIGO-2024 | H23: G2 단독으로 CKD 확진 아님. 배지 기준은 공단 60
A24: SUP-023 | B24: EGFR | C24: ALL | D24: G2 | E24: 60~89 | F24: BAR_CONTEXT | G24: KDIGO-2024 | H24: G2 단독으로 CKD 확진 아님. 배지 기준은 공단 60
A25: SUP-024 | B25: EGFR | C25: ALL | D25: G3a | E25: 45~59 | F25: BAR_CONTEXT | G25: KDIGO-2024 | H25: G2 단독으로 CKD 확진 아님. 배지 기준은 공단 60
A26: SUP-025 | B26: EGFR | C26: ALL | D26: G3b | E26: 30~44 | F26: BAR_CONTEXT | G26: KDIGO-2024 | H26: G2 단독으로 CKD 확진 아님. 배지 기준은 공단 60
A27: SUP-026 | B27: EGFR | C27: ALL | D27: G4 | E27: 15~29 | F27: BAR_CONTEXT | G27: KDIGO-2024 | H27: G2 단독으로 CKD 확진 아님. 배지 기준은 공단 60
A28: SUP-027 | B28: EGFR | C28: ALL | D28: G5 | E28: <15 | F28: BAR_CONTEXT | G28: KDIGO-2024 | H28: G2 단독으로 CKD 확진 아님. 배지 기준은 공단 60
A29: SUP-028 | B29: BMI | C29: ALL | D29: 저체중 | E29: <18.5 | F29: REFERENCE_ONLY | G29: KSSO-2022
A30: SUP-029 | B30: BMI | C30: ALL | D30: 정상 | E30: 18.5~22.9 | F30: REFERENCE_ONLY | G30: KSSO-2022
A31: SUP-030 | B31: BMI | C31: ALL | D31: 비만 전단계 | E31: 23~24.9 | F31: REFERENCE_ONLY | G31: KSSO-2022
A32: SUP-031 | B32: BMI | C32: ALL | D32: 1단계 비만 | E32: 25~29.9 | F32: REFERENCE_ONLY | G32: KSSO-2022
A33: SUP-032 | B33: BMI | C33: ALL | D33: 2단계 비만 | E33: 30~34.9 | F33: REFERENCE_ONLY | G33: KSSO-2022
A34: SUP-033 | B34: BMI | C34: ALL | D34: 3단계 비만 | E34: ≥35 | F34: REFERENCE_ONLY | G34: KSSO-2022

Sheet 검진식이연결
A1: metric_id | B1: priority_group | C1: eligible_band | D1: goal_axis_status | E1: phrase_status | F1: axis_question_id | G1: selection_policy | H1: source_note | I1: minimum_value_inclusive
A2: FPG | B2: 1 | C2: NORMAL_B,SUSPECT | D2: MAPPED | E2: REUSE_AXIS_POOL | F2: DIET-Q-01 | G2: SELECT_EXISTING_AXIS_POOL | H2: 혈당 신호는 채소 축에 연결. 단 음료·단 간식 축은 저혈당 처치 구분(I-08) 확정 전 제외
A3: BP | B3: 2 | C3: NORMAL_B,SUSPECT | D3: MAPPED | E3: REUSE_AXIS_POOL | F3: DIET-Q-03 | G3: SELECT_EXISTING_AXIS_POOL | H3: 혈압 신호는 짠맛·국물 축에 연결
A4: TC | B4: 3 | C4: NORMAL_B,SUSPECT | D4: MAPPED | E4: REUSE_AXIS_POOL | F4: DIET-Q-07 | G4: SELECT_EXISTING_AXIS_POOL | H4: 총콜레스테롤 신호는 기름진 음식 축에 연결
A5: BMI | B5: 3 | C5: NORMAL_B,SUSPECT | D5: MAPPED | E5: REUSE_AXIS_POOL | F5: DIET-Q-05 | G5: SELECT_EXISTING_AXIS_POOL | H5: BMI 원본값 25 이상만 식사 속도·양 축에 연결. 저체중 SUSPECT는 제외 | I5: 25

Sheet 또래등수정책
A1: policy_id | B1: policy_name | C1: value_text | D1: number_value | E1: source_id | F1: data_status
A2: PEER-01 | B2: 기준 모집단 | C2: 국민건강보험공단 건강검진정보 성별 × 5세 연령대 표본 | E2: MAI-REF-20260914 | F2: NEEDS_PERCENTILE_TABLE
A3: PEER-02 | B3: 표본 최소 건수 | C3: 500명 미만이면 인접 연령대 합산 | D3: 500 | E3: MAI-REF-20260914 | F3: POLICY_ONLY
A4: PEER-03 | B4: 백분위 | C4: P = (나보다 작은 사람 수 + 0.5 × 같은 사람 수) / N × 100 | E4: MAI-REF-20260914 | F4: POLICY_ONLY
A5: PEER-04 | B5: 등수 | C5: ceil(P), 0이면 1; 범위 1~100 | E5: MAI-REF-20260914 | F5: POLICY_ONLY
A6: PEER-05 | B6: 5구간 | C6: ceil(등수 / 20) | D6: 20 | E6: MAI-REF-20260914 | F6: POLICY_ONLY
A7: PEER-06 | B7: 갱신 | C7: 분포표 연 1회 갱신하고 요약 저장 시 버전 기록 | D7: 1 | E7: MAI-REF-20260914 | F7: POLICY_ONLY
A8: PEER-07 | B8: 데이터 없음 | C8: 합산 후에도 표본 부족 시 또래 비교 데이터를 준비 중이에요 | E8: MAI-REF-20260914 | F8: POLICY_ONLY
A9: PEER-08 | B9: 자녀 프로필 | C9: 성인 검진 표본을 쓰지 않고 소아청소년 성장도표를 따로 사용 | E9: MAI-REF-20260914 | F9: NEEDS_PERCENTILE_TABLE

Sheet 검증규칙
A1: 규칙 ID | B1: 대상 | C1: 검사 | D1: 실패 시 처리
A2: V-01 | B2: 질문 | C2: question_id + question_version 유일 | D2: 중복 질문 버전 적재 거부
A3: V-02 | B3: 선택지 | C3: 모든 질문 ID·버전마다 선택지 정확히 3개. option_order는 1, 2, 3 | D3: 선택지 누락·중복과 순서 공백 적재 거부
A4: V-03 | B4: 선택지 | C4: unknown 선택지 코드는 사용하지 않음. 답변이 없으면 질문 상태 PENDING으로 유지하고 diet_answer 행을 만들지 않음 | D4: 미응답을 ANSWERED·0점·개선 필요로 치환하지 않고 목표 잠금 유지
A5: V-04 | B5: 목표문구 | C5: phrase_id + phrase_version 유일 | D5: 중복 문구 버전 적재 거부
