Workbook

Sheet 안내
A1: maiReport 식이 참조·설정 데이터 · v1.4.0 | B1: 2026-10-13 | C1: 2026-10-19
A2: v1.0.0 발행 뒤 고친 내용을 반영한 v1.4.0입니다. 바뀐 것은 아래 「바뀐 내용」 표에 있습니다. 식이 문구 403개, 질문, 질환 규칙, 설정 기준을 제공합니다. 검진일로부터 3개월 이내 신호만 기존 식이 축에 연결합니다.
A4: 시트 | B4: 내용 | C4: 행 수
A5: 문구세트 | B5: =COUNTA(문구세트!A2:A999)&"개 운영 문구 · 문구 ID · 성격" -> 403개 운영 문구 · 문구 ID · 성격 | C5: =COUNTA(문구세트!A2:A999) -> 403
A6: 축정의 | B6: 8축 · 회전 문항 · 답 3개 · 질문 ID + 이어 묻는 식사 시각 단계 2행(축 아님) | C6: 10
A7: 질환규칙 | B7: 원본 연결·금지 플래그와 파생 추천 동작. STOP_ALL은 대체 후보 탐색 전에 적용 | C7: 14
A8: 상병코드조건 | B8: 질환규칙마다 어떤 상병코드를 몇 개월 안에 몇 회 보면 후보로 올리는지 | C8: 61
A9: 설정값 | B9: 설정 ID·원본값·용도. 문장형 규칙의 확실한 원소는 설정파라미터에 분리 | C9: 62
A10: 열정의 | B10: 모든 시트의 열마다 타입·허용값·필수 여부. 구현은 이 시트를 먼저 본다 | C10: 63
A11: 노출조건 | B11: ="문구 "&COUNTA(노출조건!A2:A999)&"개의 시간·요일·상황 분리와 자동 적용 여부" -> 문구 403개의 시간·요일·상황 분리와 자동 적용 여부 | C11: =COUNTA(노출조건!A2:A999) -> 403
A12: 설정파라미터 | B12: 원본 설정에서 확실하게 추출한 숫자·시간 원소 | C12: 20
A13: 검진식이연결 | B13: 검진 신호 4개의 기존 식이 축 연결과 BMI 원본값 적용 조건 | C13: 4
A14: 내정보질환매핑 | B14: 내정보 직접 선택 질환 4개. 선택 순서를 저장하며 3개는 기존 연결 축, 만성 신장질환은 안전 제외 조건만 적용. 통과 후보가 없으면 다음 질환·다음 출처로 이동 | C14: 4
A15: 열이 무슨 뜻인가 · 문구세트
A16: 열 | B16: 뜻 | C16: 값의 예
A17: No | B17: 통째 일련번호. 정렬을 바꿔도 원래 순서로 되돌리기 위한 것 | C17: ="1 ~ 225 (현재 "&COUNTA(문구세트!A2:A999)&"개)" -> 1 ~ 225 (현재 403개)
A18: 묶음 | B18: 문구를 의학팀 · 개발에 넘기는 단위. 지금은 전체가 1차다. 나중에 문구를 더 늘리면 2차가 생긴다 | C18: 1차
A19: 상태 | B19: 지금 후보에 넣는지. 이 열이 「사용」인 것만 실제로 쓴다 | C19: 사용 · 보류
A20: 구분 | B20: 상황 풀도 모든 질환별 금지·시간·상황 필터를 통과해야 함 | C20: 축 × 단계 · 회복 풀 · 부담 줄이기 풀
A21: 축 | B21: 기존 행동 축 8종. 곡류·식이섬유 19개는 연결 규칙 확정 전 보류 | C21: 채소 · 짠맛 · 국물 · 곡류 · 식이섬유 등
A22: 단계 | B22: 축별 실천 부담. 단계 변경 뒤 새 완료만 사용. 양호 강제 도전 없음 | C22: 입문 · 기본 · 도전
A23: 타일 문구 | B23: 홈 타일에 그대로 나가는 말. 사용자가 보는 유일한 문장이다 | C23: 저녁은 채소부터 먹기
A24: 글자수 | B24: 타일 문구의 길이. 한도 22자를 넘으면 노란색으로 칠해진다 | C24: 10
A25: 풀어 쓴 문구 | B25: 타일 문구만으로 무엇을 하라는 건지 알기 어려울 때를 위해, 같은 목표를 한 문장으로 풀어 쓴 말. 40자 이내. 화면 어디에 보여 줄지는 화면 확정 필요 | C25: 오늘도 아침·점심·저녁 세 끼를 제때 드세요.
A26: 이유 한 줄 | B26: 왜 이 목표를 주는지에 대한 설명. 화면에는 나가지 않는다. 개발·기획이 보고 다른 기능이 가져다 쓰는 값이다 | C26: 채소를 먼저 먹으면 식후 혈당이 덜 출렁여요.
A27: 시간대 표시 | B27: 자동 노출 조건은 시간대·평일·주말·명절·연휴만 사용. 명절·연휴 날짜 자료가 없으면 해당 문구 제외 | C27: 저녁 · 오전 진입 · 오후 진입
A28: 검진 경계 전용 | B28: 1차에서는 전용 문구를 사용하지 않음. 검진 신호가 기존 축 문구의 선정 우선순위를 바꾸며 안전·시간 필터는 유지 | C28: 전용값 공란
A29: 근거 | B29: 출처 ID는 근거대조서의 출처목록에서 확인. 행동의 세부 횟수·분량은 별도 검토 | C29: WHO 당류 지침 · 식생활지침 수칙 1
A30: 검토 메모·남은 확인 | B30: 문구별로 남은 확인 사항을 기록한다. 목표 선정 조건이나 의학적 승인 상태로 해석하지 않는다
A32: 열이 무슨 뜻인가 · 나머지 시트
A33: 시트 | B33: 열 | C33: 뜻
A34: 축정의 | B34: 표 순서 | C34: 후보가 동률일 때 이 순서로 고른다
A35: 축정의 | B35: 물을 수 있는 끼니 | C35: 지난 끼니가 무엇일 때 이 축을 물을 수 있는지. 「식사 시각」만 어제 저녁으로 제한된다
A36: 축정의 | B36: 선택지는 사실 응답. 집계값 1/0/-1은 기획용 코드, 빈값은 집계 제외 | C36: 왼쪽부터 양호 · 보통 · 개선 필요. 화면에는 등급 라벨을 쓰지 않고 사실만 적는다
A37: 질환규칙 | B37: 연결·금지 구분 | C37: 질환에 따른 후보 축 연결과 금지 성격을 구분한다. 금지 성격은 모든 문구 풀에 적용한다.
A38: 상병코드조건 | B38: 후보 조건 | C38: 몇 개월 안에 주상병 몇 회면 진단 후보로 올리는지. 처방 정보는 연동되지 않는다.
A39: 질환규칙 | B39: 사용자 확인 질환 | C39: 사용자 확인은 참고 신호이며 임상 확진으로 취급하지 않는다. 확인된 질환에 연결된 축만 후보가 된다.
A40: 질환규칙 | B40: 금지 성격 | C40: 진단 후보 단계부터 해당 질환의 금지 성격 문구를 제외한다. 개인별 치료 지시가 우선한다.
A41: 설정값 | B41: 설정 ID·원본값·용도. 문장형 규칙의 확실한 원소는 설정파라미터에 분리 | C41: 62
A42: 고정 문항의 한계 | B42: 평소 양은 영양 적정량이 아니다. 「못 먹거나 거름」은 못 먹은 끼니와 거른 끼니를 나누지 않는다.
...

Sheet 축정의
A1: 표 순서 | B1: 축 | C1: 관찰 범위 | D1: 질문 | E1: 선택지 1 | F1: 선택지 2 | G1: 선택지 3 | H1: 물을 수 있는 끼니 | I1: 연결 검진·질환 | J1: 해석 한계 | K1: 질문 ID | L1: 질문 버전 | M1: 선택지 코드 1 | N1: 선택지 코드 2 | O1: 선택지 코드 3 | P1: 집계값 1 | Q1: 집계값 2 | R1: 집계값 3
A2: 1 | B2: 끼니 규칙 | C2: 지난 끼니의 상대적 섭취량. 결식 빈도·영양 충족도 아님 | D2: {지난 끼니}은 평소만큼 드셨나요? | E2: 충분히 먹음 | F2: 적게 · 몇 입만 | G2: 못 먹거나 거름 | H2: 질환 확인 질문이 없는 날 또는 확인 답이 아니요·모르겠어요인 날 | I2: 체질량지수 | J2: 고정 답은 회복 목표 분기에도 사용. 미섭취와 소량 섭취를 구분할 수 없음 | K2: DIET-Q-00 | L2: 1.0.0 | M2: usual | N2: less | O2: very_little_or_skipped | P2: 1 | Q2: 0 | R2: -1
A3: 2 | B3: 채소 | C3: 채소 반찬을 먹은 정도(본인 판단). 중량·먹는 순서 아님 | D3: {지난 끼니}엔 채소 반찬을 얼마나 드셨나요? | E3: 충분히 먹음 | F3: 조금 먹음 | G3: 먹지 않음 | H3: 모든 끼니 | I3: 혈당 · 체중 · 당뇨 · 고혈압 | J3: 본인이 느낀 양만 관찰. 400g 달성·혈당 개선으로 해석 금지 | K3: DIET-Q-01 | L3: 1.0.0 | M3: two_or_more | N3: one | O3: none | P3: 1 | Q3: 0 | R3: -1
A4: 3 | B4: 단 음료 · 단 간식 | C4: 단 음료·단 간식 섭취 횟수. 양·총당량 아님 | D4: {지난 끼니} 전후 단 음료·간식은 몇 번이었나요? | E4: 없었어요 | F4: 한 번 | G4: 두 번 이상 | H4: 모든 끼니 | I4: 혈당 · 체중 · 당뇨 | J4: 섭취 횟수만 관찰. 저혈당 처치용 섭취는 불리한 응답으로 평가하지 않음 | K4: DIET-Q-02 | L4: 1.0.0 | M4: none | N4: once | O4: twice_or_more | P4: 1 | Q4: 0 | R4: -1
A5: 4 | B5: 짠맛 · 국물 | C5: 제공된 국물 중 먹은 대략 비율. 전체 나트륨 아님 | D5: {지난 끼니}엔 국물을 얼마나 드셨나요? | E5: 먹지 않음 | F5: 절반 이하 | G5: 절반 넘게 | H5: 모든 끼니 | I5: 혈압 · 고혈압 · 신장 | J5: 국물이 없는 끼니도 첫 답. 저나트륨 식사로 단정하지 않음 | K5: DIET-Q-03 | L5: 1.0.0 | M5: none | N5: half_or_less | O5: more_than_half | P5: 1 | Q5: 0 | R5: -1
A6: 5 | B6: 식사 시각 | C6: 전날 저녁 식사 후~당일 04:00 전의 야식 자기보고 양(조금 / 배불리). 오늘 아침 식사는 제외. 위해성·수면 영향 판정 아님 | D6: 어젯밤 야식은 얼마나 드셨나요? | E6: 먹지 않음 | F6: 조금 먹음 | G6: 배불리 먹음 | H6: 04:00~10:00 진입에서만(전날 밤 회상) | I6: 체중 · 비만 · 역류 | J6: 야식 여부·양만 저장. 필요한 간식과 교대근무 상황은 구분할 수 없어 좋음/나쁨 등급 산출 중지 | K6: DIET-Q-04 | L6: 1.0.0 | M6: none | N6: light | O6: meal_sized
A7: 6 | B7: 식사 속도 · 양 | C7: 식후 주관적 포만감. 속도·열량 아님 | D7: {지난 끼니} 후 배부름은 어땠나요? | E7: 편안했어요 | F7: 조금 배불렀어요 | G7: 많이 배불렀어요 | H7: 모든 끼니 | I7: 체중 · 혈당 · 당뇨 · 지질 | J7: 주관적 포만감만 관찰. 체중감량 필요·속도 과다로 해석 금지 | K7: DIET-Q-05 | L7: 1.0.0 | M7: comfortable | N7: somewhat_full | O7: too_full | P7: 1 | Q7: 0 | R7: -1
A8: 7 | B8: 단백질 | C8: 단백질 식품 섭취 여부와 맛보기 구분. 필요량 충족 아님 | D8: {지난 끼니}엔 단백질류(고기·생선·달걀 등)를 드셨나요? | E8: 먹었어요 | F8: 맛만 봤어요 | G8: 안 먹었어요 | H8: 모든 끼니 | I8: 회복 풀 전용 · 신장은 금지 | J8: 식품 존재 형태만 관찰. 단백질 필요량 충족으로 해석 금지; 개인 식사 제한 우선 | K8: DIET-Q-06 | L8: 1.0.0 | M8: ate | N8: tasted_only | O8: absent | P8: 1 | Q8: 0 | R8: -1
A9: 8 | B9: 기름진 음식 | C9: 튀긴 음식 섭취 여부와 맛보기 구분. 총지방·포화지방량 아님 | D9: {지난 끼니}엔 튀긴 음식을 드셨나요? | E9: 안 먹었어요 | F9: 맛만 봤어요 | G9: 먹었어요 | H9: 모든 끼니 | I9: 콜레스테롤 · 지질 | J9: 주관적 섭취 정도만 관찰. 총지방·포화지방량 진단 금지 | K9: DIET-Q-07 | L9: 1.0.0 | M9: absent | N9: tasted_only | O9: ate | P9: 1 | Q9: 0 | R9: -1
A10: 9 | B10: 식사 시각 단계 (축 아님 · 이어 묻기) | C10: 그 끼니를 먹은 시각의 대략 범위(1시간 구간). 양 · 내용 아님 | D10: {끼니}은 언제쯤 드셨어요? | E10: 1시간 이내 | F10: 1~2시간 전 | G10: 그보다 전 | H10: 오늘 점심 · 오늘 저녁(오후 9시까지 답할 때). 고정 질문에 「충분히 먹음 · 적게 · 몇 입만」으로 답한 바로 뒤. 「못 먹거나 거름」 · 건강 앱 식사 기록이 있으면 묻지 않음 | I10: 자기돌봄 · 일상안정의 식후 행동 판정 입력 | J10: 시각 구간은 답한 시각(10분 내림)에서 1시간씩 거꾸로(저장용). 점심은 오후 2시가 지나면 2시에 답한 것과 같은 선택지. 하한 점심 12시 · 저녁 4시. 점수 · 등급 없음 | K10: DIET-Q-08 | L10: 1.0.0 | M10: within_1h | N10: one_to_two_h | O10: earlier
A11: 10 | B11: 식사 시각 단계 (축 아님 · 이어 묻기) | C11: 아침을 먹은 시각의 대략 범위 | D11: 아침은 몇 시쯤 드셨어요? | E11: 7시 이전 | F11: 7시~8시 | G11: 8시 이후 | H11: 오늘 아침(10~12시). 조건은 위와 같음 | I11: 자기돌봄 · 일상안정의 식후 행동 판정 입력 | J11: 버튼은 7시 · 8시 정각 고정(아침 질문은 선택지 상한 시각 9시를 늘 지난 뒤). 점수 · 등급 없음. 회전 후보 아님 | K11: DIET-Q-09 | L11: 1.0.0 | M11: before_7 | N11: seven_to_eight | O11: after_8
A12: 11 | B12: 식사 시각 단계 (축 아님 · 이어 묻기) | C12: 어제 저녁을 먹은 시각의 대략 범위 | D12: 어제 저녁은 몇 시쯤 드셨어요? | E12: 7시 이전 | F12: 7시~9시 | G12: 9시 이후 | H12: 어제 저녁(00~10시 진입). 조건은 위와 같음. 어젯밤 이미 답했으면 다시 묻지 않음 | I12: 일상안정(최근 7일 식후 행동) 입력 | J12: 저녁 7시 · 9시 정각 고정(범위 17~19 · 19~21 · 21~23시). 점수 · 등급 없음 | K12: DIET-Q-10 | L12: 1.0.0 | M12: before_7 | N12: seven_to_nine | O12: after_9
A13: 12 | B13: 식사 시각 단계 (축 아님 · 이어 묻기) | C13: 저녁을 먹은 시각의 대략 범위(오후 9시 뒤에 답할 때) | D13: 저녁은 몇 시쯤 드셨어요? | E13: 7시 이전 | F13: 7시~9시 | G13: 9시 이후 | H13: 오늘 저녁을 오후 9시가 지나서 답할 때. 조건은 위와 같음 | I13: 자기돌봄 · 일상안정의 식후 행동 판정 입력 | J13: 1시간 칸 3개로는 5시 · 10시 식사를 다 덮을 수 없어 늦게 답한 날은 2시간 칸. 어제 저녁과 같은 선택지 | K13: DIET-Q-11 | L13: 1.0.0 | M13: before_7 | N13: seven_to_nine | O13: after_9

Sheet 설정파라미터
A1: setting_id | B1: parameter_key | C1: operator_code | D1: number_value | E1: text_value | F1: unit_code | G1: parse_scope | H1: note
A2: CFG-002 | B2: BAD_RATIO | C2: GTE | D2: 0.5 | F2: RATIO | G2: FULL | H2: 분모와 관찰 창을 아래 행에 함께 적었다
A3: CFG-003 | B3: GOOD_RATIO | C3: GTE | D3: 0.6 | F3: RATIO | G3: FULL | H3: 분모와 관찰 창을 아래 행에 함께 적었다
A4: CFG-004 | B4: BAD_RATIO | C4: LT | D4: 0.2 | F4: RATIO | G4: FULL | H4: 분모와 관찰 창을 아래 행에 함께 적었다
A5: CFG-005 | B5: GOOD_RATIO | C5: GTE | D5: 0.8 | F5: RATIO | G5: PARTIAL | H5: 분모·관찰 창은 원본의 별도 설정과 결합해야 함
A6: CFG-018 | B6: CONSECUTIVE_AXIS_DAYS | C6: EQ | D6: 3 | F6: DAY | G6: SOURCE_ATOM | H6: 축 재노출 제한. 질문이 나간 날 기준(답하지 않아도 센다)
A7: CFG-020 | B7: PRIMARY_DIAGNOSIS_OCCURRENCES | C7: GTE | D7: 2 | F7: COUNT | G7: SOURCE_ATOM | H7: 후보 조건의 한 항목
A8: CFG-021 | B8: REASK_INTERVAL | C8: EQ | D8: 30 | F8: DAY | G8: SOURCE_ATOM | H8: 재질문 주기
A9: CFG-029 | B9: TILE_MAX_CHARS | C9: LTE | D9: 22 | F9: CHAR | G9: SOURCE_ATOM | H9: 2줄 × 11자
A10: CFG-030 | B10: QUESTION_MAX_CHARS | C10: LTE | D10: 32 | F10: CHAR | G10: SOURCE_ATOM | H10: 2줄 × 16자
A11: CFG-031 | B11: OPTION_MAX_CHARS | C11: LTE | D11: 14 | F11: CHAR | G11: SOURCE_ATOM | H11: 답 버튼
A12: CFG-033 | B12: BEFORE_NOON_ENTRY_RATIO | C12: LT | D12: 0.4 | F12: RATIO | G12: SOURCE_ATOM | H12: 관찰 기간·분모 별도 결정
A13: CFG-038 | B13: FIXED_QUESTION_COUNT | C13: EQ | D13: 1 | F13: COUNT | G13: SOURCE_ATOM | H13: 고정 질문
A14: CFG-038 | B14: ROTATING_QUESTION_MAX | C14: LTE | D14: 1 | F14: COUNT | G14: SOURCE_ATOM | H14: 회전 질문 최대
A15: CFG-017 | B15: MORNING_ENTRY_EXCLUDE_AT_OR_AFTER | C15: GTE | E15: 10:00 | F15: LOCAL_TIME | G15: SOURCE_ATOM | H15: 사용자 시간대 기준
A16: CFG-033 | B16: ENTRY_BEFORE_TIME | C16: LT | E16: 10:00 | F16: LOCAL_TIME | G16: PARTIAL | H16: 비율의 분모·관찰 기간 별도 결정
A17: CFG-059 | B17: AXIS_SOURCE_PRIORITY | C17: EQ | D17: 1 | F17: ORDER | G17: SOURCE_ATOM | H17: SELF_REPORTED. 숫자가 작을수록 먼저 적용
A18: CFG-060 | B18: AXIS_SOURCE_PRIORITY | C18: EQ | D18: 2 | F18: ORDER | G18: SOURCE_ATOM | H18: CLINIC_CONFIRMED. 직접 선택과 같은 질환은 중복 제거
A19: CFG-061 | B19: AXIS_SOURCE_PRIORITY | C19: EQ | D19: 3 | F19: ORDER | G19: SOURCE_ATOM | H19: SCREENING. 검진일로부터 3개월 이내 신호만 사용
A20: CFG-062 | B20: AXIS_SOURCE_PRIORITY | C20: EQ | D20: 4 | F20: ORDER | G20: SOURCE_ATOM | H20: QUESTION. 앞선 출처에 통과 후보가 없을 때 사용
A21: CFG-063 | B21: SELECTION_ORDER | C21: ASC | F21: ORDER | G21: SOURCE_ATOM | H21: 선택 순서를 그대로 보존하고 중복 순서를 거부
A22: CFG-064 | B22: CLINIC_CONFIRMATION_SECOND_SLOT | C22: EQ | E22: USER_CONFIRMED=DISEASE_ROTATING;DENIED_OR_UNKNOWN=FIXED | F22: QUESTION_PLAN | G22: SOURCE_ATOM | H22: 세션 전체 최대 2개. 확인 당일 공통 고정과 회전을 동시에 내지 않음
A23: CFG-065 | B23: GOAL_RECENT_WINDOW_DAYS | C23: EQ | D23: 365 | F23: GOAL_SELECTION | G23: SOURCE_ATOM | H23: 사용자별 최근 365일 일반·식후 목표를 최신순으로 조회
A24: CFG-066 | B24: CONFIRMATION_QUEUE_ORDER | C24: EQ | E24: GROUP_BY=confirmation_label;ORDER=source_visit_date DESC,rule_id ASC;PER_DAY=1 | G24: QUESTION_PLAN | H24: 하루 한 묶음. 표기가 같은 규칙은 한 묶음으로 본다
A25: CFG-068 | B25: STAGE_UP_REQUIRES | C25: NEQ | E25: axis_state=OBSERVING | G25: GOAL_STAGE | H25: 관찰 중인 축은 단계를 올리지 않는다
A26: CFG-069 | B26: STAGE_CAP_WHEN_NEEDS_WORK | C26: EQ | E26: BASE | G26: GOAL_STAGE | H26: 개선 필요인 축은 기본까지만
A27: CFG-041 | B27: ROTATING_AXIS_ORDER | C27: EQ | E27: GROUP=linked_then_general_after_full_cycle; ORDER=answers_28d ASC, last_asked ASC, question_id ASC | G27: QUESTION_AXIS | H27: 연결 축이 없으면 전체 축을 같은 순서로 본다
A28: CFG-002 | B28: WINDOW_DAYS | C28: EQ | D28: 28 | F28: DAY | G28: FULL | H28: CFG-006과 같은 28일 창에서 센다
A29: CFG-002 | B29: MIN_VALID_ANSWERS | C29: GTE | D29: 3 | F29: COUNT | G29: FULL | H29: CFG-007. 이보다 적으면 관찰 중
A30: CFG-003 | B30: RECENT_ANSWERS | C30: EQ | D30: 7 | F30: COUNT | G30: FULL | H30: CFG-008. 최근 유효 응답 7건이 분모
A31: CFG-003 | B31: LOOKBACK_DAYS_MAX | C31: LTE | D31: 84 | F31: DAY | G31: FULL | H31: CFG-009. 7건을 못 채우면 양호 아님
A32: CFG-004 | B32: RECENT_ANSWERS | C32: EQ | D32: 7 | F32: COUNT | G32: FULL | H32: CFG-008. CFG-003과 같은 분모
A33: CFG-004 | B33: LOOKBACK_DAYS_MAX | C33: LTE | D33: 84 | F33: DAY | G33: FULL | H33: CFG-009. CFG-003과 같은 상한
A34: CFG-005 | B34: COMBINE_OPERATOR | C34: EQ | E34: AND | F34: NONE | G34: FULL | H34: 둘 다 참일 때만 양호
A35: CFG-005 | B35: COMBINE_MEMBERS | C35: EQ | E35: CFG-003,CFG-004 | F35: NONE | G35: FULL | H35: 결합 대상 설정 ID
A36: CFG-010 | B36: STAGE_UP_RECENT_GOALS | C36: EQ | D36: 4 | F36: COUNT | G36: GOAL_STAGE | H36: 마지막 단계 변경 이후 그 축의 확정된 축 목표 중 최근 4건을 본다
A37: CFG-010 | B37: STAGE_UP_MIN_COMPLETED | C37: GTE | D37: 3 | F37: COUNT | G37: GOAL_STAGE | H37: 그 4건 중 완료가 3건 이상이면 1단계 올린다
A38: CFG-010 | B38: STAGE_UP_MIN_ENDED | C38: GTE | D38: 3 | F38: COUNT | G38: GOAL_STAGE | H38: 확정된 축 목표가 3건 미만이면 판단하지 않는다
A39: CFG-011 | B39: STAGE_DOWN_CONSECUTIVE_INCOMPLETE | C39: EQ | D39: 2 | F39: COUNT | G39: GOAL_STAGE | H39: 확정된 축 목표 최근 2건이 연속 미완료면 1단계 내린다
A40: CFG-071 | B40: STAGE_LOOKBACK_DAYS | C40: LTE | D40: 56 | F40: DAY | G40: GOAL_STAGE | H40: 56일보다 오래된 목표는 세지 않는다
...

Sheet 설정값
A1: 설정 ID | B1: 구분 | C1: 설정 이름 | D1: 값 | E1: 쓰이는 곳 | F1: 비고 · 근거
A2: CFG-002 | B2: 축 상태 | C2: 개선 필요 경계 | D2: 나쁨 비율 >= 0.5 | E2: 축 상태 판정 | F2: 출시 전 테스트에서 재조정
A3: CFG-003 | B3: 축 상태 | C3: 양호 경계 · 3단계 축 (좋음) | D3: 좋음 비율 >= 0.6 | E3: 축 상태 판정 | F3: 출시 전 테스트에서 재조정
A4: CFG-004 | B4: 축 상태 | C4: 양호 경계 · 3단계 축 (나쁨 상한) | D4: 나쁨 비율 < 0.2 | E4: 축 상태 판정 | F4: 출시 전 테스트에서 재조정
A5: CFG-005 | B5: 축 상태 | C5: 양호 판정 결합 규칙 | D5: CFG-003(좋음 비율 >= 0.6) AND CFG-004(나쁨 비율 < 0.2) | E5: 축 상태 판정 | F5: 두 조건을 함께 적용. 식사 시각(DIET-Q-04)은 점수가 없어 상태 산출에서 제외. 이 문장만으로 자동 실행하지 않음
A6: CFG-006 | B6: 축 상태 | C6: 관찰 창 · 개선 필요 · 보통 | D6: 28 | E6: 유효 답 수 집계 | F6: 일; 운영 초기값. 의학적 판정 기준 아님. 종전 14일→28일. 양호는 이 창을 쓰지 않음
A7: CFG-007 | B7: 축 상태 | C7: 상태 판정 최소 건수 · 개선 필요 · 보통 | D7: 3 | E7: 축 상태 판정 | F7: 유효 응답 최소 건수. 같은 실제 끼니·질문버전 중복 제외. 이 수에 못 미치면 관찰 중
A8: CFG-008 | B8: 축 상태 | C8: 양호 판정 기준 · 최근 유효 응답 수 | D8: 7 | E8: 축 상태 판정 | F8: 기간이 아니라 건수로 판정. 7건이 모이기 전에는 비율이 넘어도 보통. 잘못 붙은 양호는 그 축의 코칭을 끊으므로 개선 필요보다 문턱을 높게 둠. 종전 3건 공통
A9: CFG-009 | B9: 축 상태 | C9: 양호 판정 기준 · 거슬러 보는 상한 | D9: 84 | E9: 축 상태 판정 | F9: 일; 이 안에 7건이 모이지 않으면 양호를 내지 않음. 회전 문항이 세션마다 최대 1개라 회전 축은 28일에 4건 안팎에 그침
A10: CFG-010 | B10: 단계 | C10: 올리기 조건 | D10: 마지막 단계 변경 이후 그 축의 확정된 축 목표 최근 4건 중 3건 완료. 확정된 축 목표가 3건 미만이면 판단하지 않음 | E10: 축 단계 상향 | F10: 기존 완료 재사용 금지. 하루 1회 조정. 단계는 실천 부담 날짜가 아니라 그 축의 확정된 목표 횟수로 센다.
A11: CFG-011 | B11: 단계 | C11: 내리기 조건 | D11: 동일 축의 축 목표가 완료되지 않은 채 끝난 것 연속 2건 | E11: 축 단계 하향 | F11: 생성된 목표만 대상. 앱에 들어오지 않아 목표가 없는 날·쉬기 상태는 제외. 마지막 단계 변경 이후 기록만 사용
A12: CFG-012 | B12: 끼니 | C12: 끼니 경계 1 | D12: 10:00:00 | E12: 지난 끼니 = 어제 저녁 / 오늘 아침 | F12: 04:00~10:00은 어제 저녁. 10:00부터 오늘 아침을 묻는다
A13: CFG-013 | B13: 끼니 | C13: 끼니 경계 2 | D13: 12:00:00 | E13: 지난 끼니 = 오늘 아침 / 오늘 점심
A14: CFG-014 | B14: 끼니 | C14: 끼니 경계 3 | D14: 17:00:00 | E14: 지난 끼니 = 오늘 점심 / 오늘 저녁 | F14: 17:00부터 오늘 저녁을 묻는다. 00:00~04:00의 어제 저녁은 실제 달력일의 전날 저녁이며 세션 날짜도 전날(04:00 경계)이다. 04:00 이후 새 세션에서 같은 meal_date·meal_type·question_id·question_version의 기존 유효 답이 있으면 재질문·중복 집계하지 않고 재사용한다
A15: CFG-015 | B15: 날짜 | C15: 세션 경계 | D15: 04:00:00 | E15: 질문 세트 · 목표 · 코칭의 하루 단위 | F15: 실제 날짜(자정 경계)와 다름
A16: CFG-016 | B16: 문구 | C16: 저녁 문구 우선 시각 | D16: 17:00:00 | E16: 시간대 표시 「저녁」 우선 | F16: 17:00~24:00에는 오늘 저녁, 00:00~04:00에는 어제 저녁으로 표시한다. 저녁 식사 여부를 임의로 단정하지 않는다
A17: CFG-017 | B17: 문구 | C17: 오전 진입 문구 제한 | D17: 10:00 이후 제외 | E17: 시간대 표시 「오전 진입」
A18: CFG-018 | B18: 회전 문항 | C18: 같은 축 연속 제한 | D18: 3일. 질문이 나간 날 기준(답하지 않아도 센다) | E18: 회전 축 선정에서 제외 | F18: 제외로 후보가 비면 제외 전으로 되돌림
A19: CFG-019 | B19: 진단 층 | C19: 진료정보 조회 창 | D19: 유형별 조회 창 | E19: 진단 후보 판정 | F19: 12개월 고정 조회 폐기. 24개월·영구상태는 매핑별 처리
A20: CFG-020 | B20: 진단 층 | C20: 기본 후보 조건 | D20: 주상병 2회 이상 | E20: 진단 후보 판정 | F20: 질환별 예외는 상병코드매핑 시트
A21: CFG-021 | B21: 진단 층 | C21: 재질문 주기 | D21: 30일 | E21: 「모르겠어요」 답변 후 | F21: 「아니오」는 12개월 동안 재질문 없음
A22: CFG-022 | B22: 검진 경계 | C22: 혈압 유효 조건 | D22: 측정 환경·기기·반복 측정·품질 저장 | E22: 기기 연동값 채택 | F22: 진료실/가정 혈압의 같은 구간 일괄 적용 보류
A23: CFG-023 | B23: 검진 경계 | C23: 공복혈당 유효 조건 | D23: 검진 검사값과 기기 관찰값을 분리 | E23: 기기 연동값 채택 | F23: 자가 혈당·CGM으로 검진 판정 덮어쓰기 또는 확진 금지
A24: CFG-024 | B24: 검진 경계 | C24: 체중 유효 조건 | D24: 하루 첫 측정 1건 | E24: 체질량지수 재계산 | F24: 7일 중앙값은 2차
A25: CFG-025 | B25: 검진 경계 | C25: 공복혈당 구간 | D25: 검사실 참고 구간: 100~125 / 126 이상 | E25: 검진 경계 판정 | F25: 진단 아님. 증상·재검·임신 여부 등 임상의 해석 필요
A26: CFG-026 | B26: 검진 경계 | C26: 혈압 구간 | D26: 원본 임계치 보존·자동 판정 연결 보류 | E26: 검진 경계 판정 | F26: 측정 환경별 임계치 승인 전 사용 금지
A27: CFG-027 | B27: 검진 경계 | C27: 콜레스테롤 구간 | D27: 검진 결과와 검사실 참고범위 저장 | E27: 검진 경계 판정 | F27: 개별 심혈관 위험에 따른 목표와 구분; LDL/총콜레스테롤 단순 대체 금지
A28: CFG-028 | B28: 검진 경계 | C28: 체질량지수 구간 | D28: 성인용 기존 분류는 참고값으로만 | E28: 검진 경계 판정 | F28: 소아·임신·부종·근감소 등 예외. 자동 감량 허가로 사용 금지
A29: CFG-029 | B29: 문구 폭 | C29: 타일 최대 | D29: 22자 (2줄 × 11자) | E29: 문구 추가 시 검증 | F29: 현재 최장 20자
... A38: CFG-038 | B38: 질문 | C38: 고정·회전 노출 수 | D38: 1+최대1 | E38: 매 세션 | F38: 고정·회전 문항 모두 선택지 3개
A39: CFG-039 | B39: 질문 | C39: 어제 목표 확인 질문 | D39: FALSE | E39: 회전 선정 | F39: 목표 완료는 토글만. 대상 끼니 일치 분기 제거
A40: CFG-040 | B40: 질문 | C40: 어제 결식 단백질 강제 | D40: FALSE | E40: 회전 선정 | F40: 확인 질문과 혼동하지 않고 응답 부족 축 순환
A41: CFG-041 | B41: 질문 | C41: 회전 우선순위 | D41: 질환 연결 축을 모두 한 번씩 물은 다음 날 일반 축 하나. 같은 묶음 안에서는 28일 유효답 최소 → 최근 질문 오래됨 → 질문 ID 오름차순 | E41: 회전 선정 | F41: 구조화 완료. 목표 축(V-39)과 따로 계산한다
A42: CFG-042 | B42: 집계 | C42: 미응답 처리 | D42: 응답 없으면 문항 미완료·집계 제외 | E42: 응답 저장 | F42: 미응답은 선택지가 아니다. PENDING으로 유지하며 목표 잠금; 답을 임의 점수로 치환 금지
A43: CFG-043 | B43: 집계 | C43: 오늘 선정용 스냅샷 | D43: 첫 선정 전일까지의 28일 | E43: 목표 선정 | F43: 오늘 응답은 내일 반영. 회복 분기만 오늘 고정답 사용
A44: CFG-044 | B44: 집계 | C44: 식사 시각 상태 | D44: 사실 빈도만 저장 | E44: 시간 축 | F44: 관찰 있음/없음. 좋음/나쁨 상태 사용 안 함
A45: CFG-045 | B45: 단계 | C45: 양호 시 도전 강제 | D45: FALSE | E45: 단계 선정 | F45: 모든 축 입문부터; 양호 자동 승급 제거
A46: CFG-046 | B46: 안전 | C46: 금지 필터 범위 | D46: 모든 풀·모든 대체 단계·최종 저장. 금지 필터 완화 불가 | E46: 목표 선정 | F46: 질환별 금지 성격·시간·보류 조건을 후보 재탐색과 최종 저장에도 다시 적용
A47: CFG-047 | B47: 안전 | C47: 후보 없음 | D47: 생성 안 함·안내 표시. 완료율 분모 3에 포함하고 미완료 처리 | E47: 목표 타일 | F47: 화면 표시 상태는 잠김과 구분. 목표가 없는 날도 완료율 분모에 포함하고 연속일수는 끊김
A48: CFG-049 | B48: 운영 | C48: 규칙 버전 | D48: 1.0.0 | E48: 전체 | F48: 2026-09-22
...

Sheet 검진식이연결
A1: metric_id | B1: priority_group | C1: eligible_band | D1: goal_axis_status | E1: phrase_status | F1: axis_question_id | G1: selection_policy | H1: source_note | I1: minimum_value_inclusive
A2: FPG | B2: 1 | C2: NORMAL_B,SUSPECT | D2: MAPPED | E2: REUSE_AXIS_POOL | F2: DIET-Q-01 | G2: SELECT_EXISTING_AXIS_POOL | H2: 혈당 신호는 채소 축에 연결. 단 음료·단 간식 축은 저혈당 처치 구분(I-08) 확정 전 제외
A3: BP | B3: 2 | C3: NORMAL_B,SUSPECT | D3: MAPPED | E3: REUSE_AXIS_POOL | F3: DIET-Q-03 | G3: SELECT_EXISTING_AXIS_POOL | H3: 혈압 신호는 짠맛·국물 축에 연결
A4: TC | B4: 3 | C4: NORMAL_B,SUSPECT | D4: MAPPED | E4: REUSE_AXIS_POOL | F4: DIET-Q-07 | G4: SELECT_EXISTING_AXIS_POOL | H4: 총콜레스테롤 신호는 기름진 음식 축에 연결
A5: BMI | B5: 3 | C5: NORMAL_B,SUSPECT | D5: MAPPED | E5: REUSE_AXIS_POOL | F5: DIET-Q-05 | G5: SELECT_EXISTING_AXIS_POOL | H5: BMI 원본값 25 이상만 식사 속도·양 축에 연결. 저체중 SUSPECT는 제외 | I5: 25

Sheet 질환규칙
A1: 규칙 ID | B1: 질환 유형 | C1: 출시 차수 | D1: 연결 | E1: 금지 | F1: 확인 질문 | G1: 확인 질문 표기 | H1: 연결 축 ID | I1: 금지 성격 | J1: 금지 사유 | K1: 근거 | L1: 비고 | M1: 추천 동작 | N1: 동작 근거
A2: DX-01 | B2: 당뇨병 | C2: 1차 | D2: Y | E2: Y | F2: Y | G2: 당뇨병 | H2: DIET-Q-01;DIET-Q-02;DIET-Q-05 | I2: 공복;감량 | J2: 저혈당 처치 우선. 공복 연장과 식사·탄수화물 일률 감량을 자동으로 내지 않는다 | K2: NIDDK-HYPO; NIDDK-DM | L2: 가당음료 대체를 당뇨 전원 금기로 해석하지 않는다 | M2: EXCLUDE_PHRASE | N2: 원본 link_enabled·ban_enabled 조합에서 파생
A3: DX-02 | B3: 고혈압 | C3: 1차 | D3: Y | E3: N | F3: Y | G3: 고혈압 | H3: DIET-Q-03;DIET-Q-01 | K3: 대한고혈압학회 진료지침(2022) 생활요법 | L3: 진료기록만으로 활성 질환·치료 필요·식품 금기를 확정하지 않는다. I12 · I13은 만성 신장질환(DX-05)에만 둔다 | M3: LINK_ONLY | N3: 원본 link_enabled·ban_enabled 조합에서 파생
A4: DX-03 | B4: 이상지질혈증 | C4: 1차 | D4: Y | E4: N | F4: Y | G4: 고지혈증(이상지질혈증) | H4: DIET-Q-07;DIET-Q-05 | K4: 한국지질동맥경화학회 진료지침 5판(2022) | L4: E78.6은 제외. 고중성지방(E78.1·E78.2)은 DX-04로 분리 | M4: LINK_ONLY | N4: 원본 link_enabled·ban_enabled 조합에서 파생
A5: DX-04 | B5: 이상지질혈증 · 고중성지방 | C5: 1차 | D5: Y | E5: N | F5: Y | G5: 고지혈증(이상지질혈증) | H5: DIET-Q-07;DIET-Q-05;DIET-Q-02 | K5: 한국지질동맥경화학회 진료지침 5판(2022) | L5: DX-03에 단 음료·단 간식 축을 더한 것. 원본에서 연결 축 칸 안에 조건문으로 들어 있던 것을 줄로 분리했다 | M5: LINK_ONLY | N5: 원본 link_enabled·ban_enabled 조합에서 파생
A6: DX-05 | B6: 만성 신장질환 | C6: 1차 | D6: N | E6: Y | F6: Y | G6: 만성 신장질환 | I6: 증량;감량;수분 | J6: 칼륨·인·단백질·수분은 병기·검사·투석·영양상태별로 개별화한다. 정보를 확인하기 전에는 섭취 증감·수분 목표를 자동으로 내지 않는다 | K6: KDIGO-2024; NIDDK-CKD | L6: 연결 축 없음. 금지만 적용한다. 칼륨·인·단백질·수분은 개인별로 달라 자동 목표를 내지 않는다 | M6: EXCLUDE_PHRASE | N6: 원본 link_enabled·ban_enabled 조합에서 파생
A7: DX-06 | B7: 심혈관질환 | C7: 1차 | D7: Y | E7: Y | F7: Y | G7: 심장 · 뇌혈관 질환(협심증 · 심근경색 · 뇌졸중 등) | H7: DIET-Q-03;DIET-Q-07 | I7: 수분 | J7: 심부전은 처방된 수분 계획이 우선이다 | K7: AHA-HF | L7: 뇌졸중 자체는 삼킴 장애가 아니라 질감·수분을 걸지 않는다. 삼킴 문제가 있으면 연하곤란(R13)이 따로 코딩되어 DX-20이 잡는다 | M7: EXCLUDE_PHRASE | N7: 원본 link_enabled·ban_enabled 조합에서 파생
A8: DX-07 | B8: 지방간 | C8: 1차 | D8: Y | E8: N | F8: Y | G8: 지방간 | H8: DIET-Q-02;DIET-Q-07;DIET-Q-05 | K8: 대한간학회 지침(2021) · 미국간학회(2023) | L8: 12개월 2회 또는 1회 + 검진 간기능 경계 | M8: LINK_ONLY | N8: 원본 link_enabled·ban_enabled 조합에서 파생
A9: DX-08 | B9: 임신 · 산후 · 수유 | C9: 1차 | D9: N | E9: Y | F9: N | I9: 감량;공복;증량 | J9: 전문가의 개인 영양 계획을 확인하기 전에는 일반 감량·공복·증량을 자동으로 내지 않는다 | K9: NICE-ED; FOODSAFETY | L9: 확인 질문을 하지 않는다 — 민감한 상태라 묻지 않고 막기만 한다 | M9: STOP_ALL | N9: 원본 link_enabled·ban_enabled 조합에서 파생
A10: DX-09 | B10: 섭식장애 | C10: 1차 | D10: N | E10: Y | F10: N | I10: 감량;공복;증량 | J10: 전문가의 개인 영양 계획을 확인하기 전에는 일반 감량·공복·증량을 자동으로 내지 않는다 | K10: NICE-ED; FOODSAFETY | L10: 확인 질문을 하지 않는다 | M10: STOP_ALL | N10: 원본 link_enabled·ban_enabled 조합에서 파생
A11: DX-10 | B11: 영양결핍 · 저체중 | C11: 1차 | D11: N | E11: Y | F11: N | I11: 감량;공복;증량 | J11: 전문가의 개인 영양 계획을 확인하기 전에는 일반 감량·공복·증량을 자동으로 내지 않는다 | K11: NICE-ED; FOODSAFETY | L11: 증량도 막는다. 앱이 임의로 더 먹으라고 하지 않는다는 뜻이다 | M11: STOP_ALL | N11: 원본 link_enabled·ban_enabled 조합에서 파생
A12: DX-11 | B12: 악성신생물 치료 중 | C12: 1차 | D12: N | E12: Y | F12: N | I12: 감량;공복;증량 | J12: 전문가의 개인 영양 계획을 확인하기 전에는 일반 감량·공복·증량을 자동으로 내지 않는다 | K12: NICE-ED; FOODSAFETY | L12: 확인 질문을 하지 않는다 | M12: STOP_ALL | N12: 원본 link_enabled·ban_enabled 조합에서 파생
A13: DX-12 | B13: 위 절제 · 비만수술 상태 | C13: 1차 | D13: N | E13: Y | F13: N | I13: 감량;공복;증량 | J13: 전문가의 개인 영양 계획을 확인하기 전에는 일반 감량·공복·증량을 자동으로 내지 않는다 | K13: NICE-ED; FOODSAFETY | L13: 영구 상태로 본다 | M13: STOP_ALL | N13: 원본 link_enabled·ban_enabled 조합에서 파생
A14: DX-18 | B14: 투석 · 이식 | C14: 1차 | D14: N | E14: Y | F14: N | I14: 증량;감량 | J14: 칼륨·인·단백질·수분은 병기·검사·투석·영양상태별로 개별화한다. 정보를 확인하기 전에는 증량·감량을 자동으로 내지 않는다 | K14: KDIGO-2024; NIDDK-CKD | L14: DX-05에서 코드를 분리했다. 상세기획이 투석을 보호 대상으로 적고 있고 후보 조건도 완성돼 있어 1차에 둔다 | M14: STOP_ALL | N14: 원본 link_enabled·ban_enabled 조합에서 파생
A15: DX-20 | B15: 연하장애 | C15: 1차 | D15: N | E15: Y | F15: N | I15: 감량;공복;증량;질감;수분 | J15: 삼킴이 어려운 상태에서는 음식의 양·속도·질감을 개인 평가 없이 자동으로 권하지 않는다. 묽은 액체는 후두가 닫히기 전에 기도로 넘어가기 쉬워 물·차 권유도 막는다 | K15: NICE-ED; FOODSAFETY | L15: 상세기획이 연하장애를 보호 대상으로 적고 있어 1차에 둔다. 인지장애(F00~F03 · G30)는 뺐다 — 치매 자체가 식이 목표의 금기가 아니고 후기의 삼킴 문제는 R13으로 잡힌다. 뇌졸중 경로는 DX-06이 일부 잡는다 | M15: STOP_ALL | N15: 원본 link_enabled·ban_enabled 조합에서 파생

Sheet 상병코드조건
A1: 규칙 ID | B1: 상병코드 | C1: 코드 이름 | D1: 매칭 | E1: 범위 끝 | F1: 기간(개월) | G1: 최소 횟수 | H1: 주상병만 | I1: 동반 필요 코드 | J1: 비고
A2: DX-01 | B2: E11 | C2: 2형 당뇨병 | D2: 접두 | F2: 12 | G2: 2 | H2: Y | J2: 2형 당뇨병. 세부 4자리 포함
A3: DX-01 | B3: E13 | C3: 기타 명시된 당뇨병 | D3: 접두 | F3: 12 | G3: 2 | H3: Y
A4: DX-01 | B4: E14 | C4: 상세불명의 당뇨병 | D4: 접두 | F4: 12 | G4: 2 | H4: Y
A5: DX-01 | B5: E10 | C5: 1형 당뇨병 | D5: 접두 | F5: 12 | G5: 2 | H5: Y | J5: 1형 당뇨병
A6: DX-02 | B6: I10 | C6: 본태성(원발성) 고혈압 | D6: 접두 | F6: 12 | G6: 2 | H6: Y
A7: DX-02 | B7: I11 | C7: 고혈압성 심장질환 | D7: 접두 | F7: 12 | G7: 2 | H7: Y
A8: DX-02 | B8: I15 | C8: 이차성 고혈압 | D8: 접두 | F8: 12 | G8: 2 | H8: Y
A9: DX-03 | B9: E78.0 | C9: 순수 고콜레스테롤혈증 | D9: 정확 | F9: 12 | G9: 2 | H9: Y
A10: DX-03 | B10: E78.4 | C10: 기타 고지질혈증 | D10: 정확 | F10: 12 | G10: 2 | H10: Y
A11: DX-03 | B11: E78.5 | C11: 상세불명의 고지질혈증 | D11: 정확 | F11: 12 | G11: 2 | H11: Y | J11: E78.6은 쓰지 않는다
A12: DX-04 | B12: E78.1 | C12: 순수 고글리세리드혈증 | D12: 정확 | F12: 12 | G12: 2 | H12: Y | J12: 고중성지방
A13: DX-04 | B13: E78.2 | C13: 혼합성 고지질혈증 | D13: 정확 | F13: 12 | G13: 2 | H13: Y | J13: 고중성지방
A14: DX-05 | B14: N18.3 | C14: 만성 신장질환 3기 | D14: 정확 | F14: 12 | G14: 1 | H14: Y | J14: 3기 이상은 1회로 족하다
A15: DX-05 | B15: N18.4 | C15: 만성 신장질환 4기 | D15: 정확 | F15: 12 | G15: 1 | H15: Y
A16: DX-05 | B16: N18.5 | C16: 만성 신장질환 5기 | D16: 정확 | F16: 12 | G16: 1 | H16: Y
A17: DX-05 | B17: N18.1 | C17: 만성 신장질환 1기 | D17: 정확 | F17: 12 | G17: 2 | H17: Y
A18: DX-05 | B18: N18.2 | C18: 만성 신장질환 2기 | D18: 정확 | F18: 12 | G18: 2 | H18: Y
A19: DX-05 | B19: N18.9 | C19: 상세불명의 만성 신장질환 | D19: 정확 | F19: 12 | G19: 2 | H19: Y
A20: DX-05 | B20: N19 | C20: 상세불명의 신장기능상실 | D20: 접두 | F20: 12 | G20: 2 | H20: Y
A21: DX-05 | B21: E11.2 | C21: 2형 당뇨병 · 신장 합병증 동반 | D21: 정확 | F21: 12 | G21: 2 | H21: Y | J21: 당뇨병성 신장합병증
A22: DX-05 | B22: E14.2 | C22: 상세불명 당뇨병 · 신장 합병증 동반 | D22: 정확 | F22: 12 | G22: 2 | H22: Y
A23: DX-05 | B23: I12 | C23: 고혈압성 신장질환 | D23: 접두 | F23: 12 | G23: 2 | H23: Y | J23: 고혈압성 신장질환. 고혈압(DX-02)에서 빼고 여기만 남겼다
A24: DX-05 | B24: I13 | C24: 고혈압성 심장 및 신장질환 | D24: 접두 | F24: 12 | G24: 2 | H24: Y | J24: 고혈압성 심장·신장질환. 고혈압(DX-02)에서 빼고 여기만 남겼다
A25: DX-06 | B25: I21 | C25: 급성 심근경색증 | D25: 접두 | F25: 12 | G25: 1 | H25: Y | J25: 급성 심근경색
A26: DX-06 | B26: I25.2 | C26: 진구성 심근경색증 | D26: 정확 | F26: 12 | G26: 1 | H26: Y | J26: 진구성 심근경색
A27: DX-06 | B27: I20 | C27: 협심증 | D27: 접두 | F27: 12 | G27: 2 | H27: Y
A28: DX-06 | B28: I22 | C28: 후속 심근경색증 | D28: 접두 | F28: 12 | G28: 2 | H28: Y
A29: DX-06 | B29: I23 | C29: 급성 심근경색증 후 특정 현존 합병증 | D29: 접두 | F29: 12 | G29: 2 | H29: Y
A30: DX-06 | B30: I24 | C30: 기타 급성 허혈성 심장질환 | D30: 접두 | F30: 12 | G30: 2 | H30: Y
A31: DX-06 | B31: I25 | C31: 만성 허혈성 심장질환 | D31: 접두 | F31: 12 | G31: 2 | H31: Y | J31: I25.2는 위 1회 규칙이 우선한다
A32: DX-06 | B32: I50 | C32: 심부전 | D32: 접두 | F32: 12 | G32: 2 | H32: Y | J32: 심부전
A33: DX-06 | B33: I63 | C33: 뇌경색증 | D33: 접두 | F33: 12 | G33: 1 | H33: Y | J33: 뇌경색
A34: DX-06 | B34: I64 | C34: 출혈 또는 경색으로 명시되지 않은 뇌졸중 | D34: 접두 | F34: 12 | G34: 1 | H34: Y | J34: 뇌졸중
A35: DX-06 | B35: I69 | C35: 뇌혈관질환의 후유증 | D35: 접두 | F35: 12 | G35: 1 | H35: Y | J35: 뇌혈관질환 후유증
A36: DX-07 | B36: K76.0 | C36: 달리 분류되지 않은 지방간 | D36: 정확 | F36: 12 | G36: 2 | H36: Y | J36: 12개월 2회 또는 1회 + 검진 간기능 경계
A37: DX-07 | B37: K75.8 | C37: 기타 명시된 염증성 간질환 — 비알코올성 지방간염 포함 | D37: 정확 | F37: 12 | G37: 2 | H37: Y
A38: DX-07 | B38: K70.0 | C38: 알코올성 지방간 | D38: 정확 | F38: 12 | G38: 2 | H38: Y
A39: DX-08 | B39: O00 | C39: 임신 · 출산 및 산후기 (O00~O99) | D39: 범위 | E39: O99 | F39: 10 | G39: 1 | H39: N | J39: 임신·출산·산욕
A40: DX-08 | B40: Z32.1 | C40: 임신 확인됨 | D40: 정확 | F40: 10 | G40: 1 | H40: N | J40: 원본에 기간이 없어 O 코드와 같게 두었다. 확인 필요
...

Sheet 열정의
A1: 시트 | B1: 열 | C1: 타입 | D1: 허용값 | E1: 필수 | F1: 설명
A2: 문구세트 | B2: No | C2: 정수 | E2: 필수 | F2: 일련번호. 정렬을 바꿔도 원래 순서로 되돌리기 위한 것
A3: 문구세트 | B3: 묶음 | C3: 문자열 | D3: 1차 | E3: 필수 | F3: 문구를 넘기는 단위. 지금은 전체가 1차
A4: 문구세트 | B4: 상태 | C4: 열거 | D4: 사용 · 보류 | E4: 필수 | F4: 「사용」인 것만 후보에 넣는다
A5: 문구세트 | B5: 구분 | C5: 열거 | D5: 축 × 단계 · 회복 풀 · 부담 줄이기 풀 | E5: 필수 | F5: 어느 풀에서 뽑히는지
A6: 문구세트 | B6: 축 | C6: 열거 | D6: 8축 이름 또는 — | E6: 필수 | F6: 구분이 「축 × 단계」일 때만 축 이름. 풀이면 —
A7: 문구세트 | B7: 단계 | C7: 열거 | D7: 입문 · 기본 · 도전 또는 빈칸 | E7: 선택 | F7: 실천 부담. 풀 문구는 비어 있다
A8: 문구세트 | B8: 타일 문구 | C8: 문자열 | D8: 22자 이하 | E8: 필수 | F8: 화면에 그대로 나가는 말
A9: 문구세트 | B9: 글자수 | C9: 정수 | D9: 1~22 | E9: 필수 | F9: 타일 문구의 길이. 저장 시 다시 계산한다
A10: 문구세트 | B10: 풀어 쓴 문구 | C10: 문자열 | D10: 40자 이내 | E10: 필수 | F10: 타일 문구를 풀어 쓴 한 문장. 무엇을 어떻게 하면 되는지 바로 알 수 있게 쓰고 마침표로 끝낸다. 타일 문구에 없는 새 음식·분량을 덧붙이지 않는다. 화면 위치는 화면 확정 필요
A11: 문구세트 | B11: 이유 한 줄 | C11: 문자열 | E11: 필수 | F11: 목표분석 탭 설명. 길이 한도 미정 — 화면 확정 필요
A12: 문구세트 | B12: 시간대 표시 | C12: 문자열 | D12: 저녁 · 오전 진입 · 오후 진입 또는 상황 태그 또는 — | E12: 필수 | F12: 시간 조건과 상황 태그가 섞여 있다. 상황을 알 수 없으면 그 문구는 보류
A13: 문구세트 | B13: 검진 경계 전용 | C13: 열거 | D13: O 또는 빈칸 | E13: 선택 | F13: 1차에서는 전용 문구 미사용. 검진 신호는 기존 축 문구 풀을 재사용하며 이 값은 공란 유지
A14: 문구세트 | B14: 성격 | C14: 열거 | D14: 감량 · 공복 · 증량 · 수분 · 질감 또는 빈칸 | E14: 선택 | F14: 질환별 금지가 이 값을 보고 문구를 뺀다. 빈칸은 어느 금지에도 걸리지 않는다
A15: 문구세트 | B15: 근거 | C15: 문자열 | E15: 필수 | F15: 출처 ID. 근거대조서의 출처 목록과 맞춘다
A16: 문구세트 | B16: 적용 메모 | C16: 문자열 | E16: 선택 | F16: 바꾼 이유와 남은 숙제
A17: 문구세트 | B17: 문구 ID | C17: 문자열 | D17: DIET-P-NNNN | E17: 필수 | F17: 고유 키. 목표 기록이 이 값을 스냅샷으로 저장한다
A18: 문구세트 | B18: 문구 버전 | C18: 문자열 | D18: N.N.N | E18: 필수 | F18: 문구를 고치면 올린다. 옛 버전 기록을 새 뜻으로 바꾸지 않는다
A19: 문구세트 | B19: 출처 ID | C19: 문자열 | E19: 선택 | F19: 근거 원문 식별자
A20: 질환규칙 | B20: 규칙 ID | C20: 문자열 | D20: DX-NN | E20: 필수 | F20: 고유 키
A21: 질환규칙 | B21: 질환 유형 | C21: 문자열 | E21: 필수 | F21: 사람이 읽는 이름. 코드로 쓰지 않는다
A22: 질환규칙 | B22: 출시 차수 | C22: 열거 | D22: 1차 · 2차 · 검토 | E22: 필수 | F22: 1차만 구현 대상. 2차·검토는 조건이 미정이다
A23: 질환규칙 | B23: 연결 | C23: 열거 | D23: Y · N | E23: 필수 | F23: Y면 확진 시 이 축 문구를 먼저 본다. 우선순위를 올릴 뿐 다른 축을 막지 않는다
A24: 질환규칙 | B24: 금지 | C24: 열거 | D24: Y · N | E24: 필수 | F24: Y면 아래 금지 성격에 해당하는 문구를 후보에서 뺀다
A25: 질환규칙 | B25: 확인 질문 | C25: 열거 | D25: Y · N | E25: 필수 | F25: N이면 사용자에게 묻지 않는다. 민감한 상태는 묻지 않고 막기만 한다
A26: 질환규칙 | B26: 확인 질문 표기 | C26: 문자열 | E26: 선택 | F26: 확인 질문이 Y일 때 화면에 쓰는 말
A27: 질환규칙 | B27: 연결 축 ID | C27: 문자열 | D27: DIET-Q-NN 세미콜론 구분 | E27: 선택 | F27: 축정의 시트의 질문 ID를 참조한다. 이름 문자열로 쓰지 않는다
A28: 질환규칙 | B28: 금지 성격 | C28: 열거 | D28: 감량 · 공복 · 증량 · 수분 · 질감 세미콜론 구분 | E28: 선택 | F28: 문구세트의 성격 열과 대조해 뺀다
A29: 질환규칙 | B29: 금지 사유 | C29: 문자열 | E29: 선택 | F29: 왜 막는지. 사람이 읽는 문장이며 코드가 해석하지 않는다
A30: 질환규칙 | B30: 근거 | C30: 문자열 | E30: 필수 | F30: 지침 출처
A31: 질환규칙 | B31: 비고 | C31: 문자열 | E31: 선택 | F31: 남은 확인 사항
A32: 상병코드조건 | B32: 규칙 ID | C32: 문자열 | D32: DX-NN | E32: 필수 | F32: 질환규칙 시트를 참조한다
A33: 상병코드조건 | B33: 상병코드 | C33: 문자열 | D33: KCD 코드 | E33: 필수 | F33: 한 줄에 코드 하나
A34: 상병코드조건 | B34: 코드 이름 | C34: 문자열 | E34: 필수 | F34: 그 코드가 무엇인지 사람이 읽기 위한 것. 판정에 쓰지 않는다. ICD-10 기준 표기이며 실제 KCD 마스터의 공식 명칭·5단위 세분류와 대조해야 한다
A35: 상병코드조건 | B35: 매칭 | C35: 열거 | D35: 접두 · 정확 · 범위 | E35: 필수 | F35: 접두는 그 코드로 시작하는 전부. 정확은 그 코드만. 범위는 범위 끝까지
A36: 상병코드조건 | B36: 범위 끝 | C36: 문자열 | D36: KCD 코드 | E36: 선택 | F36: 매칭이 「범위」일 때만 채운다
A37: 상병코드조건 | B37: 기간(개월) | C37: 정수 | E37: 선택 | F37: 비어 있으면 기간을 보지 않는다(영구 상태) 또는 조건 미정
A38: 상병코드조건 | B38: 최소 횟수 | C38: 정수 | E38: 선택 | F38: 이 횟수 이상이면 진단 후보로 올린다
A39: 상병코드조건 | B39: 주상병만 | C39: 열거 | D39: Y · N | E39: 선택 | F39: Y면 주상병만 센다
A40: 상병코드조건 | B40: 동반 필요 코드 | C40: 문자열 | D40: 세미콜론 구분 | E40: 선택 | F40: 이 코드가 같이 있을 때만 성립한다
...

Sheet 내정보질환매핑
A1: condition_code | B1: display_name | C1: diet_status | D1: rule_id | E1: mapping_note | F1: source_ui
A2: HYPERTENSION | B2: 고혈압 | C2: MAPPED | D2: DX-02 | E2: 기존 짠맛 축에 연결 | F2: 공개 프로토타입 > 더보기 > 내정보 > 만성질환
A3: DIABETES | B3: 당뇨병 | C3: MAPPED | D3: DX-01 | E3: 기존 단 음료·간식 축에 연결; 공복·감량 금지 적용 | F3: 공개 프로토타입 > 더보기 > 내정보 > 만성질환
A4: DYSLIPIDEMIA | B4: 이상지질혈증 | C4: MAPPED | D4: DX-03 | E4: 기존 기름진 음식 축에 연결; 고중성지방 세부형은 추정하지 않음 | F4: 공개 프로토타입 > 더보기 > 내정보 > 만성질환
A5: CHRONIC_KIDNEY_DISEASE | B5: 만성 신장질환 | C5: SAFETY_ONLY | D5: DX-05 | E5: 자가 선택 시 새 연결 축 없이 섭취 증감·수분 목표 금지에만 사용 | F5: 공개 프로토타입 > 더보기 > 내정보 > 만성질환

Sheet 달력일자
A1: country_code | B1: calendar_date | C1: calendar_code | D1: calendar_name | E1: source_id | F1: updated_at
A2: KR | B2: 2026-02-16 | C2: HOLIDAY | D2: 설 연휴 | E2: 기획 확정(10-08). 공식 공고 확인 전 | F2: 2026-10-08
A3: KR | B3: 2026-02-17 | C3: HOLIDAY | D3: 설 연휴 | E3: 기획 확정(10-08). 공식 공고 확인 전 | F3: 2026-10-08
A4: KR | B4: 2026-02-18 | C4: HOLIDAY | D4: 설 연휴 | E4: 기획 확정(10-08). 공식 공고 확인 전 | F4: 2026-10-08
A5: KR | B5: 2026-09-24 | C5: HOLIDAY | D5: 추석 연휴 | E5: 기획 확정(10-08). 공식 공고 확인 전 | F5: 2026-10-08
A6: KR | B6: 2026-09-25 | C6: HOLIDAY | D6: 추석 연휴 | E6: 기획 확정(10-08). 공식 공고 확인 전 | F6: 2026-10-08
A7: KR | B7: 2026-09-26 | C7: HOLIDAY | D7: 추석 연휴 | E7: 기획 확정(10-08). 공식 공고 확인 전 | F7: 2026-10-08
A8: KR | B8: 2027-02-05 | C8: HOLIDAY | D8: 설 연휴 | E8: 기획 확정(10-08). 공식 공고 확인 전 | F8: 2026-10-08
A9: KR | B9: 2027-02-06 | C9: HOLIDAY | D9: 설 연휴 | E9: 기획 확정(10-08). 공식 공고 확인 전 | F9: 2026-10-08
A10: KR | B10: 2027-02-07 | C10: HOLIDAY | D10: 설 연휴 | E10: 기획 확정(10-08). 공식 공고 확인 전 | F10: 2026-10-08
A11: KR | B11: 2027-02-08 | C11: HOLIDAY | D11: 설 연휴 | E11: 기획 확정(10-08). 공식 공고 확인 전 | F11: 2026-10-08
A12: KR | B12: 2027-09-14 | C12: HOLIDAY | D12: 추석 연휴 | E12: 기획 확정(10-08). 공식 공고 확인 전 | F12: 2026-10-08
... A14: KR | B14: 2027-09-16 | C14: HOLIDAY | D14: 추석 연휴 | E14: 기획 확정(10-08). 공식 공고 확인 전 | F14: 2026-10-08

Sheet 노출조건
A1: phrase_id | B1: phrase_version | C1: raw_tag | D1: time_code | E1: calendar_code | F1: context_code | G1: after_dinner_eligible | H1: parse_status | I1: context_match_mode | J1: context_codes | K1: source_row
A2: DIET-P-0001 | B2: 1.0.0 | C2: 오전 진입 | D2: MORNING_ENTRY | E2: ANY | F2: ANY | G2: FALSE | H2: READY | K2: 2
A3: DIET-P-0002 | B3: 1.0.0 | C3: 오전 진입 | D3: MORNING_ENTRY | E3: ANY | F3: ANY | G3: FALSE | H3: READY | K3: 3
A4: DIET-P-0003 | B4: 1.0.0 | D4: ANY | E4: ANY | F4: ANY | G4: FALSE | H4: READY | K4: 4
A5: DIET-P-0004 | B5: 1.0.0 | D5: ANY | E5: ANY | F5: ANY | G5: FALSE | H5: READY | K5: 5
A6: DIET-P-0005 | B6: 1.0.0 | D6: ANY | E6: ANY | F6: ANY | G6: FALSE | H6: READY | K6: 6
A7: DIET-P-0006 | B7: 1.0.0 | D7: ANY | E7: ANY | F7: ANY | G7: FALSE | H7: READY | K7: 7
A8: DIET-P-0007 | B8: 1.0.0 | C8: 저녁 | D8: ANY | E8: ANY | F8: ANY | G8: FALSE | H8: READY | K8: 8
A9: DIET-P-0008 | B9: 1.0.0 | D9: ANY | E9: ANY | F9: ANY | G9: FALSE | H9: READY | K9: 9
A10: DIET-P-0009 | B10: 1.0.0 | D10: ANY | E10: ANY | F10: ANY | G10: FALSE | H10: READY | K10: 10
A11: DIET-P-0010 | B11: 1.0.0 | D11: ANY | E11: ANY | F11: ANY | G11: FALSE | H11: READY | K11: 11
A12: DIET-P-0011 | B12: 1.0.0 | C12: 저녁 | D12: ANY | E12: ANY | F12: ANY | G12: FALSE | H12: READY | K12: 12
A13: DIET-P-0012 | B13: 1.0.0 | D13: ANY | E13: ANY | F13: ANY | G13: FALSE | H13: READY | K13: 13
A14: DIET-P-0014 | B14: 1.0.0 | D14: ANY | E14: ANY | F14: ANY | G14: FALSE | H14: READY | K14: 14
A15: DIET-P-0015 | B15: 1.0.0 | D15: ANY | E15: ANY | F15: ANY | G15: FALSE | H15: READY | K15: 15
A16: DIET-P-0016 | B16: 1.0.0 | D16: ANY | E16: ANY | F16: ANY | G16: FALSE | H16: READY | K16: 16
A17: DIET-P-0017 | B17: 1.0.0 | D17: ANY | E17: ANY | F17: ANY | G17: FALSE | H17: READY | K17: 17
A18: DIET-P-0022 | B18: 1.0.0 | D18: ANY | E18: ANY | F18: ANY | G18: FALSE | H18: READY | K18: 18
A19: DIET-P-0023 | B19: 1.0.0 | D19: ANY | E19: ANY | F19: ANY | G19: FALSE | H19: READY | K19: 19
A20: DIET-P-0025 | B20: 1.0.0 | D20: ANY | E20: ANY | F20: ANY | G20: FALSE | H20: READY | K20: 20
A21: DIET-P-0027 | B21: 1.0.0 | D21: ANY | E21: ANY | F21: ANY | G21: FALSE | H21: READY | K21: 21
A22: DIET-P-0028 | B22: 1.0.0 | D22: ANY | E22: ANY | F22: ANY | G22: FALSE | H22: READY | K22: 22
A23: DIET-P-0029 | B23: 1.0.0 | D23: ANY | E23: ANY | F23: ANY | G23: FALSE | H23: READY | K23: 23
A24: DIET-P-0030 | B24: 1.0.0 | D24: ANY | E24: ANY | F24: ANY | G24: FALSE | H24: READY | K24: 24
... A26: DIET-P-0032 | B26: 1.0.0 | D26: ANY | E26: ANY | F26: ANY | G26: FALSE | H26: READY | K26: 26
A27: DIET-P-0033 | B27: 1.0.0 | C27: 저녁 | D27: EVENING | E27: ANY | F27: ANY | G27: TRUE | H27: READY | K27: 27
A28: DIET-P-0034 | B28: 1.0.0 | D28: ANY | E28: ANY | F28: ANY | G28: FALSE | H28: READY | K28: 28
A29: DIET-P-0035 | B29: 1.0.0 | C29: 오후 진입 | D29: AFTERNOON_ENTRY | E29: ANY | F29: ANY | G29: FALSE | H29: READY | K29: 29
A30: DIET-P-0036 | B30: 1.0.0 | D30: ANY | E30: ANY | F30: ANY | G30: FALSE | H30: READY | K30: 30
A31: DIET-P-0037 | B31: 1.0.0 | C31: 저녁 | D31: ANY | E31: ANY | F31: ANY | G31: FALSE | H31: READY | K31: 31
A32: DIET-P-0039 | B32: 1.0.0 | C32: 오전 진입 | D32: MORNING_ENTRY | E32: ANY | F32: ANY | G32: FALSE | H32: READY | K32: 32
A33: DIET-P-0040 | B33: 1.0.0 | C33: 오전 진입 | D33: MORNING_ENTRY | E33: ANY | F33: ANY | G33: FALSE | H33: READY | K33: 33
A34: DIET-P-0041 | B34: 1.0.0 | C34: — | D34: ANY | E34: ANY | F34: ANY | G34: FALSE | H34: READY | K34: 34
A35: DIET-P-0042 | B35: 1.0.0 | C35: — | D35: ANY | E35: ANY | F35: ANY | G35: FALSE | H35: READY | K35: 35
A36: DIET-P-0044 | B36: 1.0.0 | C36: — | D36: ANY | E36: ANY | F36: ANY | G36: FALSE | H36: READY | K36: 37
A37: DIET-P-0045 | B37: 1.0.0 | C37: — | D37: ANY | E37: ANY | F37: ANY | G37: FALSE | H37: READY | K37: 38
A38: DIET-P-0046 | B38: 1.0.0 | C38: — | D38: ANY | E38: ANY | F38: ANY | G38: FALSE | H38: READY | K38: 39
A39: DIET-P-0047 | B39: 1.0.0 | C39: — | D39: ANY | E39: ANY | F39: ANY | G39: FALSE | H39: READY | K39: 40
A40: DIET-P-0048 | B40: 1.0.0 | C40: — | D40: ANY | E40: ANY | F40: ANY | G40: FALSE | H40: READY | K40: 41
A41: DIET-P-0049 | B41: 1.0.0 | C41: — | D41: ANY | E41: ANY | F41: ANY | G41: FALSE | H41: READY | K41: 42
...

Sheet 문구세트
A1: No | B1: 묶음 | C1: 상태 | D1: 구분 | E1: 축 | F1: 단계 | G1: 타일 문구 | H1: 글자수 | I1: 풀어 쓴 문구 | J1: 이유 한 줄 | K1: 노출 조건 표시 | L1: 검진 경계 전용 | M1: 성격 | N1: 근거 | O1: 적용 메모 | P1: 문구 ID | Q1: 문구 버전 | R1: 출처 ID
A2: 1 | B2: 1차 | C2: 사용 | D2: 축 × 단계 | E2: 끼니 규칙 | F2: 입문 | G2: 아침에 뭐라도 한 입 | H2: 11 | I2: 아침을 거르지 말고, 먹을 수 있는 음식을 한 입이라도 드세요. | J2: 먹을 수 있는 음식부터 식사를 시작해 보는 행동이에요. | K2: 오전 진입 | M2: 증량 | N2: WHO-DIET | O2: 근거 범위에 맞춰 이유 문장 수정 | P2: DIET-P-0001 | Q2: 1.0.0 | R2: WHO-DIET
A3: 2 | B3: 1차 | C3: 사용 | D3: 축 × 단계 | E3: 끼니 규칙 | F3: 기본 | G3: 아침 거르지 않기 | H3: 9 | I3: 오늘은 아침 식사를 거르지 말고 챙겨 드세요. | J3: 아침 식사를 챙기는 행동이에요. | K3: 오전 진입 | M3: 증량 | N3: WHO-DIET | O3: 근거 범위에 맞춰 이유 문장 수정 | P3: DIET-P-0002 | Q3: 1.0.0 | R3: WHO-DIET
A4: 3 | B4: 1차 | C4: 사용 | D4: 축 × 단계 | E4: 끼니 규칙 | F4: 기본 | G4: 점심 · 저녁 챙기기 | H4: 11 | I4: 오늘은 점심과 저녁 식사를 거르지 말고 챙겨 드세요. | J4: 점심과 저녁 식사를 챙기는 행동이에요. | M4: 증량 | N4: WHO-DIET | O4: 근거 범위에 맞춰 이유 문장 수정 | P4: DIET-P-0003 | Q4: 1.0.0 | R4: WHO-DIET
A5: 4 | B5: 1차 | C5: 사용 | D5: 축 × 단계 | E5: 끼니 규칙 | F5: 도전 | G5: 세 끼 제때 먹기 | H5: 9 | I5: 오늘도 아침·점심·저녁 세 끼를 제때 드세요. | J5: 세 끼를 제때 먹도록 계획해 보는 행동이에요. | N5: WHO-DIET | O5: 근거 범위에 맞춰 이유 문장 수정 · 10-19 특정 음식 이름을 음식 종류로 | P5: DIET-P-0004 | Q5: 1.0.0 | R5: WHO-DIET
A6: 5 | B6: 1차 | C6: 사용 | D6: 축 × 단계 | E6: 채소 | F6: 입문 | G6: 한 끼에 채소 하나 | H6: 10 | I6: 오늘 한 끼는 채소 반찬을 한 가지 이상 곁들여 드세요. | J6: 한 끼에 채소 반찬을 포함하는 행동이에요. | M6: 증량 | N6: WHO-DIET; NIDDK-CKD | O6: 근거 범위에 맞춰 이유 문장 수정 | P6: DIET-P-0005 | Q6: 1.0.0 | R6: WHO-DIET / NIDDK-CKD
A7: 6 | B7: 1차 | C7: 사용 | D7: 축 × 단계 | E7: 채소 | F7: 기본 | G7: 채소 반찬 하나 더 | H7: 10 | I7: 오늘 식사에 평소보다 채소 반찬을 한 가지 더 올려 보세요. | J7: 채소 반찬을 한 가지 더 준비해 보는 행동이에요. | M7: 증량 | N7: WHO-DIET; NIDDK-CKD | O7: 근거 범위에 맞춰 이유 문장 수정 | P7: DIET-P-0006 | Q7: 1.0.0 | R7: WHO-DIET / NIDDK-CKD
A8: 7 | B8: 1차 | C8: 사용 | D8: 축 × 단계 | E8: 채소 | F8: 기본 | G8: 저녁은 채소부터 먹기 | H8: 11 | I8: 저녁을 먹을 때 밥이나 고기보다 채소 반찬을 먼저 드세요. | J8: 채소 반찬부터 먹어 보는 행동이에요. | K8: 저녁 | N8: WHO-DIET; NIDDK-CKD | O8: 근거 범위에 맞춰 이유 문장 수정 | P8: DIET-P-0007 | Q8: 1.0.0 | R8: WHO-DIET / NIDDK-CKD
A9: 8 | B9: 1차 | C9: 사용 | D9: 축 × 단계 | E9: 채소 | F9: 도전 | G9: 끼니마다 채소부터 먹기 | H9: 12 | I9: 오늘은 끼니마다 밥이나 고기보다 채소 반찬을 먼저 드세요. | J9: 각 끼니에서 채소를 먼저 먹어 보는 행동이에요. | N9: WHO-DIET; NIDDK-CKD | O9: 근거 범위에 맞춰 이유 문장 수정 | P9: DIET-P-0008 | Q9: 1.0.0 | R9: WHO-DIET / NIDDK-CKD
A10: 9 | B10: 1차 | C10: 사용 | D10: 축 × 단계 | E10: 단 음료 · 단 간식 | F10: 입문 | G10: 한 잔은 물로 바꾸기 | H10: 11 | I10: 오늘 마실 단 음료 중 한 잔은 물로 바꿔 보세요. | J10: 단 음료 한 번을 물로 바꾸는 행동이에요. | M10: 수분 | N10: WHO-DIET; AHA-HF | O10: 근거 범위에 맞춰 이유 문장 수정 | P10: DIET-P-0009 | Q10: 1.0.0 | R10: WHO-DIET / AHA-HF
A11: 10 | B11: 1차 | C11: 사용 | D11: 축 × 단계 | E11: 단 음료 · 단 간식 | F11: 기본 | G11: 단 음료는 물로 바꾸기 | H11: 12 | I11: 단 음료가 생각나면 물이나 설탕 없는 음료로 바꿔 드세요. | J11: 설탕을 넣지 않은 음료로 바꾸는 행동이에요. | M11: 수분 | N11: WHO-DIET; AHA-HF; NIDDK-HYPO | O11: 근거 범위에 맞춰 이유 문장 수정 | P11: DIET-P-0010 | Q11: 1.0.0 | R11: WHO-DIET / AHA-HF / NIDDK-HYPO
A12: 11 | B12: 1차 | C12: 사용 | D12: 축 × 단계 | E12: 단 음료 · 단 간식 | F12: 기본 | G12: 저녁 디저트 건너뛰기 | H12: 11 | I12: 저녁 식사 뒤 디저트나 단 간식은 오늘 하루 건너뛰어 보세요. | J12: 추가 디저트를 먹을지 살펴보는 행동이에요. | K12: 저녁 | M12: 공복 | N12: WHO-DIET; NIDDK-HYPO | O12: 근거 범위에 맞춰 이유 문장 수정 | P12: DIET-P-0011 | Q12: 1.0.0 | R12: WHO-DIET / NIDDK-HYPO
A13: 12 | B13: 1차 | C13: 사용 | D13: 축 × 단계 | E13: 단 음료 · 단 간식 | F13: 도전 | G13: 오늘은 단 음료 없이 | H13: 11 | I13: 오늘 하루는 평소 마시던 단 음료를 마시지 않고 지내 보세요. | J13: 평소 마시던 단 음료를 쉬어 보는 행동이에요. | M13: 공복 | N13: WHO-DIET; AHA-HF; NIDDK-HYPO | O13: 근거 범위에 맞춰 이유 문장 수정 | P13: DIET-P-0012 | Q13: 1.0.0 | R13: WHO-DIET / AHA-HF / NIDDK-HYPO
A14: 14 | B14: 1차 | C14: 사용 | D14: 축 × 단계 | E14: 짠맛 · 국물 | F14: 입문 | G14: 한 끼는 국물 반만 | H14: 10 | I14: 오늘 한 끼는 국이나 찌개 국물을 평소의 절반만 드세요. | J14: 국물을 덜 먹으면 그 국물에 든 나트륨 섭취도 줄어요. | M14: 감량 | N14: WHO-DIET; AHA-HF; NIDDK-HYPO | O14: 근거 범위에 맞춰 이유 문장 수정 | P14: DIET-P-0014 | Q14: 1.0.0 | R14: WHO-DIET / AHA-HF / NIDDK-HYPO
A15: 15 | B15: 1차 | C15: 사용 | D15: 축 × 단계 | E15: 짠맛 · 국물 | F15: 기본 | G15: 국물은 건더기 위주로 | H15: 11 | I15: 국이나 찌개를 먹을 때 국물보다 건더기 위주로 드세요. | J15: 국물 섭취량을 줄이는 행동이에요. | N15: WHO-DIET; AHA-HF | O15: 근거 범위에 맞춰 이유 문장 수정 | P15: DIET-P-0015 | Q15: 1.0.0 | R15: WHO-DIET / AHA-HF
A16: 16 | B16: 1차 | C16: 사용 | D16: 축 × 단계 | E16: 짠맛 · 국물 | F16: 기본 | G16: 한 끼는 싱겁게 먹기 | H16: 11 | I16: 오늘 한 끼는 소금이나 간장을 더 넣지 말고 싱겁게 드세요. | J16: 추가하는 소금과 장의 양을 줄이는 행동이에요. | N16: WHO-DIET; NIDDK-HYPO | O16: 근거 범위에 맞춰 이유 문장 수정 | P16: DIET-P-0016 | Q16: 1.0.0 | R16: WHO-DIET / NIDDK-HYPO
A17: 17 | B17: 1차 | C17: 사용 | D17: 축 × 단계 | E17: 짠맛 · 국물 | F17: 도전 | G17: 나트륨 표시 보기 | H17: 9 | I17: 가공식품을 살 때 포장의 나트륨 표시를 보고 덜 짠 것을 고르세요. | J17: 제품의 나트륨 표시를 비교해 고르는 행동이에요. | N17: WHO-DIET | O17: 행동 문구 수정; 근거 범위에 맞춰 이유 문장 수정 | P17: DIET-P-0017 | Q17: 1.0.0 | R17: WHO-DIET
A18: 22 | B18: 1차 | C18: 사용 | D18: 축 × 단계 | E18: 식사 속도 · 양 | F18: 입문 | G18: 식사 중 수저 내려놓기 | H18: 12 | I18: 식사 중간에 수저를 잠깐 내려놓고 먹는 속도를 살펴보세요. | J18: 식사 중 잠깐 멈춰 먹는 속도를 살펴봐요. | N18: WHO-DIET; NICE-ED | O18: 근거 범위에 맞춰 이유 문장 수정 | P18: DIET-P-0022 | Q18: 1.0.0 | R18: WHO-DIET / NICE-ED
A19: 23 | B19: 1차 | C19: 사용 | D19: 축 × 단계 | E19: 식사 속도 · 양 | F19: 기본 | G19: 한 끼는 천천히 먹기 | H19: 11 | I19: 오늘 한 끼는 서두르지 말고 시간을 들여 천천히 드세요. | J19: 식사를 서두르지 않고 먹어 보는 행동이에요. | N19: WHO-DIET; NICE-ED | O19: 행동 문구 수정; 근거 범위에 맞춰 이유 문장 수정 | P19: DIET-P-0023 | Q19: 1.0.0 | R19: WHO-DIET / NICE-ED
A20: 25 | B20: 1차 | C20: 사용 | D20: 축 × 단계 | E20: 식사 속도 · 양 | F20: 도전 | G20: 먹으면서 배부름 살피기 | H20: 12 | I20: 식사하는 중간중간 배가 얼마나 부른지 스스로 살펴보세요. | J20: 식사 중 배부른 정도를 살펴보는 행동이에요. | M20: 감량 | N20: WHO-DIET; NICE-ED | O20: 행동 문구 수정; 근거 범위에 맞춰 이유 문장 수정 | P20: DIET-P-0025 | Q20: 1.0.0 | R20: WHO-DIET / NICE-ED
A21: 27 | B21: 1차 | C21: 사용 | D21: 축 × 단계 | E21: 단백질 | F21: 입문 | G21: 조금이라도 단백질 먹기 | H21: 12 | I21: 오늘 식사에 고기·생선·달걀·두부 중 하나를 조금이라도 드세요. | J21: 단백질이 든 식품을 식사에 포함하는 행동이에요. | M21: 증량 | N21: WHO-DIET; NIDDK-CKD | O21: 근거 범위에 맞춰 이유 문장 수정 | P21: DIET-P-0027 | Q21: 1.0.0 | R21: WHO-DIET / NIDDK-CKD
A22: 28 | B22: 1차 | C22: 사용 | D22: 축 × 단계 | E22: 단백질 | F22: 기본 | G22: 반찬 하나는 단백질로 | H22: 11 | I22: 반찬 중 한 가지는 고기·생선·달걀·두부 같은 단백질 반찬으로 드세요. | J22: 식사에 단백질 반찬이 있는지 살펴봐요. | M22: 증량 | N22: WHO-DIET; NIDDK-CKD | O22: 근거 범위에 맞춰 이유 문장 수정 | P22: DIET-P-0028 | Q22: 1.0.0 | R22: WHO-DIET / NIDDK-CKD
A23: 29 | B23: 1차 | C23: 사용 | D23: 축 × 단계 | E23: 단백질 | F23: 도전 | G23: 끼니마다 단백질 챙기기 | H23: 12 | I23: 오늘은 아침·점심·저녁 끼니마다 단백질 반찬을 한 가지씩 드세요. | J23: 각 끼니의 단백질 식품 구성을 살펴봐요. | M23: 증량 | N23: WHO-DIET; NIDDK-CKD | O23: 근거 범위에 맞춰 이유 문장 수정 | P23: DIET-P-0029 | Q23: 1.0.0 | R23: WHO-DIET / NIDDK-CKD
A24: 30 | B24: 1차 | C24: 사용 | D24: 축 × 단계 | E24: 기름진 음식 | F24: 입문 | G24: 튀긴 반찬은 하나만 | H24: 10 | I24: 한 끼에 튀긴 반찬은 한 가지만 골라 조금만 드세요. | J24: 튀긴 반찬의 종류와 먹는 양을 살펴봐요. | M24: 감량 | N24: WHO-DIET | O24: 근거 범위에 맞춰 이유 문장 수정 | P24: DIET-P-0030 | Q24: 1.0.0 | R24: WHO-DIET
A25: 31 | B25: 1차 | C25: 사용 | D25: 축 × 단계 | E25: 기름진 음식 | F25: 기본 | G25: 간식은 견과류로 | H25: 8 | I25: 출출할 때 과자 같은 간식 대신 견과류를 조금 드세요. | J25: 간식 종류를 바꿔 보는 행동이에요. | M25: 질감 | N25: WHO-DIET; NIDDK-CKD | O25: 근거 범위에 맞춰 이유 문장 수정 | P25: DIET-P-0031 | Q25: 1.0.0 | R25: WHO-DIET / NIDDK-CKD
A26: 32 | B26: 1차 | C26: 사용 | D26: 축 × 단계 | E26: 기름진 음식 | F26: 도전 | G26: 고기 대신 생선으로 | H26: 10 | I26: 오늘 한 끼는 고기 반찬 대신 생선 반찬으로 바꿔 드세요. | J26: 단백질 식품의 종류를 바꿔 보는 행동이에요. | N26: WHO-DIET; NIDDK-CKD; NIDDK-HYPO | O26: 근거 범위에 맞춰 이유 문장 수정 | P26: DIET-P-0032 | Q26: 1.0.0 | R26: WHO-DIET / NIDDK-CKD / NIDDK-HYPO
A27: 33 | B27: 1차 | C27: 사용 | D27: 회복 풀 | E27: — | F27: 단계 없음 | G27: 다음 끼니 잘 챙기기 | H27: 11 | I27: 이번 끼니를 거르거나 적게 먹었다면, 다음 끼니는 꼭 챙겨 드세요. | J27: 부족했던 섭취를 고려해 다음 식사를 챙겨요. | K27: 저녁 | M27: 증량 | N27: WHO-DIET | O27: 행동 문구 수정; 근거 범위에 맞춰 이유 문장 수정 · 10-19 특정 음식 이름을 음식 종류로 | P27: DIET-P-0033 | Q27: 1.0.0 | R27: WHO-DIET
A28: 34 | B28: 1차 | C28: 사용 | D28: 회복 풀 | E28: — | F28: 단계 없음 | G28: 단백질 한 입 먹기 | H28: 10 | I28: 다음 식사 때 달걀·두부·생선 같은 단백질 반찬을 한 입이라도 드세요. | J28: 단백질 식품만으로 한 끼가 충분하다고 판단하지 않아요. | M28: 증량 | N28: WHO-DIET | O28: 근거 범위에 맞춰 이유 문장 수정 | P28: DIET-P-0034 | Q28: 1.0.0 | R28: WHO-DIET
A29: 35 | B29: 1차 | C29: 사용 | D29: 회복 풀 | E29: — | F29: 단계 없음 | G29: 간식이라도 챙겨 먹기 | H29: 11 | I29: 끼니를 적게 먹었다면 먹을 수 있는 간식이라도 조금 챙겨 드세요. | J29: 끼니를 적게 먹었다면 먹을 수 있는 간식을 살펴봐요. | K29: 오후 진입 | M29: 증량 | N29: WHO-DIET | O29: 근거 범위에 맞춰 이유 문장 수정 | P29: DIET-P-0035 | Q29: 1.0.0 | R29: WHO-DIET
A30: 36 | B30: 1차 | C30: 사용 | D30: 부담 줄이기 풀 | E30: — | F30: 단계 없음 | G30: 늦은 시간, 카페인 줄이기 | H30: 14 | I30: 늦은 오후부터는 커피·녹차 같은 카페인 음료를 줄여 보세요. | J30: 카페인에 민감하다면 늦은 시간 섭취를 줄여 볼 수 있어요. | N30: WHO-DIET; NIDDK-HYPO | O30: 행동 문구 수정; 근거 범위에 맞춰 이유 문장 수정 | P30: DIET-P-0036 | Q30: 1.0.0 | R30: WHO-DIET / NIDDK-HYPO
A31: 37 | B31: 1차 | C31: 사용 | D31: 부담 줄이기 풀 | E31: — | F31: 단계 없음 | G31: 부담 없는 저녁 차리기 | H31: 12 | I31: 피곤한 날엔 손이 덜 가고 먹기 편한 음식으로 저녁을 차려 보세요. | J31: 피곤한 날 먹을 수 있는 식사를 준비해요. | K31: 저녁 | N31: WHO-DIET | O31: 행동 문구 수정; 근거 범위에 맞춰 이유 문장 수정 | P31: DIET-P-0037 | Q31: 1.0.0 | R31: WHO-DIET
A32: 39 | B32: 1차 | C32: 사용 | D32: 부담 줄이기 풀 | E32: — | F32: 단계 없음 | G32: 점심은 평소 양으로 | H32: 10 | I32: 점심은 거르거나 줄이지 말고 평소 먹던 양만큼 드세요. | J32: 평소 식사 계획에 맞춰 점심을 챙겨요. | K32: 오전 진입 | N32: WHO-DIET; NIDDK-HYPO | O32: 근거 범위에 맞춰 이유 문장 수정 | P32: DIET-P-0039 | Q32: 1.0.0 | R32: WHO-DIET / NIDDK-HYPO
A33: 40 | B33: 1차 | C33: 사용 | D33: 축 × 단계 | E33: 끼니 규칙 | F33: 입문 | G33: 아침에 우유 곁들이기 | H33: 11 | I33: 아침 식사에 우유를 한 잔 곁들여 드세요. | J33: 마실 것을 식사의 일부로 준비하는 행동이에요. | K33: 오전 진입 | M33: 증량 | N33: WHO-DIET; NIDDK-CKD; AHA-HF | O33: 행동 문구 수정; 근거 범위에 맞춰 이유 문장 수정 | P33: DIET-P-0040 | Q33: 1.0.0 | R33: WHO-DIET / NIDDK-CKD / AHA-HF
A34: 41 | B34: 1차 | C34: 사용 | D34: 축 × 단계 | E34: 끼니 규칙 | F34: 기본 | G34: 점심 늦지 않게 먹기 | H34: 11 | I34: 바쁘더라도 점심 먹을 시간을 미리 비워 두고 늦지 않게 드세요. | J34: 일정에 맞춰 점심 먹을 시간을 확보해요. | K34: — | N34: WHO-DIET | O34: 근거 범위에 맞춰 이유 문장 수정 | P34: DIET-P-0041 | Q34: 1.0.0 | R34: WHO-DIET
A35: 42 | B35: 1차 | C35: 사용 | D35: 축 × 단계 | E35: 끼니 규칙 | F35: 도전 | G35: 오늘 세 끼 챙기기 | H35: 10 | I35: 오늘은 아침·점심·저녁 세 끼를 거르지 않고 모두 드세요. | J35: 개인 식사 계획에 맞춰 끼니를 챙겨요. | K35: — | M35: 증량 | N35: WHO-DIET | O35: 근거 범위에 맞춰 이유 문장 수정 | P35: DIET-P-0042 | Q35: 1.0.0 | R35: WHO-DIET
A36: 44 | B36: 1차 | C36: 사용 | D36: 축 × 단계 | E36: 채소 | F36: 기본 | G36: 국 대신 나물 반찬 | H36: 10 | I36: 오늘 한 끼는 국 대신 나물 같은 채소 반찬을 골라 드세요. | J36: 국 대신 채소 반찬을 고르는 행동이에요. | K36: — | N36: WHO-DIET; AHA-HF; NIDDK-HYPO | O36: 근거 범위에 맞춰 이유 문장 수정 · 10-19 「A 대신 B」꼴은 기본 단계로 | P36: DIET-P-0044 | Q36: 1.0.0 | R36: WHO-DIET / AHA-HF / NIDDK-HYPO
A37: 45 | B37: 1차 | C37: 사용 | D37: 축 × 단계 | E37: 채소 | F37: 입문 | G37: 고기와 쌈 채소 먹기 | H37: 11 | I37: 고기를 먹을 때 상추·깻잎 같은 쌈 채소에 싸서 드세요. | J37: 쌈 채소는 가장 쉽게 채소를 더하는 방법이에요. | K37: — | M37: 증량 | N37: WHO-DIET; NIDDK-CKD | O37: 효과 단정 없이 행동 설명으로 유지. 개인별 적합성·문구 적합성 검토 필요 | P37: DIET-P-0045 | Q37: 1.0.0 | R37: WHO-DIET / NIDDK-CKD
A38: 46 | B38: 1차 | C38: 사용 | D38: 축 × 단계 | E38: 채소 | F38: 기본 | G38: 외식 메뉴, 채소 곁들이기 | H38: 14 | I38: 밖에서 먹을 때도 나물 · 쌈 같은 채소 반찬을 곁들여 드세요. | J38: 채소를 곁들이면 외식에서도 채소를 챙겨요. | K38: — | M38: 증량 | N38: WHO-DIET; NIDDK-CKD | O38: 근거 범위에 맞춰 이유 문장 수정 · 10-19 외식 메뉴 고르기로 · 10-19 외식 메뉴에 채소 곁들이기로 | P38: DIET-P-0046 | Q38: 1.0.0 | R38: WHO-DIET / NIDDK-CKD
A39: 47 | B39: 1차 | C39: 사용 | D39: 축 × 단계 | E39: 채소 | F39: 도전 | G39: 끼니마다 채소 두 가지 | H39: 12 | I39: 오늘은 끼니마다 서로 다른 채소 반찬을 두 가지씩 드세요. | J39: 끼니마다 채소 종류를 다양하게 골라 봐요. | K39: — | M39: 증량 | N39: WHO-DIET; NIDDK-CKD | O39: 근거 범위에 맞춰 이유 문장 수정 | P39: DIET-P-0047 | Q39: 1.0.0 | R39: WHO-DIET / NIDDK-CKD
A40: 48 | B40: 1차 | C40: 사용 | D40: 축 × 단계 | E40: 채소 | F40: 도전 | G40: 점심도 채소부터 먹기 | H40: 11 | I40: 저녁처럼 점심에도 채소 반찬을 가장 먼저 드세요. | J40: 저녁뿐 아니라 점심에도 순서를 바꿔 보는 단계예요. | K40: — | N40: WHO-DIET; NIDDK-CKD | O40: 효과 단정 없이 행동 설명으로 유지. 개인별 적합성·문구 적합성 검토 필요 | P40: DIET-P-0048 | Q40: 1.0.0 | R40: WHO-DIET / NIDDK-CKD
...
