Workbook

Sheet 입력_결과
A1: maiReport · 또래 등수(퍼센타일) 계산표
A2: 노란 셀만 입력하세요. 기준: 국민건강보험공단 건강검진통계 2024(KOSIS) 전국 수검자. 판정(정상/이상)이 아니라 "같은 성별·연령대 수검자 중 위치"입니다.
A4: 성별 | B4: 남자 | D4: 성별은 남자 / 여자 로 입력. 20세 미만은 계산하지 않습니다. 예시 값은 프로토타입 검진결과 화면(남성 45세 가정)입니다.
A5: 만 나이 | B5: 45
A6: 5세 구간 (키 형식: 45-49세) | B6: =IF(B5<20,"19세이하",IF(B5>=85,"85세이상",INT(B5/5)*5&"-"&INT(B5/5)*5+4&"세")) -> 45-49세
A7: 10세 구간 | B7: =IF(B5<20,"19세이하",IF(B5>=80,"80세이상",INT(B5/10)*10&"대")) -> 40대
A8: 조회 키 | B8: =B6&"|"&B4 -> 45-49세|남자
A10: ① 검진 항목 (분포표 기반 · 경험적 백분위)
A11: 항목 | B11: 분포표 시트 | C11: 단위 | D11: 입력값 | E11: 방향 | F11: 저값 경고 기준 | G11: 분포 위치 P (%) | H11: 또래 상위 % (rank) | I11: 100명 중 N번째 | J11: 구간 라벨 | K11: 비고 | L11: 계산: 보정값 x | M11: 계산: 행 번호
A12: 체질량지수 | B12: D_BMI | C12: kg/m² | D12: 24.5 | E12: low | F12: 18.5 | G12: =IF(OR(L12="",M12="",$B$5<20),"",(SUMPRODUCT(--(INDIRECT("'D_BMI'!E4:P4")<=L12),INDEX(INDIRECT("'D_BMI'!E6:P60"),M12,0))+SUMPRODUCT((INDIRECT("'D_BMI'!E3:P3")<L12)*(INDIRECT("'D_BMI'!E4:P4")>L12)*INDEX(INDIRECT("'D_BMI'!E6:P60"),M12,0)*(L12-INDIRECT("'D_BMI'!E3:P3"))/(INDIRECT("'D_BMI'!E4:P4")-INDIRECT("'D_BMI'!E3:P3"))))/INDEX(INDIRECT("'D_BMI'!D6:D60"),M12)*100) -> 41.152954 | H12: =IF(G12="","",IF(AND(F12<>"",D12<F12),"확인 필요",IF(E12="low",G12,100-G12))) -> 41.152954 | I12: =IF(OR(H12="",H12="확인 필요"),"",MAX(1,MIN(99,ROUND(H12,0)))) -> 41 | J12: =IF(I12="","",IF(I12<=25,"또래보다 좋음",IF(I12<=60,"또래 수준",IF(I12<=85,"또래보다 나쁨","또래 하위 15%")))) -> 또래 수준 | K12: =IF(D12="","",IF(M12="","해당 연령·성별 행 없음",IF(INDEX(INDIRECT("'D_BMI'!D6:D60"),M12)=0,"이 연령·성별은 2024년 검사 대상 아님(지질 4년 주기)",""))) | L12: =IF(D12="","",MIN(MAX(D12,INDIRECT("'D_BMI'!E3")),MAX(INDIRECT("'D_BMI'!E4:P4"))-0.000000001)) -> 24.5 | M12: =IFERROR(MATCH($B$8,INDIRECT("'D_BMI'!A6:A60"),0),"") -> 23
A13: 허리둘레 | B13: D_WAIST | C13: cm | D13: 82 | E13: low | G13: =IF(OR(L13="",M13="",$B$5<20),"",(SUMPRODUCT(--(INDIRECT("'D_WAIST'!E4:P4")<=L13),INDEX(INDIRECT("'D_WAIST'!E6:P60"),M13,0))+SUMPRODUCT((INDIRECT("'D_WAIST'!E3:P3")<L13)*(INDIRECT("'D_WAIST'!E4:P4")>L13)*INDEX(INDIRECT("'D_WAIST'!E6:P60"),M13,0)*(L13-INDIRECT("'D_WAIST'!E3:P3"))/(INDIRECT("'D_WAIST'!E4:P4")-INDIRECT("'D_WAIST'!E3:P3"))))/INDEX(INDIRECT("'D_WAIST'!D6:D60"),M13)*100) -> 27.868979 | H13: =IF(G13="","",IF(AND(F13<>"",D13<F13),"확인 필요",IF(E13="low",G13,100-G13))) -> 27.868979 | I13: =IF(OR(H13="",H13="확인 필요"),"",MAX(1,MIN(99,ROUND(H13,0)))) -> 28 | J13: =IF(I13="","",IF(I13<=25,"또래보다 좋음",IF(I13<=60,"또래 수준",IF(I13<=85,"또래보다 나쁨","또래 하위 15%")))) -> 또래 수준 | K13: =IF(D13="","",IF(M13="","해당 연령·성별 행 없음",IF(INDEX(INDIRECT("'D_WAIST'!D6:D60"),M13)=0,"이 연령·성별은 2024년 검사 대상 아님(지질 4년 주기)",""))) | L13: =IF(D13="","",MIN(MAX(D13,INDIRECT("'D_WAIST'!E3")),MAX(INDIRECT("'D_WAIST'!E4:P4"))-0.000000001)) -> 82 | M13: =IFERROR(MATCH($B$8,INDIRECT("'D_WAIST'!A6:A60"),0),"") -> 23
A14: 수축기 혈압 | B14: D_SBP | C14: mmHg | D14: 148 | E14: low | F14: 90 | G14: =IF(OR(L14="",M14="",$B$5<20),"",(SUMPRODUCT(--(INDIRECT("'D_SBP'!E4:P4")<=L14),INDEX(INDIRECT("'D_SBP'!E6:P60"),M14,0))+SUMPRODUCT((INDIRECT("'D_SBP'!E3:P3")<L14)*(INDIRECT("'D_SBP'!E4:P4")>L14)*INDEX(INDIRECT("'D_SBP'!E6:P60"),M14,0)*(L14-INDIRECT("'D_SBP'!E3:P3"))/(INDIRECT("'D_SBP'!E4:P4")-INDIRECT("'D_SBP'!E3:P3"))))/INDEX(INDIRECT("'D_SBP'!D6:D60"),M14)*100) -> 94.679028 | H14: =IF(G14="","",IF(AND(F14<>"",D14<F14),"확인 필요",IF(E14="low",G14,100-G14))) -> 94.679028 | I14: =IF(OR(H14="",H14="확인 필요"),"",MAX(1,MIN(99,ROUND(H14,0)))) -> 95 | J14: =IF(I14="","",IF(I14<=25,"또래보다 좋음",IF(I14<=60,"또래 수준",IF(I14<=85,"또래보다 나쁨","또래 하위 15%")))) -> 또래 하위 15% | K14: =IF(D14="","",IF(M14="","해당 연령·성별 행 없음",IF(INDEX(INDIRECT("'D_SBP'!D6:D60"),M14)=0,"이 연령·성별은 2024년 검사 대상 아님(지질 4년 주기)",""))) | L14: =IF(D14="","",MIN(MAX(D14,INDIRECT("'D_SBP'!E3")),MAX(INDIRECT("'D_SBP'!E4:P4"))-0.000000001)) -> 148 | M14: =IFERROR(MATCH($B$8,INDIRECT("'D_SBP'!A6:A60"),0),"") -> 23
A15: 이완기 혈압 | B15: D_DBP | C15: mmHg | D15: 94 | E15: low | F15: 60 | G15: =IF(OR(L15="",M15="",$B$5<20),"",(SUMPRODUCT(--(INDIRECT("'D_DBP'!E4:P4")<=L15),INDEX(INDIRECT("'D_DBP'!E6:P60"),M15,0))+SUMPRODUCT((INDIRECT("'D_DBP'!E3:P3")<L15)*(INDIRECT("'D_DBP'!E4:P4")>L15)*INDEX(INDIRECT("'D_DBP'!E6:P60"),M15,0)*(L15-INDIRECT("'D_DBP'!E3:P3"))/(INDIRECT("'D_DBP'!E4:P4")-INDIRECT("'D_DBP'!E3:P3"))))/INDEX(INDIRECT("'D_DBP'!D6:D60"),M15)*100) -> 90.389005 | H15: =IF(G15="","",IF(AND(F15<>"",D15<F15),"확인 필요",IF(E15="low",G15,100-G15))) -> 90.389005 | I15: =IF(OR(H15="",H15="확인 필요"),"",MAX(1,MIN(99,ROUND(H15,0)))) -> 90 | J15: =IF(I15="","",IF(I15<=25,"또래보다 좋음",IF(I15<=60,"또래 수준",IF(I15<=85,"또래보다 나쁨","또래 하위 15%")))) -> 또래 하위 15% | K15: =IF(D15="","",IF(M15="","해당 연령·성별 행 없음",IF(INDEX(INDIRECT("'D_DBP'!D6:D60"),M15)=0,"이 연령·성별은 2024년 검사 대상 아님(지질 4년 주기)",""))) | L15: =IF(D15="","",MIN(MAX(D15,INDIRECT("'D_DBP'!E3")),MAX(INDIRECT("'D_DBP'!E4:P4"))-0.000000001)) -> 94 | M15: =IFERROR(MATCH($B$8,INDIRECT("'D_DBP'!A6:A60"),0),"") -> 23
A16: 공복 혈당 | B16: D_FBG | C16: mg/dL | D16: 128 | E16: low | G16: =IF(OR(L16="",M16="",$B$5<20),"",(SUMPRODUCT(--(INDIRECT("'D_FBG'!E4:P4")<=L16),INDEX(INDIRECT("'D_FBG'!E6:P60"),M16,0))+SUMPRODUCT((INDIRECT("'D_FBG'!E3:P3")<L16)*(INDIRECT("'D_FBG'!E4:P4")>L16)*INDEX(INDIRECT("'D_FBG'!E6:P60"),M16,0)*(L16-INDIRECT("'D_FBG'!E3:P3"))/(INDIRECT("'D_FBG'!E4:P4")-INDIRECT("'D_FBG'!E3:P3"))))/INDEX(INDIRECT("'D_FBG'!D6:D60"),M16)*100) -> 91.145246 | H16: =IF(G16="","",IF(AND(F16<>"",D16<F16),"확인 필요",IF(E16="low",G16,100-G16))) -> 91.145246 | I16: =IF(OR(H16="",H16="확인 필요"),"",MAX(1,MIN(99,ROUND(H16,0)))) -> 91 | J16: =IF(I16="","",IF(I16<=25,"또래보다 좋음",IF(I16<=60,"또래 수준",IF(I16<=85,"또래보다 나쁨","또래 하위 15%")))) -> 또래 하위 15% | K16: =IF(D16="","",IF(M16="","해당 연령·성별 행 없음",IF(INDEX(INDIRECT("'D_FBG'!D6:D60"),M16)=0,"이 연령·성별은 2024년 검사 대상 아님(지질 4년 주기)",""))) | L16: =IF(D16="","",MIN(MAX(D16,INDIRECT("'D_FBG'!E3")),MAX(INDIRECT("'D_FBG'!E4:P4"))-0.000000001)) -> 128 | M16: =IFERROR(MATCH($B$8,INDIRECT("'D_FBG'!A6:A60"),0),"") -> 23
A17: 총 콜레스테롤 | B17: D_TC | C17: mg/dL | D17: 201 | E17: low | G17: =IF(OR(L17="",M17="",$B$5<20),"",(SUMPRODUCT(--(INDIRECT("'D_TC'!E4:P4")<=L17),INDEX(INDIRECT("'D_TC'!E6:P60"),M17,0))+SUMPRODUCT((INDIRECT("'D_TC'!E3:P3")<L17)*(INDIRECT("'D_TC'!E4:P4")>L17)*INDEX(INDIRECT("'D_TC'!E6:P60"),M17,0)*(L17-INDIRECT("'D_TC'!E3:P3"))/(INDIRECT("'D_TC'!E4:P4")-INDIRECT("'D_TC'!E3:P3"))))/INDEX(INDIRECT("'D_TC'!D6:D60"),M17)*100) -> 44.956146 | H17: =IF(G17="","",IF(AND(F17<>"",D17<F17),"확인 필요",IF(E17="low",G17,100-G17))) -> 44.956146 | I17: =IF(OR(H17="",H17="확인 필요"),"",MAX(1,MIN(99,ROUND(H17,0)))) -> 45 | J17: =IF(I17="","",IF(I17<=25,"또래보다 좋음",IF(I17<=60,"또래 수준",IF(I17<=85,"또래보다 나쁨","또래 하위 15%")))) -> 또래 수준 | K17: =IF(D17="","",IF(M17="","해당 연령·성별 행 없음",IF(INDEX(INDIRECT("'D_TC'!D6:D60"),M17)=0,"이 연령·성별은 2024년 검사 대상 아님(지질 4년 주기)",""))) | L17: =IF(D17="","",MIN(MAX(D17,INDIRECT("'D_TC'!E3")),MAX(INDIRECT("'D_TC'!E4:P4"))-0.000000001)) -> 201 | M17: =IFERROR(MATCH($B$8,INDIRECT("'D_TC'!A6:A60"),0),"") -> 23
A18: HDL 콜레스테롤 | B18: D_HDL | C18: mg/dL | D18: 52 | E18: high | G18: =IF(OR(L18="",M18="",$B$5<20),"",(SUMPRODUCT(--(INDIRECT("'D_HDL'!E4:P4")<=L18),INDEX(INDIRECT("'D_HDL'!E6:P60"),M18,0))+SUMPRODUCT((INDIRECT("'D_HDL'!E3:P3")<L18)*(INDIRECT("'D_HDL'!E4:P4")>L18)*INDEX(INDIRECT("'D_HDL'!E6:P60"),M18,0)*(L18-INDIRECT("'D_HDL'!E3:P3"))/(INDIRECT("'D_HDL'!E4:P4")-INDIRECT("'D_HDL'!E3:P3"))))/INDEX(INDIRECT("'D_HDL'!D6:D60"),M18)*100) -> 51.834633 | H18: =IF(G18="","",IF(AND(F18<>"",D18<F18),"확인 필요",IF(E18="low",G18,100-G18))) -> 48.165367 | I18: =IF(OR(H18="",H18="확인 필요"),"",MAX(1,MIN(99,ROUND(H18,0)))) -> 48 | J18: =IF(I18="","",IF(I18<=25,"또래보다 좋음",IF(I18<=60,"또래 수준",IF(I18<=85,"또래보다 나쁨","또래 하위 15%")))) -> 또래 수준 | K18: =IF(D18="","",IF(M18="","해당 연령·성별 행 없음",IF(INDEX(INDIRECT("'D_HDL'!D6:D60"),M18)=0,"이 연령·성별은 2024년 검사 대상 아님(지질 4년 주기)",""))) | L18: =IF(D18="","",MIN(MAX(D18,INDIRECT("'D_HDL'!E3")),MAX(INDIRECT("'D_HDL'!E4:P4"))-0.000000001)) -> 52 | M18: =IFERROR(MATCH($B$8,INDIRECT("'D_HDL'!A6:A60"),0),"") -> 23
A19: 중성지방 | B19: D_TG | C19: mg/dL | D19: 115 | E19: low | G19: =IF(OR(L19="",M19="",$B$5<20),"",(SUMPRODUCT(--(INDIRECT("'D_TG'!E4:P4")<=L19),INDEX(INDIRECT("'D_TG'!E6:P60"),M19,0))+SUMPRODUCT((INDIRECT("'D_TG'!E3:P3")<L19)*(INDIRECT("'D_TG'!E4:P4")>L19)*INDEX(INDIRECT("'D_TG'!E6:P60"),M19,0)*(L19-INDIRECT("'D_TG'!E3:P3"))/(INDIRECT("'D_TG'!E4:P4")-INDIRECT("'D_TG'!E3:P3"))))/INDEX(INDIRECT("'D_TG'!D6:D60"),M19)*100) -> 36.9129 | H19: =IF(G19="","",IF(AND(F19<>"",D19<F19),"확인 필요",IF(E19="low",G19,100-G19))) -> 36.9129 | I19: =IF(OR(H19="",H19="확인 필요"),"",MAX(1,MIN(99,ROUND(H19,0)))) -> 37 | J19: =IF(I19="","",IF(I19<=25,"또래보다 좋음",IF(I19<=60,"또래 수준",IF(I19<=85,"또래보다 나쁨","또래 하위 15%")))) -> 또래 수준 | K19: =IF(D19="","",IF(M19="","해당 연령·성별 행 없음",IF(INDEX(INDIRECT("'D_TG'!D6:D60"),M19)=0,"이 연령·성별은 2024년 검사 대상 아님(지질 4년 주기)",""))) | L19: =IF(D19="","",MIN(MAX(D19,INDIRECT("'D_TG'!E3")),MAX(INDIRECT("'D_TG'!E4:P4"))-0.000000001)) -> 115 | M19: =IFERROR(MATCH($B$8,INDIRECT("'D_TG'!A6:A60"),0),"") -> 23
A20: LDL 콜레스테롤 | B20: D_LDL | C20: mg/dL | D20: 126 | E20: low | G20: =IF(OR(L20="",M20="",$B$5<20),"",(SUMPRODUCT(--(INDIRECT("'D_LDL'!E4:P4")<=L20),INDEX(INDIRECT("'D_LDL'!E6:P60"),M20,0))+SUMPRODUCT((INDIRECT("'D_LDL'!E3:P3")<L20)*(INDIRECT("'D_LDL'!E4:P4")>L20)*INDEX(INDIRECT("'D_LDL'!E6:P60"),M20,0)*(L20-INDIRECT("'D_LDL'!E3:P3"))/(INDIRECT("'D_LDL'!E4:P4")-INDIRECT("'D_LDL'!E3:P3"))))/INDEX(INDIRECT("'D_LDL'!D6:D60"),M20)*100) -> 54.238587 | H20: =IF(G20="","",IF(AND(F20<>"",D20<F20),"확인 필요",IF(E20="low",G20,100-G20))) -> 54.238587 | I20: =IF(OR(H20="",H20="확인 필요"),"",MAX(1,MIN(99,ROUND(H20,0)))) -> 54 | J20: =IF(I20="","",IF(I20<=25,"또래보다 좋음",IF(I20<=60,"또래 수준",IF(I20<=85,"또래보다 나쁨","또래 하위 15%")))) -> 또래 수준 | K20: =IF(D20="","",IF(M20="","해당 연령·성별 행 없음",IF(INDEX(INDIRECT("'D_LDL'!D6:D60"),M20)=0,"이 연령·성별은 2024년 검사 대상 아님(지질 4년 주기)",""))) | L20: =IF(D20="","",MIN(MAX(D20,INDIRECT("'D_LDL'!E3")),MAX(INDIRECT("'D_LDL'!E4:P4"))-0.000000001)) -> 126 | M20: =IFERROR(MATCH($B$8,INDIRECT("'D_LDL'!A6:A60"),0),"") -> 23
A21: 혈색소 | B21: D_HB | C21: g/dL | E21: high | G21: =IF(OR(L21="",M21="",$B$5<20),"",(SUMPRODUCT(--(INDIRECT("'D_HB'!E4:P4")<=L21),INDEX(INDIRECT("'D_HB'!E6:P60"),M21,0))+SUMPRODUCT((INDIRECT("'D_HB'!E3:P3")<L21)*(INDIRECT("'D_HB'!E4:P4")>L21)*INDEX(INDIRECT("'D_HB'!E6:P60"),M21,0)*(L21-INDIRECT("'D_HB'!E3:P3"))/(INDIRECT("'D_HB'!E4:P4")-INDIRECT("'D_HB'!E3:P3"))))/INDEX(INDIRECT("'D_HB'!D6:D60"),M21)*100) | H21: =IF(G21="","",IF(AND(F21<>"",D21<F21),"확인 필요",IF(E21="low",G21,100-G21))) | I21: =IF(OR(H21="",H21="확인 필요"),"",MAX(1,MIN(99,ROUND(H21,0)))) | J21: =IF(I21="","",IF(I21<=25,"또래보다 좋음",IF(I21<=60,"또래 수준",IF(I21<=85,"또래보다 나쁨","또래 하위 15%")))) | K21: =IF(D21="","",IF(M21="","해당 연령·성별 행 없음",IF(INDEX(INDIRECT("'D_HB'!D6:D60"),M21)=0,"이 연령·성별은 2024년 검사 대상 아님(지질 4년 주기)",""))) | L21: =IF(D21="","",MIN(MAX(D21,INDIRECT("'D_HB'!E3")),MAX(INDIRECT("'D_HB'!E4:P4"))-0.000000001)) | M21: =IFERROR(MATCH($B$8,INDIRECT("'D_HB'!A6:A60"),0),"") -> 23
A22: 혈청 크레아티닌 | B22: D_CR | C22: mg/dL | D22: 1 | E22: low | G22: =IF(OR(L22="",M22="",$B$5<20),"",(SUMPRODUCT(--(INDIRECT("'D_CR'!E4:P4")<=L22),INDEX(INDIRECT("'D_CR'!E6:P60"),M22,0))+SUMPRODUCT((INDIRECT("'D_CR'!E3:P3")<L22)*(INDIRECT("'D_CR'!E4:P4")>L22)*INDEX(INDIRECT("'D_CR'!E6:P60"),M22,0)*(L22-INDIRECT("'D_CR'!E3:P3"))/(INDIRECT("'D_CR'!E4:P4")-INDIRECT("'D_CR'!E3:P3"))))/INDEX(INDIRECT("'D_CR'!D6:D60"),M22)*100) -> 52.262188 | H22: =IF(G22="","",IF(AND(F22<>"",D22<F22),"확인 필요",IF(E22="low",G22,100-G22))) -> 52.262188 | I22: =IF(OR(H22="",H22="확인 필요"),"",MAX(1,MIN(99,ROUND(H22,0)))) -> 52 | J22: =IF(I22="","",IF(I22<=25,"또래보다 좋음",IF(I22<=60,"또래 수준",IF(I22<=85,"또래보다 나쁨","또래 하위 15%")))) -> 또래 수준 | K22: =IF(D22="","",IF(M22="","해당 연령·성별 행 없음",IF(INDEX(INDIRECT("'D_CR'!D6:D60"),M22)=0,"이 연령·성별은 2024년 검사 대상 아님(지질 4년 주기)",""))) | L22: =IF(D22="","",MIN(MAX(D22,INDIRECT("'D_CR'!E3")),MAX(INDIRECT("'D_CR'!E4:P4"))-0.000000001)) -> 1 | M22: =IFERROR(MATCH($B$8,INDIRECT("'D_CR'!A6:A60"),0),"") -> 23
A23: 신사구체여과율 | B23: D_EGFR | C23: mL/min/1.73㎡ | D23: 93 | E23: high | G23: =IF(OR(L23="",M23="",$B$5<20),"",(SUMPRODUCT(--(INDIRECT("'D_EGFR'!E4:P4")<=L23),INDEX(INDIRECT("'D_EGFR'!E6:P60"),M23,0))+SUMPRODUCT((INDIRECT("'D_EGFR'!E3:P3")<L23)*(INDIRECT("'D_EGFR'!E4:P4")>L23)*INDEX(INDIRECT("'D_EGFR'!E6:P60"),M23,0)*(L23-INDIRECT("'D_EGFR'!E3:P3"))/(INDIRECT("'D_EGFR'!E4:P4")-INDIRECT("'D_EGFR'!E3:P3"))))/INDEX(INDIRECT("'D_EGFR'!D6:D60"),M23)*100) -> 39.37795 | H23: =IF(G23="","",IF(AND(F23<>"",D23<F23),"확인 필요",IF(E23="low",G23,100-G23))) -> 60.62205 | I23: =IF(OR(H23="",H23="확인 필요"),"",MAX(1,MIN(99,ROUND(H23,0)))) -> 61 | J23: =IF(I23="","",IF(I23<=25,"또래보다 좋음",IF(I23<=60,"또래 수준",IF(I23<=85,"또래보다 나쁨","또래 하위 15%")))) -> 또래보다 나쁨 | K23: =IF(D23="","",IF(M23="","해당 연령·성별 행 없음",IF(INDEX(INDIRECT("'D_EGFR'!D6:D60"),M23)=0,"이 연령·성별은 2024년 검사 대상 아님(지질 4년 주기)",""))) | L23: =IF(D23="","",MIN(MAX(D23,INDIRECT("'D_EGFR'!E3")),MAX(INDIRECT("'D_EGFR'!E4:P4"))-0.000000001)) -> 93 | M23: =IFERROR(MATCH($B$8,INDIRECT("'D_EGFR'!A6:A60"),0),"") -> 23
A24: AST | B24: D_AST | C24: U/L | D24: 21 | E24: low | G24: =IF(OR(L24="",M24="",$B$5<20),"",(SUMPRODUCT(--(INDIRECT("'D_AST'!E4:P4")<=L24),INDEX(INDIRECT("'D_AST'!E6:P60"),M24,0))+SUMPRODUCT((INDIRECT("'D_AST'!E3:P3")<L24)*(INDIRECT("'D_AST'!E4:P4")>L24)*INDEX(INDIRECT("'D_AST'!E6:P60"),M24,0)*(L24-INDIRECT("'D_AST'!E3:P3"))/(INDIRECT("'D_AST'!E4:P4")-INDIRECT("'D_AST'!E3:P3"))))/INDEX(INDIRECT("'D_AST'!D6:D60"),M24)*100) -> 44.127185 | H24: =IF(G24="","",IF(AND(F24<>"",D24<F24),"확인 필요",IF(E24="low",G24,100-G24))) -> 44.127185 | I24: =IF(OR(H24="",H24="확인 필요"),"",MAX(1,MIN(99,ROUND(H24,0)))) -> 44 | J24: =IF(I24="","",IF(I24<=25,"또래보다 좋음",IF(I24<=60,"또래 수준",IF(I24<=85,"또래보다 나쁨","또래 하위 15%")))) -> 또래 수준 | K24: =IF(D24="","",IF(M24="","해당 연령·성별 행 없음",IF(INDEX(INDIRECT("'D_AST'!D6:D60"),M24)=0,"이 연령·성별은 2024년 검사 대상 아님(지질 4년 주기)",""))) | L24: =IF(D24="","",MIN(MAX(D24,INDIRECT("'D_AST'!E3")),MAX(INDIRECT("'D_AST'!E4:P4"))-0.000000001)) -> 21 | M24: =IFERROR(MATCH($B$8,INDIRECT("'D_AST'!A6:A60"),0),"") -> 23
A25: ALT | B25: D_ALT | C25: U/L | D25: 26 | E25: low | G25: =IF(OR(L25="",M25="",$B$5<20),"",(SUMPRODUCT(--(INDIRECT("'D_ALT'!E4:P4")<=L25),INDEX(INDIRECT("'D_ALT'!E6:P60"),M25,0))+SUMPRODUCT((INDIRECT("'D_ALT'!E3:P3")<L25)*(INDIRECT("'D_ALT'!E4:P4")>L25)*INDEX(INDIRECT("'D_ALT'!E6:P60"),M25,0)*(L25-INDIRECT("'D_ALT'!E3:P3"))/(INDIRECT("'D_ALT'!E4:P4")-INDIRECT("'D_ALT'!E3:P3"))))/INDEX(INDIRECT("'D_ALT'!D6:D60"),M25)*100) -> 48.227054 | H25: =IF(G25="","",IF(AND(F25<>"",D25<F25),"확인 필요",IF(E25="low",G25,100-G25))) -> 48.227054 | I25: =IF(OR(H25="",H25="확인 필요"),"",MAX(1,MIN(99,ROUND(H25,0)))) -> 48 | J25: =IF(I25="","",IF(I25<=25,"또래보다 좋음",IF(I25<=60,"또래 수준",IF(I25<=85,"또래보다 나쁨","또래 하위 15%")))) -> 또래 수준 | K25: =IF(D25="","",IF(M25="","해당 연령·성별 행 없음",IF(INDEX(INDIRECT("'D_ALT'!D6:D60"),M25)=0,"이 연령·성별은 2024년 검사 대상 아님(지질 4년 주기)",""))) | L25: =IF(D25="","",MIN(MAX(D25,INDIRECT("'D_ALT'!E3")),MAX(INDIRECT("'D_ALT'!E4:P4"))-0.000000001)) -> 26 | M25: =IFERROR(MATCH($B$8,INDIRECT("'D_ALT'!A6:A60"),0),"") -> 23
A26: 감마-GTP | B26: D_GGT | C26: U/L | D26: 18 | E26: low | G26: =IF(OR(L26="",M26="",$B$5<20),"",(SUMPRODUCT(--(INDIRECT("'D_GGT'!E4:P4")<=L26),INDEX(INDIRECT("'D_GGT'!E6:P60"),M26,0))+SUMPRODUCT((INDIRECT("'D_GGT'!E3:P3")<L26)*(INDIRECT("'D_GGT'!E4:P4")>L26)*INDEX(INDIRECT("'D_GGT'!E6:P60"),M26,0)*(L26-INDIRECT("'D_GGT'!E3:P3"))/(INDIRECT("'D_GGT'!E4:P4")-INDIRECT("'D_GGT'!E3:P3"))))/INDEX(INDIRECT("'D_GGT'!D6:D60"),M26)*100) -> 15.046196 | H26: =IF(G26="","",IF(AND(F26<>"",D26<F26),"확인 필요",IF(E26="low",G26,100-G26))) -> 15.046196 | I26: =IF(OR(H26="",H26="확인 필요"),"",MAX(1,MIN(99,ROUND(H26,0)))) -> 15 | J26: =IF(I26="","",IF(I26<=25,"또래보다 좋음",IF(I26<=60,"또래 수준",IF(I26<=85,"또래보다 나쁨","또래 하위 15%")))) -> 또래보다 좋음 | K26: =IF(D26="","",IF(M26="","해당 연령·성별 행 없음",IF(INDEX(INDIRECT("'D_GGT'!D6:D60"),M26)=0,"이 연령·성별은 2024년 검사 대상 아님(지질 4년 주기)",""))) | L26: =IF(D26="","",MIN(MAX(D26,INDIRECT("'D_GGT'!E3")),MAX(INDIRECT("'D_GGT'!E4:P4"))-0.000000001)) -> 18 | M26: =IFERROR(MATCH($B$8,INDIRECT("'D_GGT'!A6:A60"),0),"") -> 23
A28: ② 키·체중 (인체치수조사 2020 백분위표 보간 · 좋고 나쁨 없음)
A29: 항목 | B29: 기준 시트 | C29: 단위 | D29: 입력값 | E29: 방향 | G29: 분포 위치 P (%) | H29: 큰 순 상위 % | I29: 100명 중 N번째 | K29: 비고 | L29: 계산: 백분위 구간 k | M29: 계산: 행 번호
A30: 키 | B30: M_신장체중 | C30: cm | D30: 172 | E30: none | G30: =IF(OR(L30="",$B$5<20),"",IF(L30=0,1,IF(L30>=9,99,INDEX(M_신장체중!$H$2:$P$2,L30)+(D30-INDEX(M_신장체중!$H$4:$P$47,M30,L30))/(INDEX(M_신장체중!$H$4:$P$47,M30,L30+1)-INDEX(M_신장체중!$H$4:$P$47,M30,L30))*(INDEX(M_신장체중!$H$2:$P$2,L30+1)-INDEX(M_신장체중!$H$2:$P$2,L30))))) -> 46.323529 | H30: =IF(G30="","",100-G30) -> 53.676471 | I30: =IF(H30="","",MAX(1,MIN(99,ROUND(H30,0)))) -> 54 | K30: =IF(D30="","",IF(M30="","인체치수조사는 20~69세만 제공 · 계산 불가","또래 평균 "&TEXT(INDEX(M_신장체중!$F$4:$F$47,M30),"0.0")&" · 표준편차 "&TEXT(INDEX(M_신장체중!$G$4:$G$47,M30),"0.0")&" · 종합 제외")) -> 또래 평균 172.5 · 표준편차 5.1 · 종합 제외 | L30: =IF(OR(D30="",M30=""),"",IFERROR(MATCH(D30,INDEX(M_신장체중!$H$4:$P$47,M30,0),1),0)) -> 4 | M30: =IFERROR(MATCH("키|"&$B$4&"|"&$B$6,M_신장체중!$A$4:$A$47,0),"") -> 6
A31: 체중 | B31: M_신장체중 | C31: kg | D31: 72.5 | E31: none | G31: =IF(OR(L31="",$B$5<20),"",IF(L31=0,1,IF(L31>=9,99,INDEX(M_신장체중!$H$2:$P$2,L31)+(D31-INDEX(M_신장체중!$H$4:$P$47,M31,L31))/(INDEX(M_신장체중!$H$4:$P$47,M31,L31+1)-INDEX(M_신장체중!$H$4:$P$47,M31,L31))*(INDEX(M_신장체중!$H$2:$P$2,L31+1)-INDEX(M_신장체중!$H$2:$P$2,L31))))) -> 40.458015 | H31: =IF(G31="","",100-G31) -> 59.541985 | I31: =IF(H31="","",MAX(1,MIN(99,ROUND(H31,0)))) -> 60 | K31: =IF(D31="","",IF(M31="","인체치수조사는 20~69세만 제공 · 계산 불가","또래 평균 "&TEXT(INDEX(M_신장체중!$F$4:$F$47,M31),"0.0")&" · 표준편차 "&TEXT(INDEX(M_신장체중!$G$4:$G$47,M31),"0.0")&" · 종합 제외")) -> 또래 평균 75.8 · 표준편차 11.0 · 종합 제외 | L31: =IF(OR(D31="",M31=""),"",IFERROR(MATCH(D31,INDEX(M_신장체중!$H$4:$P$47,M31,0),1),0)) -> 4 | M31: =IFERROR(MATCH("체중|"&$B$4&"|"&$B$6,M_신장체중!$A$4:$A$47,0),"") -> 28
A33: ③ 종합
A34: 계산된 항목 수 | B34: =COUNT(H12:H26) -> 14
A35: 또래 평균보다 나쁜 항목 수 (rank>50) | B35: =COUNTIF(H12:H26,">50") -> 6
A36: 평균 퍼센타일 (가중치 없음) | B36: =IF(COUNT(H12:H26)<3,"",AVERAGE(H12:H26)) -> 53.556635
A37: 종합 등급 | B37: =IF(B36="","항목 3개 미만",IF(B36<=25,"또래보다 좋음",IF(B36<=60,"또래 수준",IF(B36<=85,"또래보다 나쁨","또래 하위 15%")))) -> 또래 수준
A38: 먼저 볼 항목 (rank 상위 3) | B38: =IFERROR(INDEX($A$12:$A$26,MATCH(LARGE($H$12:$H$26,1),$H$12:$H$26,0)),"") -> 수축기 혈압 | C38: =IFERROR(INDEX($A$12:$A$26,MATCH(LARGE($H$12:$H$26,2),$H$12:$H$26,0)),"") -> 공복 혈당 | D38: =IFERROR(INDEX($A$12:$A$26,MATCH(LARGE($H$12:$H$26,3),$H$12:$H$26,0)),"") -> 이완기 혈압
A40: 산식과 규칙
A41: P(분포 위치) = [ Σ(상한≤x 구간 인원) + 해당 구간 인원 × (x−하한)/(상한−하한) ] ÷ 성별·연령 구간 총 인원 × 100 ← 정규분포 가정 없이 실제 수검자 분포에서 계산
A42: rank(또래 상위 %) = P (낮을수록 좋은 항목) 또는 100−P (높을수록 좋은 항목: HDL, 혈색소, 신사구체여과율)
A43: 100명 중 N번째 = rank를 정수로 반올림하고 1~99로 제한. 0과 100은 표시하지 않음
A44: 구간 라벨: 1~25 또래보다 좋음 / 26~60 또래 수준 / 61~85 또래보다 나쁨 / 86~99 또래 하위 15%
A45: 저값 경고: BMI 18.5 미만, 수축기 90 미만, 이완기 60 미만이면 순위 대신 "확인 필요" (낮은 값이 상위로 보이는 것을 막음). 종합에서 제외
...

Sheet D_BMI
A1: 체질량지수 분포 · 국민건강보험공단 건강검진통계 2024 (KOSIS, 전국) · 단위 kg/m²
A2: 3~4행 하한·상한은 열 이름의 구간 경계. 양끝 개방 구간의 바깥 경계는 계산용 가정값(파란색). 데이터 셀(6행 이하)은 수정하지 마세요.
D3: 하한 | E3: 10 | F3: 18.5 | G3: 25 | H3: 30 | I3: 40 | J3: 1000000000 | K3: 1000000000 | L3: 1000000000 | M3: 1000000000 | N3: 1000000000 | O3: 1000000000 | P3: 1000000000
D4: 상한 | E4: 18.5 | F4: 25 | G4: 30 | H4: 40 | I4: 60 | J4: 2000000000 | K4: 2000000000 | L4: 2000000000 | M4: 2000000000 | N4: 2000000000 | O4: 2000000000 | P4: 2000000000
A5: 키 | B5: 연령 | C5: 성별 | D5: 계 | E5: 저체중(18.5미만) | F5: 정상(18.5~25미만) | G5: 비만1단계(25~30미만) | H5: 비만2단계(30~40미만) | I5: 비만3단계(40이상) | J5: (미사용) | K5: (미사용) | L5: (미사용) | M5: (미사용) | N5: (미사용) | O5: (미사용) | P5: (미사용)
A6: 계|합계 | B6: 계 | C6: 합계 | D6: 17510081 | E6: 582126 | F6: 9913201 | G6: 5665466 | H6: 1307731 | I6: 41557 | J6: 0 | K6: 0 | L6: 0 | M6: 0 | N6: 0 | O6: 0 | P6: 0
A7: 계|남자 | B7: 계 | C7: 남자 | D7: 9091686 | E7: 123362 | F7: 4410154 | G7: 3707704 | H7: 825962 | I7: 24504 | J7: 0 | K7: 0 | L7: 0 | M7: 0 | N7: 0 | O7: 0 | P7: 0
A8: 계|여자 | B8: 계 | C8: 여자 | D8: 8418395 | E8: 458764 | F8: 5503047 | G8: 1957762 | H8: 481769 | I8: 17053 | J8: 0 | K8: 0 | L8: 0 | M8: 0 | N8: 0 | O8: 0 | P8: 0
A9: 19세이하|합계 | B9: 19세이하 | C9: 합계 | D9: 8653 | E9: 705 | F9: 4910 | G9: 1922 | H9: 1040 | I9: 76 | J9: 0 | K9: 0 | L9: 0 | M9: 0 | N9: 0 | O9: 0 | P9: 0
A10: 19세이하|남자 | B10: 19세이하 | C10: 남자 | D10: 5723 | E10: 353 | F10: 3050 | G10: 1460 | H10: 803 | I10: 57 | J10: 0 | K10: 0 | L10: 0 | M10: 0 | N10: 0 | O10: 0 | P10: 0
A11: 19세이하|여자 | B11: 19세이하 | C11: 여자 | D11: 2930 | E11: 352 | F11: 1860 | G11: 462 | H11: 237 | I11: 19 | J11: 0 | K11: 0 | L11: 0 | M11: 0 | N11: 0 | O11: 0 | P11: 0
A12: 20-24세|합계 | B12: 20~24세 | C12: 합계 | D12: 544564 | E12: 55357 | F12: 335151 | G12: 107294 | H12: 43845 | I12: 2917 | J12: 0 | K12: 0 | L12: 0 | M12: 0 | N12: 0 | O12: 0 | P12: 0
A13: 20-24세|남자 | B13: 20~24세 | C13: 남자 | D13: 232290 | E13: 10534 | F13: 127209 | G13: 66528 | H13: 26334 | I13: 1685 | J13: 0 | K13: 0 | L13: 0 | M13: 0 | N13: 0 | O13: 0 | P13: 0
A14: 20-24세|여자 | B14: 20~24세 | C14: 여자 | D14: 312274 | E14: 44823 | F14: 207942 | G14: 40766 | H14: 17511 | I14: 1232 | J14: 0 | K14: 0 | L14: 0 | M14: 0 | N14: 0 | O14: 0 | P14: 0
A15: 25-29세|합계 | B15: 25~29세 | C15: 합계 | D15: 1204753 | E15: 75015 | F15: 710730 | G15: 301383 | H15: 111267 | I15: 6358 | J15: 0 | K15: 0 | L15: 0 | M15: 0 | N15: 0 | O15: 0 | P15: 0
A16: 25-29세|남자 | B16: 25~29세 | C16: 남자 | D16: 626802 | E16: 12286 | F16: 310321 | G16: 222989 | H16: 77328 | I16: 3878 | J16: 0 | K16: 0 | L16: 0 | M16: 0 | N16: 0 | O16: 0 | P16: 0
A17: 25-29세|여자 | B17: 25~29세 | C17: 여자 | D17: 577951 | E17: 62729 | F17: 400409 | G17: 78394 | H17: 33939 | I17: 2480 | J17: 0 | K17: 0 | L17: 0 | M17: 0 | N17: 0 | O17: 0 | P17: 0
... A53: 85세이상|여자 | B53: 85세이상 | C53: 여자 | D53: 62933 | E53: 5846 | F53: 37602 | G53: 16844 | H53: 2627 | I53: 14 | J53: 0 | K53: 0 | L53: 0 | M53: 0 | N53: 0 | O53: 0 | P53: 0

Sheet D_WAIST
A1: 허리둘레 분포 · 국민건강보험공단 건강검진통계 2024 (KOSIS, 전국) · 단위 cm
A2: 3~4행 하한·상한은 열 이름의 구간 경계. 양끝 개방 구간의 바깥 경계는 계산용 가정값(파란색). 데이터 셀(6행 이하)은 수정하지 마세요.
D3: 하한 | E3: 50 | F3: 75 | G3: 80 | H3: 85 | I3: 90 | J3: 95 | K3: 100 | L3: 105 | M3: 110 | N3: 1000000000 | O3: 1000000000 | P3: 1000000000
D4: 상한 | E4: 75 | F4: 80 | G4: 85 | H4: 90 | I4: 95 | J4: 100 | K4: 105 | L4: 110 | M4: 140 | N4: 2000000000 | O4: 2000000000 | P4: 2000000000
A5: 키 | B5: 연령 | C5: 성별 | D5: 계 | E5: 75cm미만 | F5: 75-79 | G5: 80-84 | H5: 85-89 | I5: 90-94 | J5: 95-99 | K5: 100-104 | L5: 105-109 | M5: 110cm이상 | N5: (미사용) | O5: (미사용) | P5: (미사용)
A6: 계|합계 | B6: 계 | C6: 합계 | D6: 17504300 | E6: 5153493 | F6: 2420801 | G6: 3258551 | H6: 2853900 | I6: 1903641 | J6: 1035640 | K6: 486881 | L6: 214417 | M6: 176976 | N6: 0 | O6: 0 | P6: 0
A7: 계|남자 | B7: 계 | C7: 남자 | D7: 9092955 | E7: 934743 | F7: 1100423 | G7: 2000852 | H7: 2062247 | I7: 1466148 | J7: 819380 | K7: 390519 | L7: 173274 | M7: 145369 | N7: 0 | O7: 0 | P7: 0
A8: 계|여자 | B8: 계 | C8: 여자 | D8: 8411345 | E8: 4218750 | F8: 1320378 | G8: 1257699 | H8: 791653 | I8: 437493 | J8: 216260 | K8: 96362 | L8: 41143 | M8: 31607 | N8: 0 | O8: 0 | P8: 0
A9: 19세이하|합계 | B9: 19세이하 | C9: 합계 | D9: 8654 | E9: 4285 | F9: 1167 | G9: 1056 | H9: 715 | I9: 487 | J9: 358 | K9: 248 | L9: 137 | M9: 201 | N9: 0 | O9: 0 | P9: 0
A10: 19세이하|남자 | B10: 19세이하 | C10: 남자 | D10: 5725 | E10: 2165 | F10: 854 | G10: 857 | H10: 587 | I10: 417 | J10: 316 | K10: 221 | L10: 126 | M10: 182 | N10: 0 | O10: 0 | P10: 0
A11: 19세이하|여자 | B11: 19세이하 | C11: 여자 | D11: 2929 | E11: 2120 | F11: 313 | G11: 199 | H11: 128 | I11: 70 | J11: 42 | K11: 27 | L11: 11 | M11: 19 | N11: 0 | O11: 0 | P11: 0
A12: 20-24세|합계 | B12: 20~24세 | C12: 합계 | D12: 544683 | E12: 311732 | F12: 68276 | G12: 61265 | H12: 40309 | I12: 25030 | J12: 15821 | K12: 9637 | L12: 5597 | M12: 7016 | N12: 0 | O12: 0 | P12: 0
A13: 20-24세|남자 | B13: 20~24세 | C13: 남자 | D13: 232371 | E13: 71966 | F13: 40320 | G13: 41985 | H13: 29481 | I13: 18620 | J13: 12036 | K13: 7602 | L13: 4499 | M13: 5862 | N13: 0 | O13: 0 | P13: 0
A14: 20-24세|여자 | B14: 20~24세 | C14: 여자 | D14: 312312 | E14: 239766 | F14: 27956 | G14: 19280 | H14: 10828 | I14: 6410 | J14: 3785 | K14: 2035 | L14: 1098 | M14: 1154 | N14: 0 | O14: 0 | P14: 0
A15: 25-29세|합계 | B15: 25~29세 | C15: 합계 | D15: 1204258 | E15: 552838 | F15: 161498 | G15: 172707 | H15: 126424 | I15: 79323 | J15: 48853 | K15: 28355 | L15: 15939 | M15: 18321 | N15: 0 | O15: 0 | P15: 0
A16: 25-29세|남자 | B16: 25~29세 | C16: 남자 | D16: 626992 | E16: 120910 | F16: 107285 | G16: 134528 | H16: 104365 | I16: 66101 | J16: 40823 | K16: 23831 | L16: 13455 | M16: 15694 | N16: 0 | O16: 0 | P16: 0
A17: 25-29세|여자 | B17: 25~29세 | C17: 여자 | D17: 577266 | E17: 431928 | F17: 54213 | G17: 38179 | H17: 22059 | I17: 13222 | J17: 8030 | K17: 4524 | L17: 2484 | M17: 2627 | N17: 0 | O17: 0 | P17: 0
... A53: 85세이상|여자 | B53: 85세이상 | C53: 여자 | D53: 63002 | E53: 16879 | F53: 9729 | G53: 13526 | H53: 10506 | I53: 6775 | J53: 3503 | K53: 1418 | L53: 449 | M53: 217 | N53: 0 | O53: 0 | P53: 0

Sheet D_SBP
A1: 수축기 혈압 분포 · 국민건강보험공단 건강검진통계 2024 (KOSIS, 전국) · 단위 mmHg
A2: 3~4행 하한·상한은 열 이름의 구간 경계. 양끝 개방 구간의 바깥 경계는 계산용 가정값(파란색). 데이터 셀(6행 이하)은 수정하지 마세요.
D3: 하한 | E3: 70 | F3: 110 | G3: 120 | H3: 130 | I3: 140 | J3: 150 | K3: 160 | L3: 170 | M3: 180 | N3: 1000000000 | O3: 1000000000 | P3: 1000000000
D4: 상한 | E4: 110 | F4: 120 | G4: 130 | H4: 140 | I4: 150 | J4: 160 | K4: 170 | L4: 180 | M4: 220 | N4: 2000000000 | O4: 2000000000 | P4: 2000000000
A5: 키 | B5: 연령 | C5: 성별 | D5: 계 | E5: 110미만 | F5: 110-119 | G5: 120-129 | H5: 130-139 | I5: 140-149 | J5: 150-159 | K5: 160-169 | L5: 170-179 | M5: 180이상 | N5: (미사용) | O5: (미사용) | P5: (미사용)
A6: 계|합계 | B6: 계 | C6: 합계 | D6: 17516901 | E6: 2918325 | F6: 4667566 | G6: 4330052 | H6: 3650104 | I6: 1181671 | J6: 512297 | K6: 171935 | L6: 52553 | M6: 32398 | N6: 0 | O6: 0 | P6: 0
A7: 계|남자 | B7: 계 | C7: 남자 | D7: 9093244 | E7: 905632 | F7: 2310476 | G7: 2499485 | H7: 2258227 | I7: 688410 | J7: 289709 | K7: 95143 | L7: 28614 | M7: 17548 | N7: 0 | O7: 0 | P7: 0
A8: 계|여자 | B8: 계 | C8: 여자 | D8: 8423657 | E8: 2012693 | F8: 2357090 | G8: 1830567 | H8: 1391877 | I8: 493261 | J8: 222588 | K8: 76792 | L8: 23939 | M8: 14850 | N8: 0 | O8: 0 | P8: 0
A9: 19세이하|합계 | B9: 19세이하 | C9: 합계 | D9: 8655 | E9: 2160 | F9: 3156 | G9: 1910 | H9: 1203 | I9: 152 | J9: 52 | K9: 14 | L9: 6 | M9: 2 | N9: 0 | O9: 0 | P9: 0
A10: 19세이하|남자 | B10: 19세이하 | C10: 남자 | D10: 5725 | E10: 909 | F10: 2099 | G10: 1514 | H10: 1014 | I10: 122 | J10: 49 | K10: 12 | L10: 6 | M10: 0 | N10: 0 | O10: 0 | P10: 0
A11: 19세이하|여자 | B11: 19세이하 | C11: 여자 | D11: 2930 | E11: 1251 | F11: 1057 | G11: 396 | H11: 189 | I11: 30 | J11: 3 | K11: 2 | L11: 0 | M11: 2 | N11: 0 | O11: 0 | P11: 0
A12: 20-24세|합계 | B12: 20~24세 | C12: 합계 | D12: 544717 | E12: 172730 | F12: 190631 | G12: 111165 | H12: 57904 | I12: 8344 | J12: 2858 | K12: 782 | L12: 211 | M12: 92 | N12: 0 | O12: 0 | P12: 0
A13: 20-24세|남자 | B13: 20~24세 | C13: 남자 | D13: 232358 | E13: 36784 | F13: 79618 | G13: 64690 | H13: 41875 | I13: 6349 | J13: 2237 | K13: 577 | L13: 163 | M13: 65 | N13: 0 | O13: 0 | P13: 0
A14: 20-24세|여자 | B14: 20~24세 | C14: 여자 | D14: 312359 | E14: 135946 | F14: 111013 | G14: 46475 | H14: 16029 | I14: 1995 | J14: 621 | K14: 205 | L14: 48 | M14: 27 | N14: 0 | O14: 0 | P14: 0
A15: 25-29세|합계 | B15: 25~29세 | C15: 합계 | D15: 1205411 | E15: 322987 | F15: 414760 | G15: 266888 | H15: 161447 | I15: 25880 | J15: 9231 | K15: 2874 | L15: 786 | M15: 558 | N15: 0 | O15: 0 | P15: 0
A16: 25-29세|남자 | B16: 25~29세 | C16: 남자 | D16: 626997 | E16: 80863 | F16: 207835 | G16: 178172 | H16: 128570 | I16: 20855 | J16: 7458 | K16: 2259 | L16: 597 | M16: 388 | N16: 0 | O16: 0 | P16: 0
A17: 25-29세|여자 | B17: 25~29세 | C17: 여자 | D17: 578414 | E17: 242124 | F17: 206925 | G17: 88716 | H17: 32877 | I17: 5025 | J17: 1773 | K17: 615 | L17: 189 | M17: 170 | N17: 0 | O17: 0 | P17: 0
... A53: 85세이상|여자 | B53: 85세이상 | C53: 여자 | D53: 63266 | E53: 4781 | F53: 9399 | G53: 14024 | H53: 15134 | I53: 9811 | J53: 5733 | K53: 2701 | L53: 1009 | M53: 674 | N53: 0 | O53: 0 | P53: 0

Sheet D_DBP
A1: 이완기 혈압 분포 · 국민건강보험공단 건강검진통계 2024 (KOSIS, 전국) · 단위 mmHg
A2: 3~4행 하한·상한은 열 이름의 구간 경계. 양끝 개방 구간의 바깥 경계는 계산용 가정값(파란색). 데이터 셀(6행 이하)은 수정하지 마세요.
D3: 하한 | E3: 40 | F3: 70 | G3: 80 | H3: 90 | I3: 100 | J3: 110 | K3: 120 | L3: 1000000000 | M3: 1000000000 | N3: 1000000000 | O3: 1000000000 | P3: 1000000000
D4: 상한 | E4: 70 | F4: 80 | G4: 90 | H4: 100 | I4: 110 | J4: 120 | K4: 150 | L4: 2000000000 | M4: 2000000000 | N4: 2000000000 | O4: 2000000000 | P4: 2000000000
A5: 키 | B5: 연령 | C5: 성별 | D5: 계 | E5: 70미만 | F5: 70-79 | G5: 80-89 | H5: 90-99 | I5: 100-109 | J5: 110-119 | K5: 120이상 | L5: (미사용) | M5: (미사용) | N5: (미사용) | O5: (미사용) | P5: (미사용)
A6: 계|합계 | B6: 계 | C6: 합계 | D6: 17516901 | E6: 4862573 | F6: 6559305 | G6: 4721309 | H6: 1057805 | I6: 250654 | J6: 50054 | K6: 15201 | L6: 0 | M6: 0 | N6: 0 | O6: 0 | P6: 0
A7: 계|남자 | B7: 계 | C7: 남자 | D7: 9093244 | E7: 1786863 | F7: 3444689 | G7: 2943605 | H7: 694122 | I7: 176352 | J7: 36378 | K7: 11235 | L7: 0 | M7: 0 | N7: 0 | O7: 0 | P7: 0
A8: 계|여자 | B8: 계 | C8: 여자 | D8: 8423657 | E8: 3075710 | F8: 3114616 | G8: 1777704 | H8: 363683 | I8: 74302 | J8: 13676 | K8: 3966 | L8: 0 | M8: 0 | N8: 0 | O8: 0 | P8: 0
A9: 19세이하|합계 | B9: 19세이하 | C9: 합계 | D9: 8655 | E9: 3949 | F9: 3290 | G9: 1288 | H9: 101 | I9: 21 | J9: 5 | K9: 1 | L9: 0 | M9: 0 | N9: 0 | O9: 0 | P9: 0
A10: 19세이하|남자 | B10: 19세이하 | C10: 남자 | D10: 5725 | E10: 2292 | F10: 2334 | G10: 999 | H10: 82 | I10: 14 | J10: 4 | K10: 0 | L10: 0 | M10: 0 | N10: 0 | O10: 0 | P10: 0
A11: 19세이하|여자 | B11: 19세이하 | C11: 여자 | D11: 2930 | E11: 1657 | F11: 956 | G11: 289 | H11: 19 | I11: 7 | J11: 1 | K11: 1 | L11: 0 | M11: 0 | N11: 0 | O11: 0 | P11: 0
A12: 20-24세|합계 | B12: 20~24세 | C12: 합계 | D12: 544717 | E12: 257444 | F12: 199276 | G12: 77156 | H12: 8656 | I12: 1762 | J12: 333 | K12: 90 | L12: 0 | M12: 0 | N12: 0 | O12: 0 | P12: 0
A13: 20-24세|남자 | B13: 20~24세 | C13: 남자 | D13: 232358 | E13: 83766 | F13: 95880 | G13: 45730 | H13: 5577 | I13: 1141 | J13: 208 | K13: 56 | L13: 0 | M13: 0 | N13: 0 | O13: 0 | P13: 0
A14: 20-24세|여자 | B14: 20~24세 | C14: 여자 | D14: 312359 | E14: 173678 | F14: 103396 | G14: 31426 | H14: 3079 | I14: 621 | J14: 125 | K14: 34 | L14: 0 | M14: 0 | N14: 0 | O14: 0 | P14: 0
A15: 25-29세|합계 | B15: 25~29세 | C15: 합계 | D15: 1205411 | E15: 487537 | F15: 460743 | G15: 218747 | H15: 29063 | I15: 7073 | J15: 1629 | K15: 619 | L15: 0 | M15: 0 | N15: 0 | O15: 0 | P15: 0
A16: 25-29세|남자 | B16: 25~29세 | C16: 남자 | D16: 626997 | E16: 184328 | F16: 262333 | G16: 152366 | H16: 21222 | I16: 5179 | J16: 1141 | K16: 428 | L16: 0 | M16: 0 | N16: 0 | O16: 0 | P16: 0
A17: 25-29세|여자 | B17: 25~29세 | C17: 여자 | D17: 578414 | E17: 303209 | F17: 198410 | G17: 66381 | H17: 7841 | I17: 1894 | J17: 488 | K17: 191 | L17: 0 | M17: 0 | N17: 0 | O17: 0 | P17: 0
... A53: 85세이상|여자 | B53: 85세이상 | C53: 여자 | D53: 63266 | E53: 19587 | F53: 21952 | G53: 16770 | H53: 4044 | I53: 733 | J53: 140 | K53: 40 | L53: 0 | M53: 0 | N53: 0 | O53: 0 | P53: 0

Sheet D_FBG
A1: 공복 혈당 분포 · 국민건강보험공단 건강검진통계 2024 (KOSIS, 전국) · 단위 mg/dL
A2: 3~4행 하한·상한은 열 이름의 구간 경계. 양끝 개방 구간의 바깥 경계는 계산용 가정값(파란색). 데이터 셀(6행 이하)은 수정하지 마세요.
D3: 하한 | E3: 50 | F3: 100 | G3: 110 | H3: 126 | I3: 140 | J3: 160 | K3: 180 | L3: 200 | M3: 1000000000 | N3: 1000000000 | O3: 1000000000 | P3: 1000000000
D4: 상한 | E4: 100 | F4: 110 | G4: 126 | H4: 140 | I4: 160 | J4: 180 | K4: 200 | L4: 350 | M4: 2000000000 | N4: 2000000000 | O4: 2000000000 | P4: 2000000000
A5: 키 | B5: 연령 | C5: 성별 | D5: 계 | E5: 100미만 | F5: 100-109 | G5: 110-125 | H5: 126-139 | I5: 140-159 | J5: 160-179 | K5: 180-199 | L5: 200이상 | M5: (미사용) | N5: (미사용) | O5: (미사용) | P5: (미사용)
A6: 계|합계 | B6: 계 | C6: 합계 | D6: 17516657 | E6: 10524597 | F6: 3633287 | G6: 1978663 | H6: 608266 | I6: 378503 | J6: 159648 | K6: 80292 | L6: 153401 | M6: 0 | N6: 0 | O6: 0 | P6: 0
A7: 계|남자 | B7: 계 | C7: 남자 | D7: 9093069 | E7: 4846543 | F7: 2107557 | G7: 1226060 | H7: 390355 | I7: 251056 | J7: 107961 | K7: 55307 | L7: 108230 | M7: 0 | N7: 0 | O7: 0 | P7: 0
A8: 계|여자 | B8: 계 | C8: 여자 | D8: 8423588 | E8: 5678054 | F8: 1525730 | G8: 752603 | H8: 217911 | I8: 127447 | J8: 51687 | K8: 24985 | L8: 45171 | M8: 0 | N8: 0 | O8: 0 | P8: 0
A9: 19세이하|합계 | B9: 19세이하 | C9: 합계 | D9: 8654 | E9: 7279 | F9: 1074 | G9: 226 | H9: 28 | I9: 12 | J9: 6 | K9: 6 | L9: 23 | M9: 0 | N9: 0 | O9: 0 | P9: 0
A10: 19세이하|남자 | B10: 19세이하 | C10: 남자 | D10: 5724 | E10: 4777 | F10: 741 | G10: 156 | H10: 21 | I10: 10 | J10: 4 | K10: 2 | L10: 13 | M10: 0 | N10: 0 | O10: 0 | P10: 0
A11: 19세이하|여자 | B11: 19세이하 | C11: 여자 | D11: 2930 | E11: 2502 | F11: 333 | G11: 70 | H11: 7 | I11: 2 | J11: 2 | K11: 4 | L11: 10 | M11: 0 | N11: 0 | O11: 0 | P11: 0
A12: 20-24세|합계 | B12: 20~24세 | C12: 합계 | D12: 544697 | E12: 472830 | F12: 57308 | G12: 10366 | H12: 1550 | I12: 837 | J12: 398 | K12: 289 | L12: 1119 | M12: 0 | N12: 0 | O12: 0 | P12: 0
A13: 20-24세|남자 | B13: 20~24세 | C13: 남자 | D13: 232348 | E13: 192849 | F13: 31339 | G13: 5982 | H13: 870 | I13: 471 | J13: 200 | K13: 127 | L13: 510 | M13: 0 | N13: 0 | O13: 0 | P13: 0
A14: 20-24세|여자 | B14: 20~24세 | C14: 여자 | D14: 312349 | E14: 279981 | F14: 25969 | G14: 4384 | H14: 680 | I14: 366 | J14: 198 | K14: 162 | L14: 609 | M14: 0 | N14: 0 | O14: 0 | P14: 0
A15: 25-29세|합계 | B15: 25~29세 | C15: 합계 | D15: 1205373 | E15: 998702 | F15: 159999 | G15: 33728 | H15: 4728 | I15: 2684 | J15: 1265 | K15: 849 | L15: 3418 | M15: 0 | N15: 0 | O15: 0 | P15: 0
A16: 25-29세|남자 | B16: 25~29세 | C16: 남자 | D16: 626978 | E16: 490425 | F16: 105239 | G16: 23141 | H16: 3052 | I16: 1723 | J16: 782 | K16: 513 | L16: 2103 | M16: 0 | N16: 0 | O16: 0 | P16: 0
A17: 25-29세|여자 | B17: 25~29세 | C17: 여자 | D17: 578395 | E17: 508277 | F17: 54760 | G17: 10587 | H17: 1676 | I17: 961 | J17: 483 | K17: 336 | L17: 1315 | M17: 0 | N17: 0 | O17: 0 | P17: 0
... A53: 85세이상|여자 | B53: 85세이상 | C53: 여자 | D53: 63312 | E53: 29660 | F53: 13359 | G53: 10668 | H53: 4066 | I53: 2727 | J53: 1244 | K53: 621 | L53: 967 | M53: 0 | N53: 0 | O53: 0 | P53: 0

Sheet D_TC
A1: 총 콜레스테롤 분포 · 국민건강보험공단 건강검진통계 2024 (KOSIS, 전국) · 단위 mg/dL
A2: 3~4행 하한·상한은 열 이름의 구간 경계. 양끝 개방 구간의 바깥 경계는 계산용 가정값(파란색). 데이터 셀(6행 이하)은 수정하지 마세요.
D3: 하한 | E3: 80 | F3: 140 | G3: 160 | H3: 180 | I3: 200 | J3: 220 | K3: 240 | L3: 260 | M3: 280 | N3: 1000000000 | O3: 1000000000 | P3: 1000000000
D4: 상한 | E4: 140 | F4: 160 | G4: 180 | H4: 200 | I4: 220 | J4: 240 | K4: 260 | L4: 280 | M4: 400 | N4: 2000000000 | O4: 2000000000 | P4: 2000000000
A5: 키 | B5: 연령 | C5: 성별 | D5: 계 | E5: 140미만 | F5: 140-159 | G5: 160-179 | H5: 180-199 | I5: 200-219 | J5: 220-239 | K5: 240-259 | L5: 260-279 | M5: 280이상 | N5: (미사용) | O5: (미사용) | P5: (미사용)
A6: 계|합계 | B6: 계 | C6: 합계 | D6: 6013869 | E6: 533471 | F6: 654219 | G6: 936202 | H6: 1108544 | I6: 1049046 | J6: 796181 | K6: 486728 | L6: 251997 | M6: 197481 | N6: 0 | O6: 0 | P6: 0
A7: 계|남자 | B7: 계 | C7: 남자 | D7: 3306479 | E7: 340496 | F7: 367884 | G7: 515266 | H7: 610684 | I7: 572772 | J7: 425827 | K7: 251959 | L7: 126507 | M7: 95084 | N7: 0 | O7: 0 | P7: 0
A8: 계|여자 | B8: 계 | C8: 여자 | D8: 2707390 | E8: 192975 | F8: 286335 | G8: 420936 | H8: 497860 | I8: 476274 | J8: 370354 | K8: 234769 | L8: 125490 | M8: 102397 | N8: 0 | O8: 0 | P8: 0
A9: 19세이하|합계 | B9: 19세이하 | C9: 합계 | D9: 0 | E9: 0 | F9: 0 | G9: 0 | H9: 0 | I9: 0 | J9: 0 | K9: 0 | L9: 0 | M9: 0 | N9: 0 | O9: 0 | P9: 0
A10: 19세이하|남자 | B10: 19세이하 | C10: 남자 | D10: 0 | E10: 0 | F10: 0 | G10: 0 | H10: 0 | I10: 0 | J10: 0 | K10: 0 | L10: 0 | M10: 0 | N10: 0 | O10: 0 | P10: 0
A11: 19세이하|여자 | B11: 19세이하 | C11: 여자 | D11: 0 | E11: 0 | F11: 0 | G11: 0 | H11: 0 | I11: 0 | J11: 0 | K11: 0 | L11: 0 | M11: 0 | N11: 0 | O11: 0 | P11: 0
A12: 20-24세|합계 | B12: 20~24세 | C12: 합계 | D12: 106555 | E12: 7140 | F12: 17677 | G12: 26334 | H12: 24899 | I12: 16310 | J12: 8340 | K12: 3627 | L12: 1383 | M12: 845 | N12: 0 | O12: 0 | P12: 0
A13: 20-24세|남자 | B13: 20~24세 | C13: 남자 | D13: 106555 | E13: 7140 | F13: 17677 | G13: 26334 | H13: 24899 | I13: 16310 | J13: 8340 | K13: 3627 | L13: 1383 | M13: 845 | N13: 0 | O13: 0 | P13: 0
A14: 20-24세|여자 | B14: 20~24세 | C14: 여자 | D14: 0 | E14: 0 | F14: 0 | G14: 0 | H14: 0 | I14: 0 | J14: 0 | K14: 0 | L14: 0 | M14: 0 | N14: 0 | O14: 0 | P14: 0
A15: 25-29세|합계 | B15: 25~29세 | C15: 합계 | D15: 196547 | E15: 7273 | F15: 21161 | G15: 40383 | H15: 47343 | I15: 37739 | J15: 23043 | K15: 11392 | L15: 4966 | M15: 3247 | N15: 0 | O15: 0 | P15: 0
A16: 25-29세|남자 | B16: 25~29세 | C16: 남자 | D16: 196547 | E16: 7273 | F16: 21161 | G16: 40383 | H16: 47343 | I16: 37739 | J16: 23043 | K16: 11392 | L16: 4966 | M16: 3247 | N16: 0 | O16: 0 | P16: 0
A17: 25-29세|여자 | B17: 25~29세 | C17: 여자 | D17: 0 | E17: 0 | F17: 0 | G17: 0 | H17: 0 | I17: 0 | J17: 0 | K17: 0 | L17: 0 | M17: 0 | N17: 0 | O17: 0 | P17: 0
... A53: 85세이상|여자 | B53: 85세이상 | C53: 여자 | D53: 24918 | E53: 5400 | F53: 4931 | G53: 4915 | H53: 3911 | I53: 2686 | J53: 1612 | K53: 828 | L53: 389 | M53: 246 | N53: 0 | O53: 0 | P53: 0

Sheet D_HDL
A1: HDL 콜레스테롤 분포 · 국민건강보험공단 건강검진통계 2024 (KOSIS, 전국) · 단위 mg/dL
A2: 3~4행 하한·상한은 열 이름의 구간 경계. 양끝 개방 구간의 바깥 경계는 계산용 가정값(파란색). 데이터 셀(6행 이하)은 수정하지 마세요.
D3: 하한 | E3: 15 | F3: 30 | G3: 40 | H3: 50 | I3: 60 | J3: 70 | K3: 80 | L3: 90 | M3: 1000000000 | N3: 1000000000 | O3: 1000000000 | P3: 1000000000
D4: 상한 | E4: 30 | F4: 40 | G4: 50 | H4: 60 | I4: 70 | J4: 80 | K4: 90 | L4: 130 | M4: 2000000000 | N4: 2000000000 | O4: 2000000000 | P4: 2000000000
A5: 키 | B5: 연령 | C5: 성별 | D5: 계 | E5: 30미만 | F5: 30-39 | G5: 40-49 | H5: 50-59 | I5: 60-69 | J5: 70-79 | K5: 80-89 | L5: 90이상 | M5: (미사용) | N5: (미사용) | O5: (미사용) | P5: (미사용)
A6: 계|합계 | B6: 계 | C6: 합계 | D6: 6013854 | E6: 39495 | F6: 528148 | G6: 1477568 | H6: 1652725 | I6: 1184921 | J6: 652947 | K6: 297093 | L6: 180957 | M6: 0 | N6: 0 | O6: 0 | P6: 0
A7: 계|남자 | B7: 계 | C7: 남자 | D7: 3306467 | E7: 31646 | F7: 418707 | G7: 1043321 | H7: 947482 | I7: 523303 | J7: 220695 | K7: 80344 | L7: 40969 | M7: 0 | N7: 0 | O7: 0 | P7: 0
A8: 계|여자 | B8: 계 | C8: 여자 | D8: 2707387 | E8: 7849 | F8: 109441 | G8: 434247 | H8: 705243 | I8: 661618 | J8: 432252 | K8: 216749 | L8: 139988 | M8: 0 | N8: 0 | O8: 0 | P8: 0
A9: 19세이하|합계 | B9: 19세이하 | C9: 합계 | D9: 0 | E9: 0 | F9: 0 | G9: 0 | H9: 0 | I9: 0 | J9: 0 | K9: 0 | L9: 0 | M9: 0 | N9: 0 | O9: 0 | P9: 0
A10: 19세이하|남자 | B10: 19세이하 | C10: 남자 | D10: 0 | E10: 0 | F10: 0 | G10: 0 | H10: 0 | I10: 0 | J10: 0 | K10: 0 | L10: 0 | M10: 0 | N10: 0 | O10: 0 | P10: 0
A11: 19세이하|여자 | B11: 19세이하 | C11: 여자 | D11: 0 | E11: 0 | F11: 0 | G11: 0 | H11: 0 | I11: 0 | J11: 0 | K11: 0 | L11: 0 | M11: 0 | N11: 0 | O11: 0 | P11: 0
A12: 20-24세|합계 | B12: 20~24세 | C12: 합계 | D12: 106554 | E12: 509 | F12: 9161 | G12: 30249 | H12: 34453 | I12: 20460 | J12: 8174 | K12: 2557 | L12: 991 | M12: 0 | N12: 0 | O12: 0 | P12: 0
A13: 20-24세|남자 | B13: 20~24세 | C13: 남자 | D13: 106554 | E13: 509 | F13: 9161 | G13: 30249 | H13: 34453 | I13: 20460 | J13: 8174 | K13: 2557 | L13: 991 | M13: 0 | N13: 0 | O13: 0 | P13: 0
A14: 20-24세|여자 | B14: 20~24세 | C14: 여자 | D14: 0 | E14: 0 | F14: 0 | G14: 0 | H14: 0 | I14: 0 | J14: 0 | K14: 0 | L14: 0 | M14: 0 | N14: 0 | O14: 0 | P14: 0
A15: 25-29세|합계 | B15: 25~29세 | C15: 합계 | D15: 196541 | E15: 1156 | F15: 18390 | G15: 56178 | H15: 60792 | I15: 36847 | J15: 15580 | K15: 5277 | L15: 2321 | M15: 0 | N15: 0 | O15: 0 | P15: 0
A16: 25-29세|남자 | B16: 25~29세 | C16: 남자 | D16: 196541 | E16: 1156 | F16: 18390 | G16: 56178 | H16: 60792 | I16: 36847 | J16: 15580 | K16: 5277 | L16: 2321 | M16: 0 | N16: 0 | O16: 0 | P16: 0
A17: 25-29세|여자 | B17: 25~29세 | C17: 여자 | D17: 0 | E17: 0 | F17: 0 | G17: 0 | H17: 0 | I17: 0 | J17: 0 | K17: 0 | L17: 0 | M17: 0 | N17: 0 | O17: 0 | P17: 0
... A53: 85세이상|여자 | B53: 85세이상 | C53: 여자 | D53: 24918 | E53: 695 | F53: 3725 | G53: 6877 | H53: 6560 | I53: 4100 | J53: 1928 | K53: 717 | L53: 316 | M53: 0 | N53: 0 | O53: 0 | P53: 0

Sheet D_TG
A1: 중성지방 분포 · 국민건강보험공단 건강검진통계 2024 (KOSIS, 전국) · 단위 mg/dL
A2: 3~4행 하한·상한은 열 이름의 구간 경계. 양끝 개방 구간의 바깥 경계는 계산용 가정값(파란색). 데이터 셀(6행 이하)은 수정하지 마세요.
D3: 하한 | E3: 20 | F3: 50 | G3: 100 | H3: 150 | I3: 200 | J3: 300 | K3: 400 | L3: 500 | M3: 1000000000 | N3: 1000000000 | O3: 1000000000 | P3: 1000000000
D4: 상한 | E4: 50 | F4: 100 | G4: 150 | H4: 200 | I4: 300 | J4: 400 | K4: 500 | L4: 1000 | M4: 2000000000 | N4: 2000000000 | O4: 2000000000 | P4: 2000000000
A5: 키 | B5: 연령 | C5: 성별 | D5: 계 | E5: 50미만 | F5: 50-99 | G5: 100-149 | H5: 150-199 | I5: 200-299 | J5: 300-399 | K5: 400-499 | L5: 500이상 | M5: (미사용) | N5: (미사용) | O5: (미사용) | P5: (미사용)
A6: 계|합계 | B6: 계 | C6: 합계 | D6: 6013843 | E6: 394970 | F6: 2364528 | G6: 1650523 | H6: 791860 | I6: 555064 | J6: 152057 | K6: 50957 | L6: 53884 | M6: 0 | N6: 0 | O6: 0 | P6: 0
A7: 계|남자 | B7: 계 | C7: 남자 | D7: 3306460 | E7: 163829 | F7: 1105848 | G7: 921943 | H7: 506900 | I7: 398479 | J7: 120289 | K7: 42388 | L7: 46784 | M7: 0 | N7: 0 | O7: 0 | P7: 0
A8: 계|여자 | B8: 계 | C8: 여자 | D8: 2707383 | E8: 231141 | F8: 1258680 | G8: 728580 | H8: 284960 | I8: 156585 | J8: 31768 | K8: 8569 | L8: 7100 | M8: 0 | N8: 0 | O8: 0 | P8: 0
A9: 19세이하|합계 | B9: 19세이하 | C9: 합계 | D9: 0 | E9: 0 | F9: 0 | G9: 0 | H9: 0 | I9: 0 | J9: 0 | K9: 0 | L9: 0 | M9: 0 | N9: 0 | O9: 0 | P9: 0
A10: 19세이하|남자 | B10: 19세이하 | C10: 남자 | D10: 0 | E10: 0 | F10: 0 | G10: 0 | H10: 0 | I10: 0 | J10: 0 | K10: 0 | L10: 0 | M10: 0 | N10: 0 | O10: 0 | P10: 0
A11: 19세이하|여자 | B11: 19세이하 | C11: 여자 | D11: 0 | E11: 0 | F11: 0 | G11: 0 | H11: 0 | I11: 0 | J11: 0 | K11: 0 | L11: 0 | M11: 0 | N11: 0 | O11: 0 | P11: 0
A12: 20-24세|합계 | B12: 20~24세 | C12: 합계 | D12: 106554 | E12: 12448 | F12: 50535 | G12: 24677 | H12: 9862 | I12: 6414 | J12: 1573 | K12: 478 | L12: 567 | M12: 0 | N12: 0 | O12: 0 | P12: 0
A13: 20-24세|남자 | B13: 20~24세 | C13: 남자 | D13: 106554 | E13: 12448 | F13: 50535 | G13: 24677 | H13: 9862 | I13: 6414 | J13: 1573 | K13: 478 | L13: 567 | M13: 0 | N13: 0 | O13: 0 | P13: 0
A14: 20-24세|여자 | B14: 20~24세 | C14: 여자 | D14: 0 | E14: 0 | F14: 0 | G14: 0 | H14: 0 | I14: 0 | J14: 0 | K14: 0 | L14: 0 | M14: 0 | N14: 0 | O14: 0 | P14: 0
A15: 25-29세|합계 | B15: 25~29세 | C15: 합계 | D15: 196542 | E15: 17037 | F15: 83550 | G15: 48981 | H15: 22341 | I15: 16286 | J15: 4676 | K15: 1622 | L15: 2049 | M15: 0 | N15: 0 | O15: 0 | P15: 0
A16: 25-29세|남자 | B16: 25~29세 | C16: 남자 | D16: 196542 | E16: 17037 | F16: 83550 | G16: 48981 | H16: 22341 | I16: 16286 | J16: 4676 | K16: 1622 | L16: 2049 | M16: 0 | N16: 0 | O16: 0 | P16: 0
A17: 25-29세|여자 | B17: 25~29세 | C17: 여자 | D17: 0 | E17: 0 | F17: 0 | G17: 0 | H17: 0 | I17: 0 | J17: 0 | K17: 0 | L17: 0 | M17: 0 | N17: 0 | O17: 0 | P17: 0
... A53: 85세이상|여자 | B53: 85세이상 | C53: 여자 | D53: 24917 | E53: 574 | F53: 9266 | G53: 9055 | H53: 3781 | I53: 1821 | J53: 295 | K53: 70 | L53: 55 | M53: 0 | N53: 0 | O53: 0 | P53: 0

Sheet D_LDL
A1: LDL 콜레스테롤 분포 · 국민건강보험공단 건강검진통계 2024 (KOSIS, 전국) · 단위 mg/dL
A2: 3~4행 하한·상한은 열 이름의 구간 경계. 양끝 개방 구간의 바깥 경계는 계산용 가정값(파란색). 데이터 셀(6행 이하)은 수정하지 마세요.
D3: 하한 | E3: 20 | F3: 70 | G3: 100 | H3: 130 | I3: 160 | J3: 190 | K3: 1000000000 | L3: 1000000000 | M3: 1000000000 | N3: 1000000000 | O3: 1000000000 | P3: 1000000000
D4: 상한 | E4: 70 | F4: 100 | G4: 130 | H4: 160 | I4: 190 | J4: 300 | K4: 2000000000 | L4: 2000000000 | M4: 2000000000 | N4: 2000000000 | O4: 2000000000 | P4: 2000000000
A5: 키 | B5: 연령 | C5: 성별 | D5: 계 | E5: 70미만 | F5: 70-99 | G5: 100-129 | H5: 130-159 | I5: 160-189 | J5: 190이상 | K5: (미사용) | L5: (미사용) | M5: (미사용) | N5: (미사용) | O5: (미사용) | P5: (미사용)
A6: 계|합계 | B6: 계 | C6: 합계 | D6: 5899487 | E6: 740160 | F6: 1414837 | G6: 1752478 | H6: 1276011 | I6: 532762 | J6: 183239 | K6: 0 | L6: 0 | M6: 0 | N6: 0 | O6: 0 | P6: 0
A7: 계|남자 | B7: 계 | C7: 남자 | D7: 3212354 | E7: 432039 | F7: 744892 | G7: 958782 | H7: 702280 | I7: 284203 | J7: 90158 | K7: 0 | L7: 0 | M7: 0 | N7: 0 | O7: 0 | P7: 0
A8: 계|여자 | B8: 계 | C8: 여자 | D8: 2687133 | E8: 308121 | F8: 669945 | G8: 793696 | H8: 573731 | I8: 248559 | J8: 93081 | K8: 0 | L8: 0 | M8: 0 | N8: 0 | O8: 0 | P8: 0
A9: 19세이하|합계 | B9: 19세이하 | C9: 합계 | D9: 0 | E9: 0 | F9: 0 | G9: 0 | H9: 0 | I9: 0 | J9: 0 | K9: 0 | L9: 0 | M9: 0 | N9: 0 | O9: 0 | P9: 0
A10: 19세이하|남자 | B10: 19세이하 | C10: 남자 | D10: 0 | E10: 0 | F10: 0 | G10: 0 | H10: 0 | I10: 0 | J10: 0 | K10: 0 | L10: 0 | M10: 0 | N10: 0 | O10: 0 | P10: 0
A11: 19세이하|여자 | B11: 19세이하 | C11: 여자 | D11: 0 | E11: 0 | F11: 0 | G11: 0 | H11: 0 | I11: 0 | J11: 0 | K11: 0 | L11: 0 | M11: 0 | N11: 0 | O11: 0 | P11: 0
A12: 20-24세|합계 | B12: 20~24세 | C12: 합계 | D12: 105453 | E12: 8013 | F12: 35538 | G12: 39225 | H12: 17328 | I12: 4387 | J12: 962 | K12: 0 | L12: 0 | M12: 0 | N12: 0 | O12: 0 | P12: 0
A13: 20-24세|남자 | B13: 20~24세 | C13: 남자 | D13: 105453 | E13: 8013 | F13: 35538 | G13: 39225 | H13: 17328 | I13: 4387 | J13: 962 | K13: 0 | L13: 0 | M13: 0 | N13: 0 | O13: 0 | P13: 0
A14: 20-24세|여자 | B14: 20~24세 | C14: 여자 | D14: 0 | E14: 0 | F14: 0 | G14: 0 | H14: 0 | I14: 0 | J14: 0 | K14: 0 | L14: 0 | M14: 0 | N14: 0 | O14: 0 | P14: 0
A15: 25-29세|합계 | B15: 25~29세 | C15: 합계 | D15: 192693 | E15: 9684 | F15: 49638 | G15: 74119 | H15: 42625 | I15: 13221 | J15: 3406 | K15: 0 | L15: 0 | M15: 0 | N15: 0 | O15: 0 | P15: 0
A16: 25-29세|남자 | B16: 25~29세 | C16: 남자 | D16: 192693 | E16: 9684 | F16: 49638 | G16: 74119 | H16: 42625 | I16: 13221 | J16: 3406 | K16: 0 | L16: 0 | M16: 0 | N16: 0 | O16: 0 | P16: 0
A17: 25-29세|여자 | B17: 25~29세 | C17: 여자 | D17: 0 | E17: 0 | F17: 0 | G17: 0 | H17: 0 | I17: 0 | J17: 0 | K17: 0 | L17: 0 | M17: 0 | N17: 0 | O17: 0 | P17: 0
... A53: 85세이상|여자 | B53: 85세이상 | C53: 여자 | D53: 24772 | E53: 6539 | F53: 8356 | G53: 5886 | H53: 2836 | I53: 910 | J53: 245 | K53: 0 | L53: 0 | M53: 0 | N53: 0 | O53: 0 | P53: 0

Sheet D_HB
A1: 혈색소 분포 · 국민건강보험공단 건강검진통계 2024 (KOSIS, 전국) · 단위 g/dL
A2: 3~4행 하한·상한은 열 이름의 구간 경계. 양끝 개방 구간의 바깥 경계는 계산용 가정값(파란색). 데이터 셀(6행 이하)은 수정하지 마세요.
D3: 하한 | E3: 6 | F3: 10 | G3: 11 | H3: 12 | I3: 13 | J3: 14 | K3: 15 | L3: 15.6 | M3: 16 | N3: 16.6 | O3: 1000000000 | P3: 1000000000
D4: 상한 | E4: 10 | F4: 11 | G4: 12 | H4: 13 | I4: 14 | J4: 15 | K4: 15.6 | L4: 16 | M4: 16.6 | N4: 20 | O4: 2000000000 | P4: 2000000000
A5: 키 | B5: 연령 | C5: 성별 | D5: 계 | E5: 10.0미만 | F5: 10.0-10.9 | G5: 11.0-11.9 | H5: 12.0-12.9 | I5: 13.0-13.9 | J5: 14.0-14.9 | K5: 15.0-15.5 | L5: 15.6-15.9 | M5: 16.0-16.5 | N5: 16.6이상 | O5: (미사용) | P5: (미사용)
A6: 계|합계 | B6: 계 | C6: 합계 | D6: 17516433 | E6: 137924 | F6: 202748 | G6: 678933 | H6: 2433849 | I6: 4142681 | J6: 4100121 | K6: 2295965 | L6: 1261904 | M6: 1289359 | N6: 972949 | O6: 0 | P6: 0
A7: 계|남자 | B7: 계 | C7: 남자 | D7: 9092941 | E7: 18853 | F7: 25806 | G7: 65987 | H7: 213197 | I7: 861427 | J7: 2467611 | K7: 2025227 | L7: 1198214 | M7: 1255478 | N7: 961141 | O7: 0 | P7: 0
A8: 계|여자 | B8: 계 | C8: 여자 | D8: 8423492 | E8: 119071 | F8: 176942 | G8: 612946 | H8: 2220652 | I8: 3281254 | J8: 1632510 | K8: 270738 | L8: 63690 | M8: 33881 | N8: 11808 | O8: 0 | P8: 0
A9: 19세이하|합계 | B9: 19세이하 | C9: 합계 | D9: 8654 | E9: 29 | F9: 65 | G9: 285 | H9: 878 | I9: 1465 | J9: 1839 | K9: 1572 | L9: 958 | M9: 990 | N9: 573 | O9: 0 | P9: 0
A10: 19세이하|남자 | B10: 19세이하 | C10: 남자 | D10: 5724 | E10: 0 | F10: 0 | G10: 12 | H10: 20 | I10: 266 | J10: 1388 | K10: 1531 | L10: 950 | M10: 984 | N10: 573 | O10: 0 | P10: 0
A11: 19세이하|여자 | B11: 19세이하 | C11: 여자 | D11: 2930 | E11: 29 | F11: 65 | G11: 273 | H11: 858 | I11: 1199 | J11: 451 | K11: 41 | L11: 8 | M11: 6 | N11: 0 | O11: 0 | P11: 0
A12: 20-24세|합계 | B12: 20~24세 | C12: 합계 | D12: 544696 | E12: 2757 | F12: 5237 | G12: 22137 | H12: 90036 | I12: 141608 | J12: 105095 | K12: 64224 | L12: 40266 | M12: 44019 | N12: 29317 | O12: 0 | P12: 0
A13: 20-24세|남자 | B13: 20~24세 | C13: 남자 | D13: 232346 | E13: 76 | F13: 83 | G13: 243 | H13: 1159 | I13: 9347 | J13: 51011 | K13: 58306 | L13: 39316 | M13: 43590 | N13: 29215 | O13: 0 | P13: 0
A14: 20-24세|여자 | B14: 20~24세 | C14: 여자 | D14: 312350 | E14: 2681 | F14: 5154 | G14: 21894 | H14: 88877 | I14: 132261 | J14: 54084 | K14: 5918 | L14: 950 | M14: 429 | N14: 102 | O14: 0 | P14: 0
A15: 25-29세|합계 | B15: 25~29세 | C15: 합계 | D15: 1205367 | E15: 4447 | F15: 8362 | G15: 34729 | H15: 161620 | I15: 277118 | J15: 253028 | K15: 173324 | L15: 107111 | M15: 112178 | N15: 73450 | O15: 0 | P15: 0
A16: 25-29세|남자 | B16: 25~29세 | C16: 남자 | D16: 626975 | E16: 236 | F16: 196 | G16: 571 | H16: 2746 | I16: 26144 | J16: 146673 | K16: 160915 | L16: 104934 | M16: 111358 | N16: 73202 | O16: 0 | P16: 0
A17: 25-29세|여자 | B17: 25~29세 | C17: 여자 | D17: 578392 | E17: 4211 | F17: 8166 | G17: 34158 | H17: 158874 | I17: 250974 | J17: 106355 | K17: 12409 | L17: 2177 | M17: 820 | N17: 248 | O17: 0 | P17: 0
... A53: 85세이상|여자 | B53: 85세이상 | C53: 여자 | D53: 63308 | E53: 4605 | F53: 7297 | G53: 14007 | H53: 18174 | I53: 12948 | J53: 5009 | K53: 892 | L53: 194 | M53: 121 | N53: 61 | O53: 0 | P53: 0

Sheet D_CR
A1: 혈청 크레아티닌 분포 · 국민건강보험공단 건강검진통계 2024 (KOSIS, 전국) · 단위 mg/dL
A2: 3~4행 하한·상한은 열 이름의 구간 경계. 양끝 개방 구간의 바깥 경계는 계산용 가정값(파란색). 데이터 셀(6행 이하)은 수정하지 마세요.
D3: 하한 | E3: 0.3 | F3: 0.9 | G3: 1.1 | H3: 1.3 | I3: 1.5 | J3: 1.7 | K3: 1.9 | L3: 2.1 | M3: 1000000000 | N3: 1000000000 | O3: 1000000000 | P3: 1000000000
D4: 상한 | E4: 0.9 | F4: 1.1 | G4: 1.3 | H4: 1.5 | I4: 1.7 | J4: 1.9 | K4: 2.1 | L4: 5 | M4: 2000000000 | N4: 2000000000 | O4: 2000000000 | P4: 2000000000
A5: 키 | B5: 연령 | C5: 성별 | D5: 계 | E5: 0.9미만 | F5: 0.9-1.0 | G5: 1.1-1.2 | H5: 1.3-1.4 | I5: 1.5-1.6 | J5: 1.7-1.8 | K5: 1.9-2.0 | L5: 2.1이상 | M5: (미사용) | N5: (미사용) | O5: (미사용) | P5: (미사용)
A6: 계|합계 | B6: 계 | C6: 합계 | D6: 17516863 | E6: 9759710 | F6: 5289296 | G6: 1966209 | H6: 356942 | I6: 68286 | J6: 24492 | K6: 12116 | L6: 39812 | M6: 0 | N6: 0 | O6: 0 | P6: 0
A7: 계|남자 | B7: 계 | C7: 남자 | D7: 9093256 | E7: 2570349 | F7: 4219131 | G7: 1852322 | H7: 333912 | I7: 59491 | J7: 20277 | K7: 9677 | L7: 28097 | M7: 0 | N7: 0 | O7: 0 | P7: 0
A8: 계|여자 | B8: 계 | C8: 여자 | D8: 8423607 | E8: 7189361 | F8: 1070165 | G8: 113887 | H8: 23030 | I8: 8795 | J8: 4215 | K8: 2439 | L8: 11715 | M8: 0 | N8: 0 | O8: 0 | P8: 0
A9: 19세이하|합계 | B9: 19세이하 | C9: 합계 | D9: 8654 | E9: 4716 | F9: 3121 | G9: 767 | H9: 47 | I9: 3 | J9: 0 | K9: 0 | L9: 0 | M9: 0 | N9: 0 | O9: 0 | P9: 0
A10: 19세이하|남자 | B10: 19세이하 | C10: 남자 | D10: 5724 | E10: 2139 | F10: 2776 | G10: 759 | H10: 47 | I10: 3 | J10: 0 | K10: 0 | L10: 0 | M10: 0 | N10: 0 | O10: 0 | P10: 0
A11: 19세이하|여자 | B11: 19세이하 | C11: 여자 | D11: 2930 | E11: 2577 | F11: 345 | G11: 8 | H11: 0 | I11: 0 | J11: 0 | K11: 0 | L11: 0 | M11: 0 | N11: 0 | O11: 0 | P11: 0
A12: 20-24세|합계 | B12: 20~24세 | C12: 합계 | D12: 544704 | E12: 338899 | F12: 149571 | G12: 49628 | H12: 6016 | I12: 353 | J12: 45 | K12: 15 | L12: 177 | M12: 0 | N12: 0 | O12: 0 | P12: 0
A13: 20-24세|남자 | B13: 20~24세 | C13: 남자 | D13: 232355 | E13: 62052 | F13: 115828 | G13: 48073 | H13: 5941 | I13: 340 | J13: 37 | K13: 10 | L13: 74 | M13: 0 | N13: 0 | O13: 0 | P13: 0
A14: 20-24세|여자 | B14: 20~24세 | C14: 여자 | D14: 312349 | E14: 276847 | F14: 33743 | G14: 1555 | H14: 75 | I14: 13 | J14: 8 | K14: 5 | L14: 103 | M14: 0 | N14: 0 | O14: 0 | P14: 0
A15: 25-29세|합계 | B15: 25~29세 | C15: 합계 | D15: 1205383 | E15: 672677 | F15: 377772 | G15: 136420 | H15: 16975 | I15: 993 | J15: 109 | K15: 40 | L15: 397 | M15: 0 | N15: 0 | O15: 0 | P15: 0
A16: 25-29세|남자 | B16: 25~29세 | C16: 남자 | D16: 626988 | E16: 160188 | F16: 315307 | G16: 133348 | H16: 16854 | I16: 956 | J16: 88 | K16: 28 | L16: 219 | M16: 0 | N16: 0 | O16: 0 | P16: 0
A17: 25-29세|여자 | B17: 25~29세 | C17: 여자 | D17: 578395 | E17: 512489 | F17: 62465 | G17: 3072 | H17: 121 | I17: 37 | J17: 21 | K17: 12 | L17: 178 | M17: 0 | N17: 0 | O17: 0 | P17: 0
... A53: 85세이상|여자 | B53: 85세이상 | C53: 여자 | D53: 63312 | E53: 36222 | F53: 15438 | G53: 6352 | H53: 2641 | I53: 1173 | J53: 591 | K53: 321 | L53: 574 | M53: 0 | N53: 0 | O53: 0 | P53: 0

Sheet D_EGFR
A1: 신사구체여과율 분포 · 국민건강보험공단 건강검진통계 2024 (KOSIS, 전국) · 단위 mL/min/1.73㎡
A2: 3~4행 하한·상한은 열 이름의 구간 경계. 양끝 개방 구간의 바깥 경계는 계산용 가정값(파란색). 데이터 셀(6행 이하)은 수정하지 마세요.
D3: 하한 | E3: 5 | F3: 30 | G3: 40 | H3: 50 | I3: 60 | J3: 80 | K3: 100 | L3: 150 | M3: 1000000000 | N3: 1000000000 | O3: 1000000000 | P3: 1000000000
D4: 상한 | E4: 30 | F4: 40 | G4: 50 | H4: 60 | I4: 80 | J4: 100 | K4: 150 | L4: 200 | M4: 2000000000 | N4: 2000000000 | O4: 2000000000 | P4: 2000000000
A5: 키 | B5: 연령 | C5: 성별 | D5: 계 | E5: 30미만 | F5: 30-39 | G5: 40-49 | H5: 50-59 | I5: 60-79 | J5: 80-99 | K5: 100-149 | L5: 150이상 | M5: (미사용) | N5: (미사용) | O5: (미사용) | P5: (미사용)
A6: 계|합계 | B6: 계 | C6: 합계 | D6: 17507116 | E6: 40111 | F6: 49193 | G6: 130114 | H6: 381707 | I6: 2997974 | J6: 6983354 | K6: 6908962 | L6: 15701 | M6: 0 | N6: 0 | O6: 0 | P6: 0
A7: 계|남자 | B7: 계 | C7: 남자 | D7: 9088489 | E7: 23630 | F7: 26814 | G7: 71990 | H7: 207235 | I7: 1717900 | J7: 3862470 | K7: 3171933 | L7: 6517 | M7: 0 | N7: 0 | O7: 0 | P7: 0
A8: 계|여자 | B8: 계 | C8: 여자 | D8: 8418627 | E8: 16481 | F8: 22379 | G8: 58124 | H8: 174472 | I8: 1280074 | J8: 3120884 | K8: 3737029 | L8: 9184 | M8: 0 | N8: 0 | O8: 0 | P8: 0
A9: 19세이하|합계 | B9: 19세이하 | C9: 합계 | D9: 8650 | E9: 0 | F9: 0 | G9: 1 | H9: 1 | I9: 57 | J9: 1114 | K9: 7364 | L9: 113 | M9: 0 | N9: 0 | O9: 0 | P9: 0
A10: 19세이하|남자 | B10: 19세이하 | C10: 남자 | D10: 5720 | E10: 0 | F10: 0 | G10: 1 | H10: 1 | I10: 47 | J10: 755 | K10: 4857 | L10: 59 | M10: 0 | N10: 0 | O10: 0 | P10: 0
A11: 19세이하|여자 | B11: 19세이하 | C11: 여자 | D11: 2930 | E11: 0 | F11: 0 | G11: 0 | H11: 0 | I11: 10 | J11: 359 | K11: 2507 | L11: 54 | M11: 0 | N11: 0 | O11: 0 | P11: 0
A12: 20-24세|합계 | B12: 20~24세 | C12: 합계 | D12: 544353 | E12: 58 | F12: 15 | G12: 45 | H12: 193 | I12: 11744 | J12: 81632 | K12: 448401 | L12: 2265 | M12: 0 | N12: 0 | O12: 0 | P12: 0
A13: 20-24세|남자 | B13: 20~24세 | C13: 남자 | D13: 232174 | E13: 32 | F13: 7 | G13: 22 | H13: 94 | I13: 6421 | J13: 49389 | K13: 175511 | L13: 698 | M13: 0 | N13: 0 | O13: 0 | P13: 0
A14: 20-24세|여자 | B14: 20~24세 | C14: 여자 | D14: 312179 | E14: 26 | F14: 8 | G14: 23 | H14: 99 | I14: 5323 | J14: 32243 | K14: 272890 | L14: 1567 | M14: 0 | N14: 0 | O14: 0 | P14: 0
A15: 25-29세|합계 | B15: 25~29세 | C15: 합계 | D15: 1204762 | E15: 169 | F15: 72 | G15: 100 | H15: 452 | I15: 36850 | J15: 211978 | K15: 953120 | L15: 2021 | M15: 0 | N15: 0 | O15: 0 | P15: 0
A16: 25-29세|남자 | B16: 25~29세 | C16: 남자 | D16: 626686 | E16: 93 | F16: 42 | G16: 52 | H16: 317 | I16: 20172 | J16: 143435 | K16: 462056 | L16: 519 | M16: 0 | N16: 0 | O16: 0 | P16: 0
A17: 25-29세|여자 | B17: 25~29세 | C17: 여자 | D17: 578076 | E17: 76 | F17: 30 | G17: 48 | H17: 135 | I17: 16678 | J17: 68543 | K17: 491064 | L17: 1502 | M17: 0 | N17: 0 | O17: 0 | P17: 0
... A53: 85세이상|여자 | B53: 85세이상 | C53: 여자 | D53: 63258 | E53: 2011 | F53: 3966 | G53: 7371 | H53: 13584 | I53: 24279 | J53: 11698 | K53: 308 | L53: 41 | M53: 0 | N53: 0 | O53: 0 | P53: 0

Sheet D_AST
A1: AST 분포 · 국민건강보험공단 건강검진통계 2024 (KOSIS, 전국) · 단위 U/L
A2: 3~4행 하한·상한은 열 이름의 구간 경계. 양끝 개방 구간의 바깥 경계는 계산용 가정값(파란색). 데이터 셀(6행 이하)은 수정하지 마세요.
D3: 하한 | E3: 5 | F3: 31 | G3: 41 | H3: 51 | I3: 61 | J3: 71 | K3: 81 | L3: 91 | M3: 101 | N3: 1000000000 | O3: 1000000000 | P3: 1000000000
D4: 상한 | E4: 31 | F4: 41 | G4: 51 | H4: 61 | I4: 71 | J4: 81 | K4: 91 | L4: 101 | M4: 300 | N4: 2000000000 | O4: 2000000000 | P4: 2000000000
A5: 키 | B5: 연령 | C5: 성별 | D5: 계 | E5: 30이하 | F5: 31-40 | G5: 41-50 | H5: 51-60 | I5: 61-70 | J5: 71-80 | K5: 81-90 | L5: 91-100 | M5: 101이상 | N5: (미사용) | O5: (미사용) | P5: (미사용)
A6: 계|합계 | B6: 계 | C6: 합계 | D6: 17516816 | E6: 13597099 | F6: 2402713 | G6: 745997 | H6: 314192 | I6: 159766 | J6: 90472 | K6: 56078 | L6: 36652 | M6: 113847 | N6: 0 | O6: 0 | P6: 0
A7: 계|남자 | B7: 계 | C7: 남자 | D7: 9093184 | E7: 6574844 | F7: 1500941 | G7: 495568 | H7: 212211 | I7: 108427 | J7: 61387 | K7: 37919 | L7: 24736 | M7: 77151 | N7: 0 | O7: 0 | P7: 0
A8: 계|여자 | B8: 계 | C8: 여자 | D8: 8423632 | E8: 7022255 | F8: 901772 | G8: 250429 | H8: 101981 | I8: 51339 | J8: 29085 | K8: 18159 | L8: 11916 | M8: 36696 | N8: 0 | O8: 0 | P8: 0
A9: 19세이하|합계 | B9: 19세이하 | C9: 합계 | D9: 8654 | E9: 7686 | F9: 522 | G9: 166 | H9: 89 | I9: 54 | J9: 33 | K9: 16 | L9: 19 | M9: 69 | N9: 0 | O9: 0 | P9: 0
A10: 19세이하|남자 | B10: 19세이하 | C10: 남자 | D10: 5724 | E10: 4894 | F10: 454 | G10: 137 | H10: 78 | I10: 43 | J10: 27 | K10: 15 | L10: 18 | M10: 58 | N10: 0 | O10: 0 | P10: 0
A11: 19세이하|여자 | B11: 19세이하 | C11: 여자 | D11: 2930 | E11: 2792 | F11: 68 | G11: 29 | H11: 11 | I11: 11 | J11: 6 | K11: 1 | L11: 1 | M11: 11 | N11: 0 | O11: 0 | P11: 0
A12: 20-24세|합계 | B12: 20~24세 | C12: 합계 | D12: 544704 | E12: 488488 | F12: 30116 | G12: 10376 | H12: 5093 | I12: 2956 | J12: 1792 | K12: 1212 | L12: 952 | M12: 3719 | N12: 0 | O12: 0 | P12: 0
A13: 20-24세|남자 | B13: 20~24세 | C13: 남자 | D13: 232351 | E13: 191884 | F13: 21727 | G13: 7548 | H13: 3644 | I13: 2111 | J13: 1291 | K13: 838 | L13: 662 | M13: 2646 | N13: 0 | O13: 0 | P13: 0
A14: 20-24세|여자 | B14: 20~24세 | C14: 여자 | D14: 312353 | E14: 296604 | F14: 8389 | G14: 2828 | H14: 1449 | I14: 845 | J14: 501 | K14: 374 | L14: 290 | M14: 1073 | N14: 0 | O14: 0 | P14: 0
A15: 25-29세|합계 | B15: 25~29세 | C15: 합계 | D15: 1205378 | E15: 1043672 | F15: 89704 | G15: 30277 | H15: 14092 | I15: 7975 | J15: 4855 | K15: 3377 | L15: 2244 | M15: 9182 | N15: 0 | O15: 0 | P15: 0
A16: 25-29세|남자 | B16: 25~29세 | C16: 남자 | D16: 626984 | E16: 499074 | F16: 71656 | G16: 24152 | H16: 11092 | I16: 6151 | J16: 3757 | K16: 2590 | L16: 1672 | M16: 6840 | N16: 0 | O16: 0 | P16: 0
A17: 25-29세|여자 | B17: 25~29세 | C17: 여자 | D17: 578394 | E17: 544598 | F17: 18048 | G17: 6125 | H17: 3000 | I17: 1824 | J17: 1098 | K17: 787 | L17: 572 | M17: 2342 | N17: 0 | O17: 0 | P17: 0
... A53: 85세이상|여자 | B53: 85세이상 | C53: 여자 | D53: 63312 | E53: 51121 | F53: 8647 | G53: 1997 | H53: 689 | I53: 307 | J53: 172 | K53: 108 | L53: 62 | M53: 209 | N53: 0 | O53: 0 | P53: 0

Sheet D_ALT
A1: ALT 분포 · 국민건강보험공단 건강검진통계 2024 (KOSIS, 전국) · 단위 U/L
A2: 3~4행 하한·상한은 열 이름의 구간 경계. 양끝 개방 구간의 바깥 경계는 계산용 가정값(파란색). 데이터 셀(6행 이하)은 수정하지 마세요.
D3: 하한 | E3: 3 | F3: 36 | G3: 41 | H3: 46 | I3: 51 | J3: 61 | K3: 71 | L3: 81 | M3: 91 | N3: 101 | O3: 1000000000 | P3: 1000000000
D4: 상한 | E4: 36 | F4: 41 | G4: 46 | H4: 51 | I4: 61 | J4: 71 | K4: 81 | L4: 91 | M4: 101 | N4: 300 | O4: 2000000000 | P4: 2000000000
A5: 키 | B5: 연령 | C5: 성별 | D5: 계 | E5: 35이하 | F5: 36-40 | G5: 41-45 | H5: 46-50 | I5: 51-60 | J5: 61-70 | K5: 71-80 | L5: 81-90 | M5: 91-100 | N5: 101이상 | O5: (미사용) | P5: (미사용)
A6: 계|합계 | B6: 계 | C6: 합계 | D6: 17516776 | E6: 14377684 | F6: 799338 | G6: 555869 | H6: 388646 | I6: 500154 | J6: 287762 | K6: 177974 | L6: 116042 | M6: 79125 | N6: 234182 | O6: 0 | P6: 0
A7: 계|남자 | B7: 계 | C7: 남자 | D7: 9093161 | E7: 6712829 | F7: 578752 | G7: 414961 | H7: 295039 | I7: 386202 | J7: 225302 | K7: 140247 | L7: 91903 | M7: 63014 | N7: 184912 | O7: 0 | P7: 0
A8: 계|여자 | B8: 계 | C8: 여자 | D8: 8423615 | E8: 7664855 | F8: 220586 | G8: 140908 | H8: 93607 | I8: 113952 | J8: 62460 | K8: 37727 | L8: 24139 | M8: 16111 | N8: 49270 | O8: 0 | P8: 0
A9: 19세이하|합계 | B9: 19세이하 | C9: 합계 | D9: 8654 | E9: 7647 | F9: 199 | G9: 166 | H9: 91 | I9: 126 | J9: 97 | K9: 65 | L9: 54 | M9: 44 | N9: 165 | O9: 0 | P9: 0
A10: 19세이하|남자 | B10: 19세이하 | C10: 남자 | D10: 5724 | E10: 4840 | F10: 177 | G10: 146 | H10: 83 | I10: 107 | J10: 88 | K10: 57 | L10: 44 | M10: 40 | N10: 142 | O10: 0 | P10: 0
A11: 19세이하|여자 | B11: 19세이하 | C11: 여자 | D11: 2930 | E11: 2807 | F11: 22 | G11: 20 | H11: 8 | I11: 19 | J11: 9 | K11: 8 | L11: 10 | M11: 4 | N11: 23 | O11: 0 | P11: 0
A12: 20-24세|합계 | B12: 20~24세 | C12: 합계 | D12: 544699 | E12: 485123 | F12: 11778 | G12: 8791 | H12: 6222 | I12: 8858 | J12: 5706 | K12: 3865 | L12: 2899 | M12: 2197 | N12: 9260 | O12: 0 | P12: 0
A13: 20-24세|남자 | B13: 20~24세 | C13: 남자 | D13: 232347 | E13: 185953 | F13: 9039 | G13: 6796 | H13: 4876 | I13: 6922 | J13: 4466 | K13: 3017 | L13: 2266 | M13: 1720 | N13: 7292 | O13: 0 | P13: 0
A14: 20-24세|여자 | B14: 20~24세 | C14: 여자 | D14: 312352 | E14: 299170 | F14: 2739 | G14: 1995 | H14: 1346 | I14: 1936 | J14: 1240 | K14: 848 | L14: 633 | M14: 477 | N14: 1968 | O14: 0 | P14: 0
A15: 25-29세|합계 | B15: 25~29세 | C15: 합계 | D15: 1205377 | E15: 1025193 | F15: 36806 | G15: 27013 | H15: 19792 | I15: 27119 | J15: 17578 | K15: 11867 | L15: 8611 | M15: 6458 | N15: 24940 | O15: 0 | P15: 0
A16: 25-29세|남자 | B16: 25~29세 | C16: 남자 | D16: 626982 | E16: 473721 | F16: 30853 | G16: 22902 | H16: 16888 | I16: 23190 | J16: 15050 | K16: 10171 | L16: 7380 | M16: 5558 | N16: 21269 | O16: 0 | P16: 0
